Workbook

Sheet Cover
A1: London Stock Exchange Group plc (LSEG.L)
A2: Driver-based model: quarterly build, divisional EBITDA, three statements, DCF, SOTP, reverse DCF, scenarios, pair trade
A3: Tobenna Agubuche | github.com/Tobenna30/finance-models | Not investment advice
A5: Scenario selected | B5: =CHOOSE(Inputs!$C$7,"Bear","Base","Bull")
A6: Share price (p) | B6: =Inputs!$C$18
A7: DCF fair value (p) | B7: =DCF!B23
A8: DCF upside | B8: =DCF!B25
A9: SOTP value (p) | B9: =SOTP!B13
A10: SOTP upside | B10: =SOTP!B14
A11: Probability-weighted DCF (p) | B11: =Scenarios!B16
A12: 2026E adj EPS (p) | B12: =Model!F20
A13: 2027E P/E | B13: =DCF!B28
A14: Net debt / EBITDA 2027E | B14: =Model!G55
A15: Retention implied by share price | B15: ='Reverse DCF'!C5
A16: Stub (ex-Tradeweb) forward P/E | B16: ='Stub ex-Tradeweb'!B13
A17: Trailing P/E vs 5y average | B17: ='Valuation history'!I4
A18: Balance sheet checks (sum, should be 0) | B18: =SUM(Model!E53:Model!J53)

Sheet Inputs
A1: LSEG – Model inputs
A2: Blue = hard-coded input. Tag: S = sourced, A = assumption, D = derived. £m unless stated. Series columns F–J = 2026–2030.
A4: Input | B4: Unit | C4: Value | D4: Tag | E4: Source / note | F4: 2026 | G4: 2027 | H4: 2028 | I4: 2029 | J4: 2030
A6: Scenario (1 = Bear, 2 = Base, 3 = Bull)
A7: Scenario | B7: 1/2/3 | C7: 2 | D7: A | E7: Change this cell to flex the whole model.
F8: Bear | G8: Base | H8: Bull
A9: Retention adjustment | B9: % | C9: =CHOOSE(Inputs!$C$7,F9,G9,H9) | D9: A | F9: -0.018 | G9: 0 | H9: 0.007
A10: Workflows extra growth spread | B10: % | C10: =CHOOSE(Inputs!$C$7,F10,G10,H10) | D10: A | F10: -0.02 | G10: 0 | H10: 0.01
A11: Markets volume growth adjustment | B11: % | C11: =CHOOSE(Inputs!$C$7,F11,G11,H11) | D11: A | F11: -0.03 | G11: 0 | H11: 0.02
A12: ETF AUM growth adjustment | B12: % | C12: =CHOOSE(Inputs!$C$7,F12,G12,H12) | D12: A | F12: -0.06 | G12: 0 | H12: 0.04
A13: NTI spread shock (2027) | B13: % | C13: =CHOOSE(Inputs!$C$7,F13,G13,H13) | D13: A | F13: -0.2 | G13: 0 | H13: 0
A14: Divisional margin change per year | B14: % | C14: =CHOOSE(Inputs!$C$7,F14,G14,H14) | D14: A | F14: -0.004 | G14: 0 | H14: 0.002
A15: Terminal growth | B15: % | C15: =CHOOSE(Inputs!$C$7,F15,G15,H15) | D15: A | F15: 0.025 | G15: 0.03 | H15: 0.035
A17: Market data & FX
A18: Share price | B18: p | C18: 9510 | D18: S | E18: Alpha Vantage quote LSEG.LON, close 23 Oct 2026
A19: GBPUSD | B19: $ per £ | C19: 1.32 | D19: S | E19: Q3 2026 guidance FX
A20: EURGBP | B20: € per £ | C20: 1.17 | D20: S | E20: Q3 2026 guidance FX
A21: Opening shares | B21: m | C21: 510 | D21: S | E21: 31 Dec 2025, excl. treasury
A23: Q4 2026E reported growth vs Q4 2025 (2026E = 9M actual + Q4E)
A24: Q4 growth wf | B24: % | C24: 0.015 | D24: A | E24: Workflows; anchored on Q3 2026 reported growth
A25: Q4 growth df | B25: % | C25: 0.065 | D25: A | E25: Data & Feeds; anchored on Q3 2026 reported growth
A26: Q4 growth an | B26: % | C26: 0.05 | D26: A | E26: Analytics; anchored on Q3 2026 reported growth
A27: Q4 growth fs | B27: % | C27: 0.07 | D27: A | E27: FTSE Russell Subscription; anchored on Q3 2026 reported growth
A28: Q4 growth fa | B28: % | C28: 0.12 | D28: A | E28: FTSE Russell Asset-based; anchored on Q3 2026 reported growth
A29: Q4 growth ri | B29: % | C29: 0.09 | D29: A | E29: Risk Intelligence; anchored on Q3 2026 reported growth
A30: Q4 growth eq | B30: % | C30: 0.08 | D30: A | E30: Equities; anchored on Q3 2026 reported growth
A31: Q4 growth fido | B31: % | C31: 0.1 | D31: A | E31: Fixed Income, Derivatives & Other; anchored on Q3 2026 reported growth
A32: Q4 growth fx | B32: % | C32: 0.04 | D32: A | E32: FX; anchored on Q3 2026 reported growth
A33: Q4 growth otc | B33: % | C33: 0.12 | D33: A | E33: OTC Derivatives; anchored on Q3 2026 reported growth
A34: Q4 growth sr | B34: % | C34: 0.06 | D34: A | E34: Securities & Reporting; anchored on Q3 2026 reported growth
A35: Q4 growth ncc | B35: % | C35: 0 | D35: A | E35: Non-Cash Collateral; anchored on Q3 2026 reported growth
... A37: Q4 growth oth | B37: % | C37: 0 | D37: A | E37: Other; anchored on Q3 2026 reported growth
A39: Subscription engine: ASV growth = gross sales % + price/other – (1 – retention)
A40: Retention | B40: % | D40: A | E40: 2025A 92.4%; H1 2026 92.8% | G40: 0.928 | H40: 0.928 | I40: 0.928 | J40: 0.928
A41: Gross sales % | B41: % of sub. income | D41: D | E41: 2025: rolling gross sales £481m / subscription income £5,187m | G41: 0.093 | H41: 0.093 | I41: 0.092 | J41: 0.092
A42: Price & other | B42: % | D42: D | E42: 2025 implied: 5.9% ASV – 9.3% sales + 7.6% churn = 4.2% | G42: 0.04 | H42: 0.04 | I42: 0.04 | J42: 0.04
A43: Spread wf | B43: pp vs ASV | D43: A | E43: Workflows growth minus ASV growth (H1 2026 organic spreads) | G43: -0.03 | H43: -0.03 | I43: -0.03 | J43: -0.03
A44: Spread df | B44: pp vs ASV | D44: A | E44: Data & Feeds growth minus ASV growth (H1 2026 organic spreads) | G44: 0.012 | H44: 0.012 | I44: 0.012 | J44: 0.012
A45: Spread an | B45: pp vs ASV | D45: A | E45: Analytics growth minus ASV growth (H1 2026 organic spreads) | G45: 0 | H45: 0 | I45: 0 | J45: 0
A46: Spread fs | B46: pp vs ASV | D46: A | E46: FTSE Russell Subscription growth minus ASV growth (H1 2026 organic spreads) | G46: 0.005 | H46: 0.005 | I46: 0.005 | J46: 0.005
...

Sheet Divisions
A1: LSEG – Divisional build
A2: 2026E = 9M actual + Q4E (Quarterly). 2027E+ driven by ASV/retention, ETF AUM, Tradeweb ADV, SwapClear notional and cash collateral.
A4: £m unless stated | C4: 2023 | D4: 2024 | E4: 2025 | F4: 2026 | G4: 2027 | H4: 2028 | I4: 2029 | J4: 2030
C5: A | D5: A | E5: A | F5: E | G5: E | H5: E | I5: E | J5: E
A7: Subscription KPIs
A8: Revenue retention | E8: 0.924 | G8: =Inputs!$G$40+Inputs!$C$9 | H8: =Inputs!$H$40+Inputs!$C$9 | I8: =Inputs!$I$40+Inputs!$C$9 | J8: =Inputs!$J$40+Inputs!$C$9
A9: ASV growth | D9: 0.063 | E9: 0.059 | G9: =Inputs!$G$41+Inputs!$G$42-(1-G8) | H9: =Inputs!$H$41+Inputs!$H$42-(1-H8) | I9: =Inputs!$I$41+Inputs!$I$42-(1-I8) | J9: =Inputs!$J$41+Inputs!$J$42-(1-J8)
A11: Data & Analytics
A12: Workflows | D12: 1899 | E12: 1925 | F12: =Quarterly!$K$5 | G12: =F12*(1+G$9+Inputs!$G$43+Inputs!$C$10) | H12: =G12*(1+H$9+Inputs!$H$43+Inputs!$C$10) | I12: =H12*(1+I$9+Inputs!$I$43+Inputs!$C$10) | J12: =I12*(1+J$9+Inputs!$J$43+Inputs!$C$10)
A13: Data & Feeds | D13: 1740 | E13: 1822 | F13: =Quarterly!$K$6 | G13: =F13*(1+G$9+Inputs!$G$44) | H13: =G13*(1+H$9+Inputs!$H$44) | I13: =H13*(1+I$9+Inputs!$I$44) | J13: =I13*(1+J$9+Inputs!$J$44)
A14: Analytics | D14: 220 | E14: 231 | F14: =Quarterly!$K$7 | G14: =F14*(1+G$9+Inputs!$G$45) | H14: =G14*(1+H$9+Inputs!$H$45) | I14: =H14*(1+I$9+Inputs!$I$45) | J14: =I14*(1+J$9+Inputs!$J$45)
A15: Octus | F15: =IF(F$4=Inputs!$C$94,Inputs!$C$95/Inputs!$C$19*(1+Inputs!$C$96)^(F$4-2026),IF(F$4>Inputs!$C$94,E15*(1+Inputs!$C$96),0)) | G15: =IF(G$4=Inputs!$C$94,Inputs!$C$95/Inputs!$C$19*(1+Inputs!$C$96)^(G$4-2026),IF(G$4>Inputs!$C$94,F15*(1+Inputs!$C$96),0)) | H15: =IF(H$4=Inputs!$C$94,Inputs!$C$95/Inputs!$C$19*(1+Inputs!$C$96)^(H$4-2026),IF(H$4>Inputs!$C$94,G15*(1+Inputs!$C$96),0)) | I15: =IF(I$4=Inputs!$C$94,Inputs!$C$95/Inputs!$C$19*(1+Inputs!$C$96)^(I$4-2026),IF(I$4>Inputs!$C$94,H15*(1+Inputs!$C$96),0)) | J15: =IF(J$4=Inputs!$C$94,Inputs!$C$95/Inputs!$C$19*(1+Inputs!$C$96)^(J$4-2026),IF(J$4>Inputs!$C$94,I15*(1+Inputs!$C$96),0))
A16: Data & Analytics income | D16: =SUM(D12:D14) | E16: =SUM(E12:E14) | F16: =SUM(F12:F15) | G16: =SUM(G12:G15) | H16: =SUM(H12:H15) | I16: =SUM(I12:I15) | J16: =SUM(J12:J15)
A18: FTSE Russell
A19: Subscription | D19: 603 | E19: 630 | F19: =Quarterly!$K$8 | G19: =F19*(1+G$9+Inputs!$G$46) | H19: =G19*(1+H$9+Inputs!$H$46) | I19: =H19*(1+I$9+Inputs!$I$46) | J19: =I19*(1+J$9+Inputs!$J$46)
A20: Average ETF AUM ($bn) | F20: =Inputs!$C$50 | G20: =F20*(1+Inputs!$G$51+Inputs!$C$12) | H20: =G20*(1+Inputs!$H$51+Inputs!$C$12) | I20: =H20*(1+Inputs!$I$51+Inputs!$C$12) | J20: =I20*(1+Inputs!$J$51+Inputs!$C$12)
A21: Asset-based yield (bps) | F21: =Quarterly!$K$9*Inputs!$C$19/(F20*1000)*10000 | G21: =F21*(1+Inputs!$G$52) | H21: =G21*(1+Inputs!$H$52) | I21: =H21*(1+Inputs!$I$52) | J21: =I21*(1+Inputs!$J$52)
A22: Asset-based | D22: 308 | E22: 324 | F22: =Quarterly!$K$9 | G22: =G20*1000*G21/10000/Inputs!$C$19 | H22: =H20*1000*H21/10000/Inputs!$C$19 | I22: =I20*1000*I21/10000/Inputs!$C$19 | J22: =J20*1000*J21/10000/Inputs!$C$19
A23: FTSE Russell income | D23: =D19+D22 | E23: =E19+E22 | F23: =F19+F22 | G23: =G19+G22 | H23: =H19+H22 | I23: =I19+I22 | J23: =J19+J22
A25: Risk Intelligence
A26: Risk Intelligence | D26: 531 | E26: 579 | F26: =Quarterly!$K$10 | G26: =F26*(1+G$9+Inputs!$G$47) | H26: =G26*(1+H$9+Inputs!$H$47) | I26: =H26*(1+I$9+Inputs!$I$47) | J26: =I26*(1+J$9+Inputs!$J$47)
A27: Risk Intelligence income | D27: =D26 | E27: =E26 | F27: =F26 | G27: =G26 | H27: =H26 | I27: =I26 | J27: =J26
A29: Markets
A30: Equities | D30: 392 | E30: 412 | F30: =Quarterly!$K$11 | G30: =F30*(1+Inputs!$G$63+Inputs!$C$11) | H30: =G30*(1+Inputs!$H$63+Inputs!$C$11) | I30: =H30*(1+Inputs!$I$63+Inputs!$C$11) | J30: =I30*(1+Inputs!$J$63+Inputs!$C$11)
A31: Tradeweb ADV ($bn/day) | E31: 2625 | F31: =Inputs!$C$55 | G31: =F31*(1+Inputs!$G$56+Inputs!$C$11) | H31: =G31*(1+Inputs!$H$56+Inputs!$C$11) | I31: =H31*(1+Inputs!$I$56+Inputs!$C$11) | J31: =I31*(1+Inputs!$J$56+Inputs!$C$11)
A32: FIDO revenue per $bn ADV (£m) | E32: =E33/E31 | F32: =Quarterly!$K$12/F31 | G32: =F32*(1+Inputs!$G$57) | H32: =G32*(1+Inputs!$H$57) | I32: =H32*(1+Inputs!$I$57) | J32: =I32*(1+Inputs!$J$57)
A33: Fixed Income, Derivatives & Other | D33: 1334 | E33: 1539 | F33: =Quarterly!$K$12 | G33: =G31*G32 | H33: =H31*H32 | I33: =I31*I32 | J33: =J31*J32
A34: FX | D34: 260 | E34: 272 | F34: =Quarterly!$K$13 | G34: =F34*(1+Inputs!$G$64+Inputs!$C$11) | H34: =G34*(1+Inputs!$H$64+Inputs!$C$11) | I34: =H34*(1+Inputs!$I$64+Inputs!$C$11) | J34: =I34*(1+Inputs!$J$64+Inputs!$C$11)
A35: OTC Derivatives (SwapClear et al.) | D35: 582 | E35: 641 | F35: =Quarterly!$K$14 | G35: =F35*(1+Inputs!$G$58+Inputs!$C$11)*(1+Inputs!$G$59) | H35: =G35*(1+Inputs!$H$58+Inputs!$C$11)*(1+Inputs!$H$59) | I35: =H35*(1+Inputs!$I$58+Inputs!$C$11)*(1+Inputs!$I$59) | J35: =I35*(1+Inputs!$J$58+Inputs!$C$11)*(1+Inputs!$J$59)
A36: Securities & Reporting | D36: 235 | E36: 229 | F36: =Quarterly!$K$15 | G36: =F36*(1+Inputs!$G$65) | H36: =G36*(1+Inputs!$H$65) | I36: =H36*(1+Inputs!$I$65) | J36: =I36*(1+Inputs!$J$65)
A37: Non-Cash Collateral | D37: 111 | E37: 117 | F37: =Quarterly!$K$16 | G37: =F37*(1+Inputs!$G$66) | H37: =G37*(1+Inputs!$H$66) | I37: =H37*(1+Inputs!$I$66) | J37: =I37*(1+Inputs!$J$66)
A38: Average cash collateral (€bn) | D38: 109 | E38: 101.3 | F38: =Inputs!$C$60 | G38: =F38*(1+Inputs!$G$61) | H38: =G38*(1+Inputs!$H$61) | I38: =H38*(1+Inputs!$I$61) | J38: =I38*(1+Inputs!$J$61)
A39: Net treasury spread (bps) | D39: =D40*Inputs!$C$20/(D38*1000)*10000 | E39: =E40*Inputs!$C$20/(E38*1000)*10000 | F39: =Quarterly!$K$17*Inputs!$C$20/(F38*1000)*10000 | G39: =F39*(1+Inputs!$G$62+IF(G$4=2027,Inputs!$C$13,0)) | H39: =G39*(1+Inputs!$H$62+IF(H$4=2027,Inputs!$C$13,0)) | I39: =H39*(1+Inputs!$I$62+IF(I$4=2027,Inputs!$C$13,0)) | J39: =I39*(1+Inputs!$J$62+IF(J$4=2027,Inputs!$C$13,0))
A40: Net Treasury Income | D40: 266 | E40: 257 | F40: =Quarterly!$K$17 | G40: =G38*1000*G39/10000/Inputs!$C$20 | H40: =H38*1000*H39/10000/Inputs!$C$20 | I40: =I38*1000*I39/10000/Inputs!$C$20 | J40: =J38*1000*J39/10000/Inputs!$C$20
A41: Markets income | D41: =D30+D33+D34+D35+D36+D37+D40 | E41: =E30+E33+E34+E35+E36+E37+E40 | F41: =F30+F33+F34+F35+F36+F37+F40 | G41: =G30+G33+G34+G35+G36+G37+G40 | H41: =H30+H33+H34+H35+H36+H37+H40 | I41: =I30+I33+I34+I35+I36+I37+I40 | J41: =J30+J33+J34+J35+J36+J37+J40
A43: Other
A44: Other | D44: 13 | E44: 8 | F44: =Quarterly!$K$18 | G44: =F44*(1+Inputs!$G$67) | H44: =G44*(1+Inputs!$H$67) | I44: =H44*(1+Inputs!$I$67) | J44: =I44*(1+Inputs!$J$67)
A45: Other income | D45: =D44 | E45: =E44 | F45: =F44 | G45: =G44 | H45: =H44 | I45: =I44 | J45: =J44
A47: Group income
A48: Total income excl. recoveries | C48: 8009 | D48: =D16+D23+D27+D41+D45 | E48: =E16+E23+E27+E41+E45 | F48: =F16+F23+F27+F41+F45 | G48: =G16+G23+G27+G41+G45 | H48: =H16+H23+H27+H41+H45 | I48: =I16+I23+I27+I41+I45 | J48: =J16+J23+J27+J41+J45
...

Sheet Quarterly
A1: LSEG – Quarterly income by line (£m)
A2: Q1 2025–Q3 2026 sourced from company releases. Q4 2026E = Q4 2025 × (1 + Inputs growth). FY2026E feeds the Divisions sheet.
A4: Line | B4: Q1 25 | C4: Q2 25 | D4: Q3 25 | E4: Q4 25 | F4: Q1 26 | G4: Q2 26 | H4: Q3 26 | I4: Q4 26E | J4: FY25 (sum) | K4: FY26E | L4: FY26E growth | M4: Q4E growth
A5: Workflows | B5: 491 | C5: 477 | D5: 471 | E5: 481 | F5: 491 | G5: 489 | H5: 479 | I5: =E5*(1+Inputs!$C$24) | J5: =SUM(B5:E5) | K5: =SUM(F5:I5) | L5: =K5/J5-1 | M5: =I5/E5-1
A6: Data & Feeds | B6: 454 | C6: 453 | D6: 453 | E6: 466 | F6: 475 | G6: 486 | H6: 483 | I6: =E6*(1+Inputs!$C$25) | J6: =SUM(B6:E6) | K6: =SUM(F6:I6) | L6: =K6/J6-1 | M6: =I6/E6-1
A7: Analytics | B7: 59 | C7: 57 | D7: 58 | E7: 58 | F7: 59 | G7: 61 | H7: 61 | I7: =E7*(1+Inputs!$C$26) | J7: =SUM(B7:E7) | K7: =SUM(F7:I7) | L7: =K7/J7-1 | M7: =I7/E7-1
A8: FTSE Russell Subscription | B8: 155 | C8: 159 | D8: 157 | E8: 159 | F8: 160 | G8: 165 | H8: 169 | I8: =E8*(1+Inputs!$C$27) | J8: =SUM(B8:E8) | K8: =SUM(F8:I8) | L8: =K8/J8-1 | M8: =I8/E8-1
A9: FTSE Russell Asset-based | B9: 83 | C9: 75 | D9: 84 | E9: 82 | F9: 88 | G9: 91 | H9: 96 | I9: =E9*(1+Inputs!$C$28) | J9: =SUM(B9:E9) | K9: =SUM(F9:I9) | L9: =K9/J9-1 | M9: =I9/E9-1
A10: Risk Intelligence | B10: 143 | C10: 144 | D10: 144 | E10: 148 | F10: 153 | G10: 157 | H10: 160 | I10: =E10*(1+Inputs!$C$29) | J10: =SUM(B10:E10) | K10: =SUM(F10:I10) | L10: =K10/J10-1 | M10: =I10/E10-1
A11: Equities | B11: 102 | C11: 103 | D11: 102 | E11: 105 | F11: 114 | G11: 116 | H11: 112 | I11: =E11*(1+Inputs!$C$30) | J11: =SUM(B11:E11) | K11: =SUM(F11:I11) | L11: =K11/J11-1 | M11: =I11/E11-1
A12: Fixed Income, Derivatives & Other | B12: 394 | C12: 383 | D12: 375 | E12: 387 | F12: 452 | G12: 412 | H12: 428 | I12: =E12*(1+Inputs!$C$31) | J12: =SUM(B12:E12) | K12: =SUM(F12:I12) | L12: =K12/J12-1 | M12: =I12/E12-1
A13: FX | B13: 69 | C13: 70 | D13: 67 | E13: 66 | F13: 74 | G13: 71 | H13: 70 | I13: =E13*(1+Inputs!$C$32) | J13: =SUM(B13:E13) | K13: =SUM(F13:I13) | L13: =K13/J13-1 | M13: =I13/E13-1
A14: OTC Derivatives | B14: 161 | C14: 153 | D14: 160 | E14: 167 | F14: 183 | G14: 172 | H14: 186 | I14: =E14*(1+Inputs!$C$33) | J14: =SUM(B14:E14) | K14: =SUM(F14:I14) | L14: =K14/J14-1 | M14: =I14/E14-1
A15: Securities & Reporting | B15: 56 | C15: 59 | D15: 55 | E15: 59 | F15: 61 | G15: 63 | H15: 61 | I15: =E15*(1+Inputs!$C$34) | J15: =SUM(B15:E15) | K15: =SUM(F15:I15) | L15: =K15/J15-1 | M15: =I15/E15-1
A16: Non-Cash Collateral | B16: 27 | C16: 30 | D16: 30 | E16: 30 | F16: 29 | G16: 30 | H16: 27 | I16: =E16*(1+Inputs!$C$35) | J16: =SUM(B16:E16) | K16: =SUM(F16:I16) | L16: =K16/J16-1 | M16: =I16/E16-1
A17: Net Treasury Income | B17: 65 | C17: 63 | D17: 61 | E17: 68 | F17: 74 | G17: 69 | H17: 73 | I17: =E17*(1+Inputs!$C$36) | J17: =SUM(B17:E17) | K17: =SUM(F17:I17) | L17: =K17/J17-1 | M17: =I17/E17-1
A18: Other | B18: 2 | C18: 2 | D18: 2 | E18: 2 | F18: 2 | G18: 2 | H18: 2 | I18: =E18*(1+Inputs!$C$37) | J18: =SUM(B18:E18) | K18: =SUM(F18:I18) | L18: =K18/J18-1 | M18: =I18/E18-1
A19: Total income excl. recoveries | B19: =SUM(B5:B18) | C19: =SUM(C5:C18) | D19: =SUM(D5:D18) | E19: =SUM(E5:E18) | F19: =SUM(F5:F18) | G19: =SUM(G5:G18) | H19: =SUM(H5:H18) | I19: =SUM(I5:I18) | ... K19: =SUM(K5:K18) | L19: =K19/J19-1
A20: YoY growth (total) | F20: =F19/B19-1 | G20: =G19/C19-1 | H20: =H19/D19-1 | I20: =I19/E19-1
A22: Note: 2025 quarterly sums differ from reported FY by up to £5m per line (restatements/rounding); FY figures on Divisions use the reported FY.

Sheet Q3 2026 update
A1: Module: react to results – LSEG Q3 2026 trading update
A2: Pre-results model = Q3 estimated from each line's H1 2026 growth, no Octus. Post-results = Q3 actuals plus Octus. Snapshot from lseg/engine.py.
A4: Line | B4: Q3 26 expected | C4: Q3 26 actual | D4: Surprise £m | E4: Surprise %
A5: Workflows | B5: 476.83884 | C5: 479 | D5: 2.161157 | E5: 0.0045322588
A6: Data & Feeds | B6: 479.97023 | C6: 483 | D6: 3.0297685 | E6: 0.0063124091
A7: Analytics | B7: 60 | C7: 61 | D7: 1 | E7: 0.016666667
A8: FTSE Russell Subscription | B8: 162.5 | C8: 169 | D8: 6.5 | E8: 0.04
A9: FTSE Russell Asset-based | B9: 95.164557 | C9: 96 | D9: 0.83544304 | E9: 0.0087789306
A10: Risk Intelligence | B10: 155.54007 | C10: 160 | D10: 4.4599303 | E10: 0.028673835
A11: Equities | B11: 114.43902 | C11: 112 | D11: -2.4390244 | E11: -0.021312873
A12: Fixed Income, Derivatives & Other | B12: 416.98842 | C12: 428 | D12: 11.011583 | E12: 0.026407407
A13: FX | B13: 69.892086 | C13: 70 | D13: 0.10791367 | E13: 0.0015440041
A14: OTC Derivatives | B14: 180.89172 | C14: 186 | D14: 5.1082803 | E14: 0.028239437
A15: Securities & Reporting | B15: 59.304348 | C15: 61 | D15: 1.6956522 | E15: 0.028592375
A16: Non-Cash Collateral | B16: 31.052632 | C16: 27 | D16: -4.0526316 | E16: -0.13050847
... A18: Other | B18: 2 | C18: 2 | D18: 0 | E18: 0
A19: Total | B19: =SUM(B5:B18) | C19: =SUM(C5:C18) | D19: =SUM(D5:D18) | E19: =C19/B19-1
A22: Estimate revision | B22: Pre-results | C22: Post-results | D22: Change
A23: 2026E income excl. recoveries | B23: 9604.5454 | C23: 9638.815 | D23: =C23/B23-1
A24: 2026E adjusted EBITDA | B24: 4944.5647 | C24: 4963.917 | D24: =C24/B24-1
A25: 2026E adjusted EPS (p) | B25: 488.69545 | C25: 490.7592 | D25: =C25/B25-1
A26: 2027E income excl. recoveries | B26: 9935.8622 | C26: 10234.085 | D26: =C26/B26-1
A27: 2027E adjusted EBITDA | B27: 5147.8795 | C27: 5273.1007 | D27: =C27/B27-1
A28: 2027E adjusted EPS (p) | B28: 533.73808 | C28: 537.56847 | D28: =C28/B28-1
A29: 2028E income excl. recoveries | B29: 10430.774 | C29: 10762.389 | D29: =C29/B29-1
A30: 2028E adjusted EBITDA | B30: 5447.1008 | C30: 5586.1348 | D30: =C30/B30-1
A31: 2028E adjusted EPS (p) | B31: 589.8932 | C31: 585.59491 | D31: =C31/B31-1
A32: DCF value (p) | B32: 9521.6725 | C32: 9343.4849 | D32: =C32/B32-1
A35: DCF value bridge (p)
A36: Pre-results | B36: 9521.6725
A37: Q3 beat and guidance | B37: 55.529762
A38: Octus at $3.5bn (40% margin, 12% growth assumed) | B38: -233.71729
A39: Post-results | B39: 9343.4849

Sheet Model
A1: LSEG – Integrated model
A2: Income and EBITDA link from Divisions. Historical cells are sourced (blue); forecasts are formulas.
A4: £m unless stated | C4: 2023 | D4: 2024 | E4: 2025 | F4: 2026 | G4: 2027 | H4: 2028 | I4: 2029 | J4: 2030
C5: A | D5: A | E5: A | F5: E | G5: E | H5: E | I5: E | J5: E
A7: Profit & loss (adjusted)
A8: Total income excl. recoveries | C8: =Divisions!C48 | D8: =Divisions!D48 | E8: =Divisions!E48 | F8: =Divisions!F48 | G8: =Divisions!G48 | H8: =Divisions!H48 | I8: =Divisions!I48 | J8: =Divisions!J48
A9: Recoveries | C9: 370 | D9: 364 | E9: 360 | F9: =E9*(1+Inputs!$C$68) | G9: =F9*(1+Inputs!$C$68) | H9: =G9*(1+Inputs!$C$68) | I9: =H9*(1+Inputs!$C$68) | J9: =I9*(1+Inputs!$C$68)
A10: Adjusted EBITDA | C10: =Divisions!C66 | D10: =Divisions!D66 | E10: =Divisions!E66 | F10: =Divisions!F66 | G10: =Divisions!G66 | H10: =Divisions!H66 | I10: =Divisions!I66 | J10: =Divisions!J66
A11: margin | C11: =C10/C8 | D11: =D10/D8 | E11: =E10/E8 | F11: =F10/F8 | G11: =G10/G8 | H11: =H10/H8 | I11: =I10/I8 | J11: =J10/J8
A12: Adjusted D&A | C12: 915 | D12: 983 | E12: 1017 | F12: =F8*Inputs!$F$78 | G12: =G8*Inputs!$G$78 | H12: =H8*Inputs!$H$78 | I12: =I8*Inputs!$I$78 | J12: =J8*Inputs!$J$78
A13: Adjusted operating profit | C13: =C10-C12 | D13: =D10-D12 | E13: =E10-E12 | F13: =F10-F12 | G13: =G10-G12 | H13: =H10-H12 | I13: =I10-I12 | J13: =J10-J12
A14: Net finance expense | D14: 195 | E14: 179 | F14: =(E51-E48)*Inputs!$C$85+IF(F$4>=Inputs!$C$94,Inputs!$C$93/Inputs!$C$19*(Inputs!$C$99-Inputs!$C$85),0) | G14: =(F51-F48)*Inputs!$C$85+IF(G$4>=Inputs!$C$94,Inputs!$C$93/Inputs!$C$19*(Inputs!$C$99-Inputs!$C$85),0) | H14: =(G51-G48)*Inputs!$C$85+IF(H$4>=Inputs!$C$94,Inputs!$C$93/Inputs!$C$19*(Inputs!$C$99-Inputs!$C$85),0) | I14: =(H51-H48)*Inputs!$C$85+IF(I$4>=Inputs!$C$94,Inputs!$C$93/Inputs!$C$19*(Inputs!$C$99-Inputs!$C$85),0) | J14: =(I51-I48)*Inputs!$C$85+IF(J$4>=Inputs!$C$94,Inputs!$C$93/Inputs!$C$19*(Inputs!$C$99-Inputs!$C$85),0)
A15: Adjusted profit before tax | D15: =D13-D14 | E15: =E13-E14 | F15: =F13-F14 | G15: =G13-G14 | H15: =H13-H14 | I15: =I13-I14 | J15: =J13-J14
A16: Tax | F16: =F15*Inputs!$C$82 | G16: =G15*Inputs!$C$82 | H16: =H15*Inputs!$C$82 | I16: =I15*Inputs!$C$82 | J16: =J15*Inputs!$C$82
A17: Adjusted net income | F17: =F15-F16 | G17: =G15-G16 | H17: =H15-H16 | I17: =I15-I16 | J17: =J15-J16
A18: Non-controlling interests (Tradeweb) | D18: 323 | E18: 334 | F18: =F17*Inputs!$C$83 | G18: =G17*Inputs!$C$83 | H18: =H17*Inputs!$C$83 | I18: =I17*Inputs!$C$83 | J18: =J17*Inputs!$C$83
A19: Adjusted net income to shareholders | F19: =F17-F18 | G19: =G17-G18 | H19: =H17-H18 | I19: =I17-I18 | J19: =J17-J18
A20: Adjusted EPS (p) | C20: 323.9 | D20: 363.5 | E20: 420.6 | F20: =F19/F44*100 | G20: =G19/G44*100 | H20: =H19/H44*100 | I20: =I19/I44*100 | J20: =J19/J44*100
A21: EPS growth | D21: =D20/C20-1 | E21: =E20/D20-1 | F21: =F20/E20-1 | G21: =G20/F20-1 | H21: =H20/G20-1 | I21: =I20/H20-1 | J21: =J20/I20-1
A23: Reported bridge
A24: Purchased intangible amortisation (existing) | D24: 1499 | E24: 1221 | F24: =Inputs!$C$80 | G24: =F24*(1-Inputs!$C$81) | H24: =G24*(1-Inputs!$C$81) | I24: =H24*(1-Inputs!$C$81) | J24: =I24*(1-Inputs!$C$81)
A25: Octus purchased amortisation | F25: =IF(F$4>=Inputs!$C$94,Inputs!$C$98,0) | G25: =IF(G$4>=Inputs!$C$94,Inputs!$C$98,0) | H25: =IF(H$4>=Inputs!$C$94,Inputs!$C$98,0) | I25: =IF(I$4>=Inputs!$C$94,Inputs!$C$98,0) | J25: =IF(J$4>=Inputs!$C$94,Inputs!$C$98,0)
A26: Total purchased amortisation | F26: =F24+F25 | G26: =G24+G25 | H26: =H24+H25 | I26: =I24+I25 | J26: =J24+J25
A27: Reported net income (total) | F27: =(F15-F26)*(1-Inputs!$C$82) | G27: =(G15-G26)*(1-Inputs!$C$82) | H27: =(H15-H26)*(1-Inputs!$C$82) | I27: =(I15-I26)*(1-Inputs!$C$82) | J27: =(J15-J26)*(1-Inputs!$C$82)
A29: Cash flow
A30: Capex | D30: 957 | E30: 919 | F30: =F8*Inputs!$F$79 | G30: =G8*Inputs!$G$79 | H30: =H8*Inputs!$H$79 | I30: =I8*Inputs!$I$79 | J30: =J8*Inputs!$J$79
A31: Other cash items (leases, WC, non-underlying) | F31: =F10*Inputs!$C$86 | G31: =G10*Inputs!$C$86 | H31: =H10*Inputs!$C$86 | I31: =I10*Inputs!$C$86 | J31: =J10*Inputs!$C$86
A32: Equity free cash flow | C32: 1800 | D32: 2184 | E32: 2445 | F32: =F10-F30-F14-F16-F31 | G32: =G10-G30-G14-G16-G31 | H32: =H10-H30-H14-H16-H31 | I32: =I10-I30-I14-I16-I31 | J32: =J10-J30-J14-J16-J31
A33: Acquisitions (Octus) | F33: =IF(F$4=Inputs!$C$94,Inputs!$C$93/Inputs!$C$19,0) | G33: =IF(G$4=Inputs!$C$94,Inputs!$C$93/Inputs!$C$19,0) | H33: =IF(H$4=Inputs!$C$94,Inputs!$C$93/Inputs!$C$19,0) | I33: =IF(I$4=Inputs!$C$94,Inputs!$C$93/Inputs!$C$19,0) | J33: =IF(J$4=Inputs!$C$94,Inputs!$C$93/Inputs!$C$19,0)
A34: New debt raised | F34: =F33 | G34: =G33 | H34: =H33 | I34: =I33 | J34: =J33
A35: Dividends paid | F35: =F45*F41/100 | G35: =G45*G41/100 | H35: =H45*H41/100 | I35: =I45*I41/100 | J35: =J45*J41/100
A36: Dividends to NCI | F36: =F18*Inputs!$C$84 | G36: =G18*Inputs!$C$84 | H36: =H18*Inputs!$C$84 | I36: =I18*Inputs!$C$84 | J36: =J18*Inputs!$C$84
A37: Share buybacks | C37: 1200 | D37: 1052 | E37: 2152 | F37: =IF(ISNUMBER(Inputs!$F$88),Inputs!$F$88,MAX(0,(F32-F35-F36)*Inputs!$C$89)) | G37: =IF(ISNUMBER(Inputs!$G$88),Inputs!$G$88,MAX(0,(G32-G35-G36)*Inputs!$C$89)) | H37: =IF(ISNUMBER(Inputs!$H$88),Inputs!$H$88,MAX(0,(H32-H35-H36)*Inputs!$C$89)) | I37: =IF(ISNUMBER(Inputs!$I$88),Inputs!$I$88,MAX(0,(I32-I35-I36)*Inputs!$C$89)) | J37: =IF(ISNUMBER(Inputs!$J$88),Inputs!$J$88,MAX(0,(J32-J35-J36)*Inputs!$C$89))
A38: Net change in cash | F38: =F32-F33+F34-F35-F36-F37 | G38: =G32-G33+G34-G35-G36-G37 | H38: =H32-H33+H34-H35-H36-H37 | I38: =I32-I33+I34-I35-I36-I37 | J38: =J32-J33+J34-J35-J36-J37
A40: Shares & returns
A41: Opening shares (m) | F41: =Inputs!$C$21 | G41: =F43 | H41: =G43 | I41: =H43 | J41: =I43
A42: Average buyback price (p) | F42: =Inputs!$C$18*(1+Inputs!$C$90)^(0+0.5) | G42: =Inputs!$C$18*(1+Inputs!$C$90)^(1+0.5) | H42: =Inputs!$C$18*(1+Inputs!$C$90)^(2+0.5) | I42: =Inputs!$C$18*(1+Inputs!$C$90)^(3+0.5) | J42: =Inputs!$C$18*(1+Inputs!$C$90)^(4+0.5)
A43: Closing shares (m) | F43: =F41-F37/F42*100 | G43: =G41-G37/G42*100 | H43: =H41-H37/H42*100 | I43: =I41-I37/I42*100 | J43: =J41-J37/J42*100
A44: Average shares (m) | D44: 532 | E44: 524 | F44: =(F41+F43)/2 | G44: =(G41+G43)/2 | H44: =(H41+H43)/2 | I44: =(I41+I43)/2 | J44: =(J41+J43)/2
A45: DPS (p) | C45: 115 | D45: 130 | E45: 150 | F45: =F19/F41*100*Inputs!$C$87 | G45: =G19/G41*100*Inputs!$C$87 | H45: =H19/H41*100*Inputs!$C$87 | I45: =I19/I41*100*Inputs!$C$87 | J45: =J19/J41*100*Inputs!$C$87
...

Sheet DCF
A1: LSEG – DCF (valuation date 31 Dec 2026, mid-year convention)
A3: Cost of equity | B3: =Inputs!$C$102+Inputs!$C$103*Inputs!$C$104
A4: After-tax cost of debt | B4: =Inputs!$C$105*(1-Inputs!$C$82)
A5: WACC | B5: =(1-Inputs!$C$106)*B3+Inputs!$C$106*B4
A6: Terminal growth | B6: =Inputs!$C$15
A8: Year | B8: 2027 | C8: 2028 | D8: 2029 | E8: 2030
A9: Period | B9: 1 | C9: 2 | D9: 3 | E9: 4
A10: Unlevered FCF | B10: =Model!G58 | C10: =Model!H58 | D10: =Model!I58 | E10: =Model!J58
A11: Discount factor | B11: =1/(1+$B$5)^(B9-0.5) | C11: =1/(1+$B$5)^(C9-0.5) | D11: =1/(1+$B$5)^(D9-0.5) | E11: =1/(1+$B$5)^(E9-0.5)
A12: PV of FCF | B12: =B10*B11 | C12: =C10*C11 | D12: =D10*D11 | E12: =E10*E11
D14: Fair value (p): WACC (down) × terminal growth (across)
A15: Sum of PV of FCF | B15: =SUM(B12:E12) | E15: 0.02 | F15: 0.025 | G15: 0.03 | H15: 0.035 | I15: 0.04
A16: Terminal value (Gordon) | B16: =E10*(1+B6)/(B5-B6) | D16: =$B$5+-0.01 | E16: =(SUMPRODUCT($B$10:$E$10/(1+$D16)^($B$9:$E$9-0.5))+$E$10*(1+E$15)/($D16-E$15)/(1+$D16)^($E$9-0.5)+$B$19+$B$20)/$B$22*100 | F16: =(SUMPRODUCT($B$10:$E$10/(1+$D16)^($B$9:$E$9-0.5))+$E$10*(1+F$15)/($D16-F$15)/(1+$D16)^($E$9-0.5)+$B$19+$B$20)/$B$22*100 | G16: =(SUMPRODUCT($B$10:$E$10/(1+$D16)^($B$9:$E$9-0.5))+$E$10*(1+G$15)/($D16-G$15)/(1+$D16)^($E$9-0.5)+$B$19+$B$20)/$B$22*100 | H16: =(SUMPRODUCT($B$10:$E$10/(1+$D16)^($B$9:$E$9-0.5))+$E$10*(1+H$15)/($D16-H$15)/(1+$D16)^($E$9-0.5)+$B$19+$B$20)/$B$22*100 | I16: =(SUMPRODUCT($B$10:$E$10/(1+$D16)^($B$9:$E$9-0.5))+$E$10*(1+I$15)/($D16-I$15)/(1+$D16)^($E$9-0.5)+$B$19+$B$20)/$B$22*100
A17: PV of terminal value | B17: =B16/(1+B5)^(E9-0.5) | D17: =$B$5+-0.005 | E17: =(SUMPRODUCT($B$10:$E$10/(1+$D17)^($B$9:$E$9-0.5))+$E$10*(1+E$15)/($D17-E$15)/(1+$D17)^($E$9-0.5)+$B$19+$B$20)/$B$22*100 | F17: =(SUMPRODUCT($B$10:$E$10/(1+$D17)^($B$9:$E$9-0.5))+$E$10*(1+F$15)/($D17-F$15)/(1+$D17)^($E$9-0.5)+$B$19+$B$20)/$B$22*100 | G17: =(SUMPRODUCT($B$10:$E$10/(1+$D17)^($B$9:$E$9-0.5))+$E$10*(1+G$15)/($D17-G$15)/(1+$D17)^($E$9-0.5)+$B$19+$B$20)/$B$22*100 | H17: =(SUMPRODUCT($B$10:$E$10/(1+$D17)^($B$9:$E$9-0.5))+$E$10*(1+H$15)/($D17-H$15)/(1+$D17)^($E$9-0.5)+$B$19+$B$20)/$B$22*100 | I17: =(SUMPRODUCT($B$10:$E$10/(1+$D17)^($B$9:$E$9-0.5))+$E$10*(1+I$15)/($D17-I$15)/(1+$D17)^($E$9-0.5)+$B$19+$B$20)/$B$22*100
A18: Enterprise value | B18: =B15+B17 | D18: =$B$5+0 | E18: =(SUMPRODUCT($B$10:$E$10/(1+$D18)^($B$9:$E$9-0.5))+$E$10*(1+E$15)/($D18-E$15)/(1+$D18)^($E$9-0.5)+$B$19+$B$20)/$B$22*100 | F18: =(SUMPRODUCT($B$10:$E$10/(1+$D18)^($B$9:$E$9-0.5))+$E$10*(1+F$15)/($D18-F$15)/(1+$D18)^($E$9-0.5)+$B$19+$B$20)/$B$22*100 | G18: =(SUMPRODUCT($B$10:$E$10/(1+$D18)^($B$9:$E$9-0.5))+$E$10*(1+G$15)/($D18-G$15)/(1+$D18)^($E$9-0.5)+$B$19+$B$20)/$B$22*100 | H18: =(SUMPRODUCT($B$10:$E$10/(1+$D18)^($B$9:$E$9-0.5))+$E$10*(1+H$15)/($D18-H$15)/(1+$D18)^($E$9-0.5)+$B$19+$B$20)/$B$22*100 | I18: =(SUMPRODUCT($B$10:$E$10/(1+$D18)^($B$9:$E$9-0.5))+$E$10*(1+I$15)/($D18-I$15)/(1+$D18)^($E$9-0.5)+$B$19+$B$20)/$B$22*100
A19: Less: net debt (end-2026) | B19: =-Model!F54 | D19: =$B$5+0.005 | E19: =(SUMPRODUCT($B$10:$E$10/(1+$D19)^($B$9:$E$9-0.5))+$E$10*(1+E$15)/($D19-E$15)/(1+$D19)^($E$9-0.5)+$B$19+$B$20)/$B$22*100 | F19: =(SUMPRODUCT($B$10:$E$10/(1+$D19)^($B$9:$E$9-0.5))+$E$10*(1+F$15)/($D19-F$15)/(1+$D19)^($E$9-0.5)+$B$19+$B$20)/$B$22*100 | G19: =(SUMPRODUCT($B$10:$E$10/(1+$D19)^($B$9:$E$9-0.5))+$E$10*(1+G$15)/($D19-G$15)/(1+$D19)^($E$9-0.5)+$B$19+$B$20)/$B$22*100 | H19: =(SUMPRODUCT($B$10:$E$10/(1+$D19)^($B$9:$E$9-0.5))+$E$10*(1+H$15)/($D19-H$15)/(1+$D19)^($E$9-0.5)+$B$19+$B$20)/$B$22*100 | I19: =(SUMPRODUCT($B$10:$E$10/(1+$D19)^($B$9:$E$9-0.5))+$E$10*(1+I$15)/($D19-I$15)/(1+$D19)^($E$9-0.5)+$B$19+$B$20)/$B$22*100
A20: Less: Tradeweb minority at market value | B20: =-Inputs!$C$111*Inputs!$C$112*(1-Inputs!$C$114)/Inputs!$C$19 | D20: =$B$5+0.01 | E20: =(SUMPRODUCT($B$10:$E$10/(1+$D20)^($B$9:$E$9-0.5))+$E$10*(1+E$15)/($D20-E$15)/(1+$D20)^($E$9-0.5)+$B$19+$B$20)/$B$22*100 | F20: =(SUMPRODUCT($B$10:$E$10/(1+$D20)^($B$9:$E$9-0.5))+$E$10*(1+F$15)/($D20-F$15)/(1+$D20)^($E$9-0.5)+$B$19+$B$20)/$B$22*100 | G20: =(SUMPRODUCT($B$10:$E$10/(1+$D20)^($B$9:$E$9-0.5))+$E$10*(1+G$15)/($D20-G$15)/(1+$D20)^($E$9-0.5)+$B$19+$B$20)/$B$22*100 | H20: =(SUMPRODUCT($B$10:$E$10/(1+$D20)^($B$9:$E$9-0.5))+$E$10*(1+H$15)/($D20-H$15)/(1+$D20)^($E$9-0.5)+$B$19+$B$20)/$B$22*100 | I20: =(SUMPRODUCT($B$10:$E$10/(1+$D20)^($B$9:$E$9-0.5))+$E$10*(1+I$15)/($D20-I$15)/(1+$D20)^($E$9-0.5)+$B$19+$B$20)/$B$22*100
A21: Equity value | B21: =B18+B19+B20
A22: Shares (end-2026, m) | B22: =Model!F43
A23: Fair value per share (p) | B23: =B21/B22*100 | D23: Beta check
A24: Current share price (p) | B24: =Inputs!$C$18 | D24: Observed 5y beta | E24: =Inputs!$C$107
A25: Upside / (downside) | B25: =B23/B24-1 | D25: Blume-adjusted | E25: =Inputs!$C$108
A26: TV as % of EV | B26: =B17/B18 | D26: Used in WACC | E26: =Inputs!$C$103
A27: Implied TV / 2030E EBITDA | B27: =B16/Model!J10
A28: 2027E P/E at current price | B28: =B24/Model!G20 | D28: DCF value (p) by beta, base case (engine snapshot)
D29: Beta | E29: 0.6 | F29: 0.85 | G29: 1
D30: Value (p) | E30: 12752.989 | F30: 9343.4849 | G30: 7879.7494

Sheet SOTP
A1: LSEG – Sum of the parts (forward P/E basis, 2026E earnings mix)
A2: Each division's share of shareholder earnings × its peer median forward P/E → blended P/E × LSEG forward EPS (same data source as comps).
A4: Division | B4: EBITDA 2026E | C4: D&A alloc. | D4: EBIT | E4: Interest alloc. | F4: Tax | G4: NCI | H4: Earnings | I4: Weight | J4: Peers | K4: Peer median P/E | L4: Weighted P/E
A5: Data & Analytics | B5: =Divisions!F57 | C5: =Model!F12*574/1017 | D5: =B5-C5 | E5: =Model!F14*D5/SUM($D$5:$D$8) | F5: =(D5-E5)*Inputs!$C$82 | G5: 0 | H5: =D5-E5-F5-G5 | I5: =H5/SUM($H$5:$H$8) | J5: FDS, SPGI, REL.L, EXPN.L | K5: =MEDIAN(Comps!G8,Comps!G5,Comps!G9,Comps!G10) | L5: =I5*K5
A6: FTSE Russell | B6: =Divisions!F59 | C6: =Model!F12*89/1017 | D6: =B6-C6 | E6: =Model!F14*D6/SUM($D$5:$D$8) | F6: =(D6-E6)*Inputs!$C$82 | G6: 0 | H6: =D6-E6-F6-G6 | I6: =H6/SUM($H$5:$H$8) | J6: MSCI, SPGI | K6: =MEDIAN(Comps!G7,Comps!G5) | L6: =I6*K6
A7: Risk Intelligence | B7: =Divisions!F61 | C7: =Model!F12*48/1017 | D7: =B7-C7 | E7: =Model!F14*D7/SUM($D$5:$D$8) | F7: =(D7-E7)*Inputs!$C$82 | G7: 0 | H7: =D7-E7-F7-G7 | I7: =H7/SUM($H$5:$H$8) | J7: EXPN.L, REL.L, MCO | K7: =MEDIAN(Comps!G10,Comps!G9,Comps!G6) | L7: =I7*K7
A8: Markets | B8: =Divisions!F63 | C8: =Model!F12*306/1017 | D8: =B8-C8 | E8: =Model!F14*D8/SUM($D$5:$D$8) | F8: =(D8-E8)*Inputs!$C$82 | G8: =Model!F18 | H8: =D8-E8-F8-G8 | I8: =H8/SUM($H$5:$H$8) | J8: ICE, CME, NDAQ, DB1.DE, ENX.PA | K8: =MEDIAN(Comps!G11,Comps!G13,Comps!G12,Comps!G14,Comps!G15) | L8: =I8*K8
A10: Blended peer P/E | B10: =SUM(L5:L8)
A11: LSEG forward P/E (same source) | B11: =Comps!G22
A12: LSEG forward EPS implied by source (p) | B12: =Comps!B24/Comps!G22
A13: SOTP value per share (p) | B13: =B10*B12
A14: Upside vs price on same source | B14: =B13/Comps!B24-1
A16: EV/EBITDA SOTP not used: third-party trailing EBITDA definitions differ (LSEG shows 17.4x on the source vs c.13x on adjusted EBITDA).

Sheet Stub ex-Tradeweb
A1: LSEG excluding its Tradeweb stake
A2: Tradeweb is listed. Remove LSEG's 51.2% stake at market value and see what the rest of the group costs, on the same forward-earnings source as the comps.
A5: LSEG market cap (£m) | B5: =Comps!B24*Inputs!$C$115/100
A6: Tradeweb market cap (£m) | B6: =Inputs!$C$111*Inputs!$C$112/Inputs!$C$19
A7: LSEG stake in Tradeweb (£m) | B7: =B6*Inputs!$C$114
A8: as % of LSEG market cap | B8: =B7/B5
A9: Stub value: LSEG ex-Tradeweb (£m) | B9: =B5-B7
A10: LSEG forward earnings (£m) | B10: =B5/Comps!G22
A11: Tradeweb forward earnings attributable to LSEG (£m) | B11: =B6/Inputs!$C$113*Inputs!$C$114
A12: Stub forward earnings (£m) | B12: =B10-B11
A13: Stub forward P/E | B13: =B9/B12
A14: LSEG group forward P/E | B14: =Comps!G22
A15: FactSet forward P/E | B15: =Comps!G8
A16: Data & analytics peer median | B16: =SOTP!K5
A17: Stub discount to data & analytics peers | B17: =B13/B16-1
A19: Read: the rest of LSEG (Data & Analytics, FTSE Russell, Risk Intelligence, LCH, equities) costs less than FactSet on forward earnings.

Sheet Valuation history
A1: LSEG trailing P/E, Jan 2022 – Oct 2026
A2: Month-end price ÷ LTM adjusted EPS (interpolated between reported half and full years; Dec 2026 = model). Prices: Alpha Vantage.
A4: Month | B4: Price (p) | C4: LTM adj EPS (p) | D4: Trailing P/E | E4: 5y average | H4: Current | I4: =D62
A5: 2022-01 | B5: 7220 | C5: 276.18333 | D5: =B5/C5 | E5: =AVERAGE($D$5:$D$62) | H5: 5y average | I5: =AVERAGE(D5:D62)
A6: 2022-02 | B6: 6574 | C6: 279.96667 | D6: =B6/C6 | E6: =AVERAGE($D$5:$D$62) | H6: 5y low | I6: =MIN(D5:D62)
A7: 2022-03 | B7: 7966 | C7: 283.75 | D7: =B7/C7 | E7: =AVERAGE($D$5:$D$62) | H7: 5y high | I7: =MAX(D5:D62)
A8: 2022-04 | B8: 7916 | C8: 287.53333 | D8: =B8/C8 | E8: =AVERAGE($D$5:$D$62) | H8: Percentile of current | I8: =PERCENTRANK(D5:D62,D62)
A9: 2022-05 | B9: 7402 | C9: 291.31667 | D9: =B9/C9 | E9: =AVERAGE($D$5:$D$62)
A10: 2022-06 | B10: 7632 | C10: 295.1 | D10: =B10/C10 | E10: =AVERAGE($D$5:$D$62)
A11: 2022-07 | B11: 7998 | C11: 298.88333 | D11: =B11/C11 | E11: =AVERAGE($D$5:$D$62)
A12: 2022-08 | B12: 8102 | C12: 302.66667 | D12: =B12/C12 | E12: =AVERAGE($D$5:$D$62)
A13: 2022-09 | B13: 7628 | C13: 306.45 | D13: =B13/C13 | E13: =AVERAGE($D$5:$D$62)
A14: 2022-10 | B14: 7566 | C14: 310.23333 | D14: =B14/C14 | E14: =AVERAGE($D$5:$D$62)
A15: 2022-11 | B15: 8248 | C15: 314.01667 | D15: =B15/C15 | E15: =AVERAGE($D$5:$D$62)
A16: 2022-12 | B16: 7136 | C16: 317.8 | D16: =B16/C16 | E16: =AVERAGE($D$5:$D$62)
A17: 2023-01 | B17: 7406 | C17: 318.30833 | D17: =B17/C17 | E17: =AVERAGE($D$5:$D$62)
A18: 2023-02 | B18: 7432 | C18: 318.81667 | D18: =B18/C18 | E18: =AVERAGE($D$5:$D$62)
A19: 2023-03 | B19: 7868 | C19: 319.325 | D19: =B19/C19 | E19: =AVERAGE($D$5:$D$62)
A20: 2023-04 | B20: 8346 | C20: 319.83333 | D20: =B20/C20 | E20: =AVERAGE($D$5:$D$62)
... A62: 2026-10 | B62: 9510 | C62: 479.3728 | D62: =B62/C62 | E62: =AVERAGE($D$5:$D$62)

Sheet Industry evidence
A1: What third-party data says about AI and market-data demand
A2: Credible industry studies and filings, Apr–Oct 2026. These inform the retention and scenario assumptions; they are not inputs to formulas.
A4: Source | B4: Date | C4: Sample | D4: Finding | E4: Read for LSEG | F4: Link
A5: Burton-Taylor (TP ICAP), via FOW | B5: 8 Apr 2026 | C5: Industry spend data | D5: Global financial market data spend reached $49.2bn in 2025, up 6.5%; AI, automated trading and volatility outweighed cost pressure. | E5: Demand for data is still growing. | F5: https://www.fow.com/insights/market-data-spend-hits-usd49-2bn-as-ai-volatility-and-algos-drive-growth
A6: Expand Research (BCG), via A-Team Insight | B6: 20 Oct 2026 | C6: Industry spend data | D6: Market and reference data spend passed $50bn; a further 7% rise expected in 2026. Data teams manage 34% more vendors than four years ago. | E6: Spend growth is broadening, not shrinking. | F6: https://a-teaminsight.com/blog/substantive-research-finds-ai-driving-market-data-costs-higher-as-investment-research-budgets-stall/
A7: Crisil Coalition Greenwich and SIX, Market Data Study | B7: 13 Oct 2026 | C7: 73 buy- and sell-side institutions | D7: Market data spending could rise by more than 50% by 2027, driven largely by AI adoption; licences built for human users are mismatched to AI use. | E7: AI increases data consumption and gives data owners pricing power. | F7: https://fintech.garden/news/2026-10-13-ai-expected-to-push-market-data-costs-up-more-than-50-by-2027-study-finds/
A8: Substantive Research, via A-Team Insight | B8: 20 Oct 2026 | C8: 50 asset managers, c.$20trn AUM | D8: AI-related charges in 2026 vendor proposals ranged from $30k to $1m; some agreements could rise up to 50% in 2027. Research budgets rose only 0.4% in H1 2026; AI research tooling spend rose 40%. | E8: Budgets are tight, so money moves from people and screens to data and AI tooling. | F8: https://a-teaminsight.com/blog/substantive-research-finds-ai-driving-market-data-costs-higher-as-investment-research-budgets-stall/
A9: FactSet Q4 FY2026 results (8-K) | B9: 30 Sep 2026 | C9: Company filing | D9: Organic ASV +7.0% to $2.57bn; ASV retention above 95%; AI solutions ASV more than doubled. FY27 guide: organic ASV +5.0% to 6.5%. | E9: Even the purest 'AI loser' is not losing customers. Also a reason not to short it. | F9: https://www.sec.gov/Archives/edgar/data/0001013237/000162828026063888/fdsq42026earningsrelease.htm

Sheet Trackers
A1: Trackers: hiring mix and the Tradeweb stub
A2: Data in /data, refreshed every Monday by .github/workflows/refresh-data.yml (Workday career sites; weekly prices).
A4: Open roles by function, snapshot 2026-10-25
A5: Function | B5: LSEG | C5: LSEG % | D5: FactSet | E5: FactSet %
A6: AI & data science | B6: 49 | C6: =B6/B14 | D6: 3 | E6: =D6/D14
A7: Sales & client | B7: 87 | C7: =B7/B14 | D7: 25 | E7: =D7/D14
A8: Engineering | B8: 286 | C8: =B8/B14 | D8: 29 | E8: =D8/D14
A9: Content & data ops | B9: 79 | C9: =B9/B14 | D9: 9 | E9: =D9/D14
A10: Product | B10: 24 | C10: =B10/B14 | D10: 4 | E10: =D10/D14
A11: Operations | B11: 54 | C11: =B11/B14 | D11: 2 | E11: =D11/D14
A12: Corporate | B12: 36 | C12: =B12/B14 | D12: 5 | E12: =D12/D14
A13: Other | B13: 53 | C13: =B13/B14 | D13: 16 | E13: =D13/D14
A14: Total | B14: =SUM(B6:B13) | D14: =SUM(D6:D13)
A16: Weekly: Tradeweb stake as % of LSEG market cap, and LSEG vs FactSet relative price in GBP (Jan 2024 = 100)
A17: Week | B17: LSEG (p) | C17: Tradeweb ($) | D17: FactSet ($) | E17: GBPUSD | F17: Tradeweb stake % of LSEG | G17: LSEG vs FactSet (rebased)
A18: 2024-01-01 | B18: 8980 | C18: 93 | D18: 456.57999 | E18: 1.2725998 | F18: 0.18226466 | G18: 100
A19: 2024-01-08 | B19: 9184 | C19: 95.910004 | D19: 466.56 | E19: 1.2747005 | F19: 0.18351597 | G19: 100.24927
A20: 2024-01-15 | B20: 9140 | C20: 97.949997 | D20: 463.45001 | E20: 1.2704996 | F20: 0.18897135 | G20: 100.10747
A21: 2024-01-22 | B21: 9070 | C21: 97.830002 | D21: 470.67001 | E21: 1.271 | F21: 0.19014889 | G21: 97.855445
A22: 2024-01-29 | B22: 8876 | C22: 96.830002 | D22: 486.76999 | E22: 1.2634 | F22: 0.19350343 | G22: 92.041362
A23: 2024-02-05 | B23: 8836 | C23: 102.39 | D23: 477.59 | E23: 1.2629994 | F23: 0.20563539 | G23: 93.358166
A24: 2024-02-12 | B24: 8888 | C24: 101.51 | D24: 458.42001 | E24: 1.2602998 | F24: 0.20313859 | G24: 97.625444
A25: 2024-02-19 | B25: 8922 | C25: 105.09 | D25: 463.47 | E25: 1.2679992 | F25: 0.20825912 | G25: 97.523266
A26: 2024-02-26 | B26: 9016 | C26: 104.81 | D26: 461.32001 | E26: 1.2658004 | F26: 0.20592533 | G26: 98.838354
A27: 2024-03-04 | B27: 9264 | C27: 102.88 | D27: 466.12 | E27: 1.2859007 | F27: 0.19367496 | G27: 102.10733
A28: 2024-03-11 | B28: 9450 | C28: 104.19 | D28: 475.95999 | E28: 1.2731993 | F28: 0.19422661 | G28: 100.99653
A29: 2024-03-18 | B29: 9652 | C29: 105.23 | D29: 447.45999 | E29: 1.2601998 | F29: 0.19406898 | G29: 108.60534
... A162: 2026-10-23 | B162: 9510 | C162: 122.57 | D162: 331.32001 | E162: 1.337399 | F162: 0.2404606 | G162: 153.37075
A164: Tradeweb share count held at the latest 10-Q; LSEG share count interpolated between disclosed points. Prices: Yahoo Finance chart endpoint.

Sheet Comps
A1: LSEG – Trading comparables
A2: Prices 20–23 Oct 2026; stockanalysis.com, accessed 25 Oct 2026. Forward P/E is the primary metric; trailing EV/EBITDA uses each provider's own EBITDA definition.
A4: Company | B4: Ticker | C4: Peer group | D4: Ccy | E4: Mkt cap (bn) | F4: EV (bn) | G4: Fwd P/E | H4: EV/EBITDA TTM | I4: EBITDA margin
A5: S&P Global | B5: SPGI | C5: Data & analytics | D5: USD | E5: 130.54 | F5: 142.16 | G5: 23.99 | H5: 17.46 | I5: 0.5051
A6: Moody's | B6: MCO | C6: Data & analytics | D6: USD | E6: 83.36 | F6: 89.36 | G6: 26.83 | H6: 22.07 | I6: 0.4952
A7: MSCI | B7: MSCI | C7: Data & analytics | D7: USD | E7: 44.02 | F7: 50.65 | G7: 28.41 | H7: 25.09 | I7: 0.5881
A8: FactSet | B8: FDS | C8: Data & analytics | D8: USD | E8: 11.68 | F8: 12.96 | G8: 16.89 | H8: 14.39 | I8: 0.3636
A9: RELX | B9: REL.L | C9: Data & analytics | D9: GBP | E9: 52.87 | F9: 61.57 | G9: 20.33 | H9: 18.26 | I9: 0.3387
A10: Experian | B10: EXPN.L | C10: Data & analytics | D10: GBP | E10: 26.78 | F10: 30.79 | G10: 20.48 | H10: 15.84 | I10: 0.3008
A11: Intercontinental Exchange | B11: ICE | C11: Exchanges & infrastructure | D11: USD | E11: 91.36 | F11: 110.82 | G11: 19.58 | H11: 16.51 | I11: 0.6359
A12: Nasdaq | B12: NDAQ | C12: Exchanges & infrastructure | D12: USD | E12: 57.33 | F12: 66.03 | G12: 22.45 | H12: 18.92 | I12: 0.6036
A13: CME Group | B13: CME | C13: Exchanges & infrastructure | D13: USD | E13: 109.42 | F13: 110.95 | G13: 23.62 | H13: 22.46 | I13: 0.7103
A14: Deutsche Börse | B14: DB1.DE | C14: Exchanges & infrastructure | D14: EUR | E14: 55.6 | F14: 60.39 | G14: 23.49 | H14: 17.5 | I14: 0.4319
A15: Euronext | B15: ENX.PA | C15: Exchanges & infrastructure | D15: EUR | E15: 17.71 | F15: 19.55 | G15: 18.93 | H15: 15.59 | I15: 0.5906
A17: Median – all peers | G17: =MEDIAN(G5:G15) | H17: =MEDIAN(H5:H15) | I17: =MEDIAN(I5:I15)
A18: Mean | G18: =AVERAGE(G5:G15) | H18: =AVERAGE(H5:H15) | I18: =AVERAGE(I5:I15)
A19: Max | G19: =MAX(G5:G15) | H19: =MAX(H5:H15) | I19: =MAX(I5:I15)
A20: Min | G20: =MIN(G5:G15) | H20: =MIN(H5:H15) | I20: =MIN(I5:I15)
A22: LSEG (same source) | E22: 45.57 | F22: 57.25 | G22: 18.39 | H22: 17.4
A23: LSEG discount to peer median (fwd P/E) | G23: =G22/G17-1
A24: LSEG price on same source (p) | B24: 9490
A25: Implied value at peer median fwd P/E (p) | B25: =B24*G17/G22
A28: SEC EDGAR cross-check (US peers, latest 10-K, audited GAAP)
A29: Ticker | B29: FY end | C29: Revenue ($m) | D29: Operating income ($m) | E29: Operating margin | F29: Net income ($m) | G29: Diluted EPS ($) | H29: Cash ($m) | I29: Debt ($m)
A30: SPGI | B30: 2025-12-31 | C30: 15336 | D30: 6478 | E30: =D30/C30 | F30: 4471 | G30: 14.66 | H30: 1745 | I30: 13088
A31: MCO | B31: 2025-12-31 | C31: 7718 | D31: 3351 | E31: =D31/C31 | F31: 2459 | G31: 13.67 | H31: 2384 | I31: 6994
A32: MSCI | B32: 2025-12-31 | C32: 3134.459 | D32: 1713.567 | E32: =D32/C32 | F32: 1202.305 | G32: 15.69 | H32: 515.332 | I32: 6202.286
A33: FDS | B33: 2026-08-31 | C33: 2476.256 | D33: 699.957 | E33: =D33/C33 | F33: 533.481 | G33: 14.57 | H33: 233.339 | I33: 1370.022
A34: ICE | B34: 2025-12-31 | C34: 12640 | D34: 4929 | E34: =D34/C34 | F34: 3315 | G34: 5.77 | H34: 837 | I34: 19644
A35: NDAQ | B35: 2025-12-31 | C35: 8262 | D35: 2331 | E35: =D35/C35 | F35: 1788 | G35: 3.09 | H35: 604 | I35: 9004
A36: CME | B36: 2025-12-31 | C36: 6520.6 | D36: 4229.5 | E36: =D36/C36 | F36: 4072.2 | G36: 11.16 | H36: 4416.9
A37: TW | B37: 2025-12-31 | C37: 2052.429 | D37: 835.338 | E37: =D37/C37 | F37: 812.792 | G37: 3.78 | H37: 2084.739
A38: Source: data.sec.gov XBRL company facts, refreshed weekly by GitHub Actions (common/edgar.py). D&A not used: XBRL tagging differs across filers.

Sheet vs Consensus
A1: LSEG – Model vs company-compiled consensus
A2: Consensus: LSEG IR, 13 Oct 2026 (12 analysts), before the Octus deal and Q3 upgrade. Model income shown ex-Octus.
A4: Line | B4: Model 2026 | C4: Model 2027 | D4: Model 2028 | E4: Cons 2026 | F4: Cons 2027 | G4: Cons 2028 | H4: Diff 2026 | I4: Diff 2027 | J4: Diff 2028
A5: Data & Analytics | B5: =Divisions!F16-Divisions!F15 | C5: =Divisions!G16-Divisions!G15 | D5: =Divisions!H16-Divisions!H15 | E5: 4143 | F5: 4394 | G5: 4649 | H5: =B5/E5-1 | I5: =C5/F5-1 | J5: =D5/G5-1
A6: FTSE Russell | B6: =Divisions!F23 | C6: =Divisions!G23 | D6: =Divisions!H23 | E6: 1035 | F6: 1130 | G6: 1226 | H6: =B6/E6-1 | I6: =C6/F6-1 | J6: =D6/G6-1
A7: Risk Intelligence | B7: =Divisions!F27 | C7: =Divisions!G27 | D7: =Divisions!H27 | E7: 632 | F7: 701 | G7: 775 | H7: =B7/E7-1 | I7: =C7/F7-1 | J7: =D7/G7-1
A8: Markets | B8: =Divisions!F41 | C8: =Divisions!G41 | D8: =Divisions!H41 | E8: 3804 | F8: 4091 | G8: 4380 | H8: =B8/E8-1 | I8: =C8/F8-1 | J8: =D8/G8-1
A9: Total income excl. recoveries | B9: =Divisions!F48-Divisions!F15 | C9: =Divisions!G48-Divisions!G15 | D9: =Divisions!H48-Divisions!H15 | E9: 9622 | F9: 10324 | G9: 11038 | H9: =B9/E9-1 | I9: =C9/F9-1 | J9: =D9/G9-1
A10: Adjusted EBITDA | B10: =Model!F10 | C10: =Model!G10 | D10: =Model!H10 | E10: 4972 | F10: 5388 | G10: 5821 | H10: =B10/E10-1 | I10: =C10/F10-1 | J10: =D10/G10-1
A11: Adjusted EPS (p) | B11: =Model!F20 | C11: =Model!G20 | D11: =Model!H20 | E11: 480.6 | F11: 550.9 | G11: 615.5 | H11: =B11/E11-1 | I11: =C11/F11-1 | J11: =D11/G11-1
A12: DPS (p) | B12: =Model!F45 | C12: =Model!G45 | D12: =Model!H45 | E12: 167.3 | F12: 189.4 | G12: 209.9 | H12: =B12/E12-1 | I12: =C12/F12-1 | J12: =D12/G12-1

Sheet Reverse DCF
A1: LSEG – What is priced in (reverse DCF)
A2: Snapshot from lseg/engine.py: each row moves one driver (base case otherwise) until DCF value = share price.
A4: Driver (2027–2030) | B4: Base case | C4: Implied by share price | D4: Change needed | E4: Context
A5: Revenue retention | B5: 0.928 | C5: 0.9344942 | D5: 0.0064941986 | E5: Lowest disclosed level is 92.4% (Dec 2025)
A6: Markets volume growth, all drivers (shown on 2028 ADV growth) | B6: 0.05 | C6: 0.059752753 | D6: 0.0097527526 | E6: Volumes shrink in real terms after a flat 2027
A7: Divisional margin change per year | B7: 0 | C7: 0.0014391102 | D7: 0.0014391102 | E7: Margins falling every year from here
A8: Terminal growth | B8: 0.03 | C8: 0.030724323 | D8: 0.00072432327 | E8: Below UK nominal GDP
A11: DCF value (p) vs revenue retention, base case otherwise
A12: Retention (2027–2030) | B12: 0.88 | C12: 0.89 | D12: 0.9 | E12: 0.91 | F12: 0.92 | G12: 0.928 | H12: 0.935
A13: DCF value (p) | B13: 8200.8893 | C13: 8426.4774 | D13: 8658.5034 | E13: 8897.0911 | F13: 9142.3657 | G13: 9343.4849 | H13: 9523.0925

Sheet Scenarios
A1: LSEG – Scenarios
A2: Snapshot from the Python engine. Set Inputs!Scenario to 1/2/3 to reproduce any column live.
B4: Bear | C4: Base | D4: Bull
A5: Probability | B5: 0.25 | C5: 0.5 | D5: 0.25
A6: Retention (2027+) | B6: 0.91 | C6: 0.928 | D6: 0.935
A7: Markets volume growth adj. | B7: -0.03 | C7: 0 | D7: 0.02
A8: ETF AUM growth adj. | B8: -0.06 | C8: 0 | D8: 0.04
A9: Terminal growth | B9: 0.025 | C9: 0.03 | D9: 0.035
A10: 2028E income | B10: 10184.024 | C10: 10762.389 | D10: 11043.905
A11: 2028E EBITDA margin | B11: 0.51076851 | C11: 0.51904225 | D11: 0.52338835
A12: 2028E adj EPS (p) | B12: 538.29919 | C12: 585.59491 | D12: 609.66729
A13: DCF value (p) | B13: 6724.2973 | C13: 9343.4849 | D13: 11643.219
A14: Upside | B14: -0.29292352 | C14: -0.017509472 | D14: 0.22431329
A16: Probability-weighted value (p) | B16: =SUMPRODUCT(B5:D5,B13:D13)
A17: Probability-weighted upside | B17: =B16/Inputs!$C$18-1
A19: Bear: AI substitution lifts churn (retention 91.0%), terminals shrink faster, volumes and ETF flows normalise, NTI spread cut 20%, margins drift down.
A20: Bull: data licensing into AI tools lifts retention to 93.5%, volumes stay firm, ETF AUM compounds, margin expansion continues.

Sheet Pair trade
A1: Trade expression: long LSEG / short FactSet (considered and rejected)
A2: Would isolate the AI-discount view and remove market beta. See the read below for why the outright long is preferred.
A5: LSEG beta (5y) | B5: 0.41
A6: FactSet beta (5y) | B6: 0.77
A7: Beta-neutral hedge: £ FactSet short per £1 LSEG long | B7: =B5/B6
A8: LSEG forward P/E | B8: 18.39
A9: FactSet forward P/E | B9: 16.89
A10: LSEG premium to FactSet | B10: =B8/B9-1
A11: FactSet short interest (% float) | B11: 0.0905
A12: Share of LSEG income outside Data & Analytics (2026E) | B12: =1-Divisions!F16/Divisions!F48
A15: Read: the pair has already worked. Since Jan 2024 LSEG has beaten FactSet by c.53% in GBP (Trackers sheet), and FactSet ASV grew 7% with retention above 95%.
A16: Conclusion: prefer the outright long. FactSet short interest is c.9% of float, so the short leg carries squeeze risk with little valuation support left.

Sheet Sources
A1: Sources
A3: FY25 | B3: LSEG 2025 Preliminary Results RNS, 26 Feb 2026
A4: FY24 | B4: LSEG 2024 Preliminary Results, 27 Feb 2025 (2023 comparatives)
A5: H126 | B5: LSEG H1 2026 Interim Report, 30 Jul 2026
A6: Q326 | B6: LSEG Q3 2026 Trading Update, Oct 2026
A7: OCT | B7: Reuters via Euronext, 'LSEG to buy Octus in $3.5 billion deal', Oct 2026
A8: PX | B8: Alpha Vantage quote LSEG.LON, close 23 Oct 2026
A9: SA | B9: stockanalysis.com statistics pages, accessed 25 Oct 2026
A12: Conventions: blue = input, black = formula, green = link to another sheet. Not investment advice.
