Workbook

Sheet Cover
A1: Refinery margin hedge: 2027 zero-cost crack collars
A2: Illustrative South African refinery. Bachelier pricing, Black-76 cross-check. Not a real asset, not executable quotes.
A4: Output | B4: Value | C4: Cell
A5: Annual budget refining margin ($m) | B5: =Monthly!T17/1000000 -> 875.06122
A6: Recommended cover | B6: =Scenarios!$D$21 -> 0.8
A7: 30% fall, recommended cover | B7: =INDEX(Scenarios!B16:B19,MATCH(Scenarios!$D$21,Scenarios!A16:A19,0)) -> -0.1
A8: 30% fall, unhedged | B8: =Scenarios!B8 -> -0.3
A9: Outage cost on unbacked calls, recommended cover | B9: =INDEX(Scenarios!C16:C19,MATCH(Scenarios!$D$21,Scenarios!A16:A19,0)) -> 0.023013699
A10: Outage + spike total change, recommended cover | B10: =INDEX(Scenarios!D16:D19,MATCH(Scenarios!$D$21,Scenarios!A16:A19,0)) -> -0.049589041
A11: Diesel put strike ($/bbl) | B11: =Pricing!$E$5 -> 38
A12: Diesel call strike, Bachelier ($/bbl) | B12: =Pricing!$F$5 -> 42
A13: Diesel call strike Dec, Black-76 ($/bbl) | B13: =Pricing!K16 -> 45.678259
A14: Selected case: margin change | B14: =Monthly!C19 -> -0.049589041
A15: Selected case: unbacked call cost | B15: =Monthly!C20 -> 0.023013699
A16: Max abs Bachelier net premium ($/bbl) | B16: =MAX(MAX(Pricing!J5:J16),-MIN(Pricing!J5:J16),MAX(Pricing!V5:V16),-MIN(Pricing!V5:V16)) -> 0
A17: Max abs Black-76 net premium ($/bbl) | B17: =MAX(MAX(Pricing!O5:O16),-MIN(Pricing!O5:O16),MAX(Pricing!AA5:AA16),-MIN(Pricing!AA5:AA16)) -> 1.21796e-07
A19: Python engine only (values, not formulas)
A20: Monte Carlo 5th percentile, unhedged | B20: -1.5566415
A21: Monte Carlo 5th percentile, 80% cover | B21: -0.35132829
A22: Outage cost, Black-76 strikes | B22: 0.015473074

Sheet Inputs
A1: Inputs
A2: Blue = hard-coded input. Tag: S = sourced, A = assumption, D = derived. Cracks in $/bbl.
A4: Input | B4: Unit | C4: Value | D4: Tag | E4: Source / note
A6: Market (build date 27 Oct 2026)
A7: Valuation date | B7: date | C7: 46322 | D7: A | E7: Build date
A8: 2027 forward crack, diesel and jet | B8: $/bbl | C8: 40 | D8: S | E8: GS: 2027 average above $40. Spot NYH ULSD crack $105.91 (D)
A9: 2027 forward crack, petrol | B9: $/bbl | C9: 26.41 | D9: D | E9: Trailing 12-month NYH gasoline crack vs Brent (FRED DGASNYH, DCOILBRENTEU)
A10: Normal vol, diesel crack | B10: $/bbl/yr | C10: 44.71 | D10: D | E10: Month-average crack changes, Oct 2025 to Oct 2026, x sqrt(12)
A11: Normal vol, petrol crack | B11: $/bbl/yr | C11: 40.56 | D11: D | E11: Month-average crack changes, Oct 2025 to Oct 2026, x sqrt(12)
A12: USD discount rate | B12: % | C12: 0.0388 | D12: S | E12: Fed funds effective, 23 Oct 2026 (FRED DFF)
A13: ZAR rate | B13: % | C13: 0.0725 | D13: S | E13: SARB repo after 23 Sep 2026 hike (eNCA, secondary)
A14: USD/ZAR spot | B14: ZAR per $ | C14: 16.6408 | D14: S | E14: Close 26 Oct 2026 (Alpha Vantage)
A16: Refinery (illustrative)
A17: Crude capacity | B17: bbl/day | C17: 100000 | D17: A | E17: Illustrative coastal South African refinery
A18: Expected availability | B18: % | C18: 0.88 | D18: A | E18: On-stream factor after planned maintenance
A19: Yield, diesel and jet | B19: % | C19: 0.45 | D19: A | E19: Share of crude run
A20: Yield, petrol | B20: % | C20: 0.35 | D20: A | E20: Other 20% (LPG, fuel oil) taken at zero crack
A21: Cash opex | B21: ZAR/bbl | C21: 100 | D21: A | E21: About $6/bbl at spot
A23: Hedge design
A24: Put distance below forward | B24: % | C24: 0.05 | D24: A | E24: Buy a put 5% below the forward crack
A25: Outage risk appetite | B25: % of margin | C25: 0.025 | D25: A | E25: Max cost of unbacked sold calls in one outage
A26: Outage length | B26: days | C26: 42 | D26: A | E26: Six-week unplanned outage
A27: Outage start | B27: date | C27: 46569 | D27: A | E27: Settled month by month
A28: Crack spike during outage | B28: % | C28: 0.3 | D28: A | E28: Cracks often rise when a refinery trips
A30: Selected case for the Monthly sheet
A31: Hedge cover | B31: % | C31: 0.8 | D31: A | E31: Change to test other ratios
A32: Parallel crack move | B32: % | C32: 0.3 | D32: A | E32: Applies to both products for all of 2027
A33: Outage on (1) or off (0) | B33: flag | C33: 1 | D33: A

Sheet Pricing
A1: Collar pricing by settlement month
A2: Bachelier (normal) prices the collar. Black-76 is a cross-check: its zero-cost call strike is solved in engine.py and the check column proves zero premium.
A4: Month | B4: Month end | C4: t (yrs) | D4: Diesel and jet: Forward | E4: Diesel and jet: Put strike | F4: Diesel and jet: Call strike | G4: Diesel and jet: sigma*sqrt(t) | H4: Diesel and jet: Put prem | I4: Diesel and jet: Call prem | J4: Diesel and jet: Net prem | K4: Diesel and jet: B76 call strike | L4: Diesel and jet: B76 vol | M4: Diesel and jet: B76 put prem | N4: Diesel and jet: B76 call prem | O4: Diesel and jet: B76 net prem | P4: Petrol: Forward | Q4: Petrol: Put strike | R4: Petrol: Call strike | S4: Petrol: sigma*sqrt(t) | T4: Petrol: Put prem | U4: Petrol: Call prem | V4: Petrol: Net prem | W4: Petrol: B76 call strike | X4: Petrol: B76 vol | Y4: Petrol: B76 put prem | Z4: Petrol: B76 call prem | AA4: Petrol: B76 net prem
A5: 1 | B5: =DATE(2027,A5+1,1)-1 -> 46418 | C5: =(B5-Inputs!$C$7)/365 -> 0.2630137 | D5: =Inputs!$C$8 -> 40 | E5: =D5*(1-Inputs!$C$24) -> 38 | F5: =2*D5-E5 -> 42 | G5: =Inputs!$C$10*SQRT(C5) -> 22.929461 | H5: =EXP(-Inputs!$C$12*C5)*((E5-D5)*_xlfn.NORM.S.DIST((E5-D5)/G5,TRUE())+G5*_xlfn.NORM.S.DIST((E5-D5)/G5,FALSE())) -> 8.0992317 | I5: =EXP(-Inputs!$C$12*C5)*((D5-F5)*_xlfn.NORM.S.DIST((D5-F5)/G5,TRUE())+G5*_xlfn.NORM.S.DIST((D5-F5)/G5,FALSE())) -> 8.0992317 | J5: =H5-I5 -> 0 | K5: 43.30241 | L5: =Inputs!$C$10/D5 -> 1.11775 | M5: =EXP(-Inputs!$C$12*C5)*(E5*_xlfn.NORM.S.DIST(-(((LN(D5/E5)+L5^2*C5/2)/(L5*SQRT(C5)))-L5*SQRT(C5)),TRUE())-D5*_xlfn.NORM.S.DIST(-((LN(D5/E5)+L5^2*C5/2)/(L5*SQRT(C5))),TRUE())) -> 7.7529325 | N5: =EXP(-Inputs!$C$12*C5)*(D5*_xlfn.NORM.S.DIST(((LN(D5/K5)+L5^2*C5/2)/(L5*SQRT(C5))),TRUE())-K5*_xlfn.NORM.S.DIST((((LN(D5/K5)+L5^2*C5/2)/(L5*SQRT(C5)))-L5*SQRT(C5)),TRUE())) -> 7.7529324 | O5: =M5-N5 -> 9.1087675e-08 | P5: =Inputs!$C$9 -> 26.41 | Q5: =P5*(1-Inputs!$C$24) -> 25.0895 | R5: =2*P5-Q5 -> 27.7305 | S5: =Inputs!$C$11*SQRT(C5) -> 20.80114 | T5: =EXP(-Inputs!$C$12*C5)*((Q5-P5)*_xlfn.NORM.S.DIST((Q5-P5)/S5,TRUE())+S5*_xlfn.NORM.S.DIST((Q5-P5)/S5,FALSE())) -> 7.5771991 | U5: =EXP(-Inputs!$C$12*C5)*((P5-R5)*_xlfn.NORM.S.DIST((P5-R5)/S5,TRUE())+S5*_xlfn.NORM.S.DIST((P5-R5)/S5,FALSE())) -> 7.5771991 | V5: =T5-U5 -> 0 | W5: 29.016269 | X5: =Inputs!$C$11/P5 -> 1.5357819 | Y5: =EXP(-Inputs!$C$12*C5)*(Q5*_xlfn.NORM.S.DIST(-(((LN(P5/Q5)+X5^2*C5/2)/(X5*SQRT(C5)))-X5*SQRT(C5)),TRUE())-P5*_xlfn.NORM.S.DIST(-((LN(P5/Q5)+X5^2*C5/2)/(X5*SQRT(C5))),TRUE())) -> 7.1687204 | Z5: =EXP(-Inputs!$C$12*C5)*(P5*_xlfn.NORM.S.DIST(((LN(P5/W5)+X5^2*C5/2)/(X5*SQRT(C5))),TRUE())-W5*_xlfn.NORM.S.DIST((((LN(P5/W5)+X5^2*C5/2)/(X5*SQRT(C5)))-X5*SQRT(C5)),TRUE())) -> 7.1687204 | AA5: =Y5-Z5 -> -4.6631266e-08
A6: 2 | B6: =DATE(2027,A6+1,1)-1 -> 46446 | C6: =(B6-Inputs!$C$7)/365 -> 0.33972603 | D6: =Inputs!$C$8 -> 40 | E6: =D6*(1-Inputs!$C$24) -> 38 | F6: =2*D6-E6 -> 42 | G6: =Inputs!$C$10*SQRT(C6) -> 26.05968 | H6: =EXP(-Inputs!$C$12*C6)*((E6-D6)*_xlfn.NORM.S.DIST((E6-D6)/G6,TRUE())+G6*_xlfn.NORM.S.DIST((E6-D6)/G6,FALSE())) -> 9.3034665 | I6: =EXP(-Inputs!$C$12*C6)*((D6-F6)*_xlfn.NORM.S.DIST((D6-F6)/G6,TRUE())+G6*_xlfn.NORM.S.DIST((D6-F6)/G6,FALSE())) -> 9.3034665 | J6: =H6-I6 -> 0 | K6: 43.523565 | L6: =Inputs!$C$10/D6 -> 1.11775 | M6: =EXP(-Inputs!$C$12*C6)*(E6*_xlfn.NORM.S.DIST(-(((LN(D6/E6)+L6^2*C6/2)/(L6*SQRT(C6)))-L6*SQRT(C6)),TRUE())-D6*_xlfn.NORM.S.DIST(-((LN(D6/E6)+L6^2*C6/2)/(L6*SQRT(C6))),TRUE())) -> 8.8720053 | N6: =EXP(-Inputs!$C$12*C6)*(D6*_xlfn.NORM.S.DIST(((LN(D6/K6)+L6^2*C6/2)/(L6*SQRT(C6))),TRUE())-K6*_xlfn.NORM.S.DIST((((LN(D6/K6)+L6^2*C6/2)/(L6*SQRT(C6)))-L6*SQRT(C6)),TRUE())) -> 8.8720053 | O6: =M6-N6 -> -5.7136777e-08 | P6: =Inputs!$C$9 -> 26.41 | Q6: =P6*(1-Inputs!$C$24) -> 25.0895 | R6: =2*P6-Q6 -> 27.7305 | S6: =Inputs!$C$11*SQRT(C6) -> 23.64081 | T6: =EXP(-Inputs!$C$12*C6)*((Q6-P6)*_xlfn.NORM.S.DIST((Q6-P6)/S6,TRUE())+S6*_xlfn.NORM.S.DIST((Q6-P6)/S6,FALSE())) -> 8.670729 | U6: =EXP(-Inputs!$C$12*C6)*((P6-R6)*_xlfn.NORM.S.DIST((P6-R6)/S6,TRUE())+S6*_xlfn.NORM.S.DIST((P6-R6)/S6,FALSE())) -> 8.670729 | V6: =T6-U6 -> 0 | W6: 29.263264 | X6: =Inputs!$C$11/P6 -> 1.5357819 | Y6: =EXP(-Inputs!$C$12*C6)*(Q6*_xlfn.NORM.S.DIST(-(((LN(P6/Q6)+X6^2*C6/2)/(X6*SQRT(C6)))-X6*SQRT(C6)),TRUE())-P6*_xlfn.NORM.S.DIST(-((LN(P6/Q6)+X6^2*C6/2)/(X6*SQRT(C6))),TRUE())) -> 8.1428897 | Z6: =EXP(-Inputs!$C$12*C6)*(P6*_xlfn.NORM.S.DIST(((LN(P6/W6)+X6^2*C6/2)/(X6*SQRT(C6))),TRUE())-W6*_xlfn.NORM.S.DIST((((LN(P6/W6)+X6^2*C6/2)/(X6*SQRT(C6)))-X6*SQRT(C6)),TRUE())) -> 8.1428896 | AA6: =Y6-Z6 -> 9.0171607e-08
A7: 3 | B7: =DATE(2027,A7+1,1)-1 -> 46477 | C7: =(B7-Inputs!$C$7)/365 -> 0.42465753 | D7: =Inputs!$C$8 -> 40 | E7: =D7*(1-Inputs!$C$24) -> 38 | F7: =2*D7-E7 -> 42 | G7: =Inputs!$C$10*SQRT(C7) -> 29.135608 | H7: =EXP(-Inputs!$C$12*C7)*((E7-D7)*_xlfn.NORM.S.DIST((E7-D7)/G7,TRUE())+G7*_xlfn.NORM.S.DIST((E7-D7)/G7,FALSE())) -> 10.476748 | I7: =EXP(-Inputs!$C$12*C7)*((D7-F7)*_xlfn.NORM.S.DIST((D7-F7)/G7,TRUE())+G7*_xlfn.NORM.S.DIST((D7-F7)/G7,FALSE())) -> 10.476748 | J7: =H7-I7 -> 0 | K7: 43.756541 | L7: =Inputs!$C$10/D7 -> 1.11775 | M7: =EXP(-Inputs!$C$12*C7)*(E7*_xlfn.NORM.S.DIST(-(((LN(D7/E7)+L7^2*C7/2)/(L7*SQRT(C7)))-L7*SQRT(C7)),TRUE())-D7*_xlfn.NORM.S.DIST(-((LN(D7/E7)+L7^2*C7/2)/(L7*SQRT(C7))),TRUE())) -> 9.948226 | N7: =EXP(-Inputs!$C$12*C7)*(D7*_xlfn.NORM.S.DIST(((LN(D7/K7)+L7^2*C7/2)/(L7*SQRT(C7))),TRUE())-K7*_xlfn.NORM.S.DIST((((LN(D7/K7)+L7^2*C7/2)/(L7*SQRT(C7)))-L7*SQRT(C7)),TRUE())) -> 9.9482259 | O7: =M7-N7 -> 1.21796e-07 | P7: =Inputs!$C$9 -> 26.41 | Q7: =P7*(1-Inputs!$C$24) -> 25.0895 | R7: =2*P7-Q7 -> 27.7305 | S7: =Inputs!$C$11*SQRT(C7) -> 26.431229 | T7: =EXP(-Inputs!$C$12*C7)*((Q7-P7)*_xlfn.NORM.S.DIST((Q7-P7)/S7,TRUE())+S7*_xlfn.NORM.S.DIST((Q7-P7)/S7,FALSE())) -> 9.7357005 | U7: =EXP(-Inputs!$C$12*C7)*((P7-R7)*_xlfn.NORM.S.DIST((P7-R7)/S7,TRUE())+S7*_xlfn.NORM.S.DIST((P7-R7)/S7,FALSE())) -> 9.7357005 | V7: =T7-U7 -> 0 | W7: 29.531283 | X7: =Inputs!$C$11/P7 -> 1.5357819 | Y7: =EXP(-Inputs!$C$12*C7)*(Q7*_xlfn.NORM.S.DIST(-(((LN(P7/Q7)+X7^2*C7/2)/(X7*SQRT(C7)))-X7*SQRT(C7)),TRUE())-P7*_xlfn.NORM.S.DIST(-((LN(P7/Q7)+X7^2*C7/2)/(X7*SQRT(C7))),TRUE())) -> 9.0685085 | Z7: =EXP(-Inputs!$C$12*C7)*(P7*_xlfn.NORM.S.DIST(((LN(P7/W7)+X7^2*C7/2)/(X7*SQRT(C7))),TRUE())-W7*_xlfn.NORM.S.DIST((((LN(P7/W7)+X7^2*C7/2)/(X7*SQRT(C7)))-X7*SQRT(C7)),TRUE())) -> 9.0685085 | AA7: =Y7-Z7 -> 1.6005854e-08
A8: 4 | B8: =DATE(2027,A8+1,1)-1 -> 46507 | C8: =(B8-Inputs!$C$7)/365 -> 0.50684932 | D8: =Inputs!$C$8 -> 40 | E8: =D8*(1-Inputs!$C$24) -> 38 | F8: =2*D8-E8 -> 42 | G8: =Inputs!$C$10*SQRT(C8) -> 31.830547 | H8: =EXP(-Inputs!$C$12*C8)*((E8-D8)*_xlfn.NORM.S.DIST((E8-D8)/G8,TRUE())+G8*_xlfn.NORM.S.DIST((E8-D8)/G8,FALSE())) -> 11.495308 | I8: =EXP(-Inputs!$C$12*C8)*((D8-F8)*_xlfn.NORM.S.DIST((D8-F8)/G8,TRUE())+G8*_xlfn.NORM.S.DIST((D8-F8)/G8,FALSE())) -> 11.495308 | J8: =H8-I8 -> 0 | K8: 43.974441 | L8: =Inputs!$C$10/D8 -> 1.11775 | M8: =EXP(-Inputs!$C$12*C8)*(E8*_xlfn.NORM.S.DIST(-(((LN(D8/E8)+L8^2*C8/2)/(L8*SQRT(C8)))-L8*SQRT(C8)),TRUE())-D8*_xlfn.NORM.S.DIST(-((LN(D8/E8)+L8^2*C8/2)/(L8*SQRT(C8))),TRUE())) -> 10.869894 | N8: =EXP(-Inputs!$C$12*C8)*(D8*_xlfn.NORM.S.DIST(((LN(D8/K8)+L8^2*C8/2)/(L8*SQRT(C8))),TRUE())-K8*_xlfn.NORM.S.DIST((((LN(D8/K8)+L8^2*C8/2)/(L8*SQRT(C8)))-L8*SQRT(C8)),TRUE())) -> 10.869894 | O8: =M8-N8 -> -5.2923715e-08 | P8: =Inputs!$C$9 -> 26.41 | Q8: =P8*(1-Inputs!$C$24) -> 25.0895 | R8: =2*P8-Q8 -> 27.7305 | S8: =Inputs!$C$11*SQRT(C8) -> 28.876023 | T8: =EXP(-Inputs!$C$12*C8)*((Q8-P8)*_xlfn.NORM.S.DIST((Q8-P8)/S8,TRUE())+S8*_xlfn.NORM.S.DIST((Q8-P8)/S8,FALSE())) -> 10.659949 | U8: =EXP(-Inputs!$C$12*C8)*((P8-R8)*_xlfn.NORM.S.DIST((P8-R8)/S8,TRUE())+S8*_xlfn.NORM.S.DIST((P8-R8)/S8,FALSE())) -> 10.659949 | V8: =T8-U8 -> 0 | W8: 29.789176 | X8: =Inputs!$C$11/P8 -> 1.5357819 | Y8: =EXP(-Inputs!$C$12*C8)*(Q8*_xlfn.NORM.S.DIST(-(((LN(P8/Q8)+X8^2*C8/2)/(X8*SQRT(C8)))-X8*SQRT(C8)),TRUE())-P8*_xlfn.NORM.S.DIST(-((LN(P8/Q8)+X8^2*C8/2)/(X8*SQRT(C8))),TRUE())) -> 9.8513488 | Z8: =EXP(-Inputs!$C$12*C8)*(P8*_xlfn.NORM.S.DIST(((LN(P8/W8)+X8^2*C8/2)/(X8*SQRT(C8))),TRUE())-W8*_xlfn.NORM.S.DIST((((LN(P8/W8)+X8^2*C8/2)/(X8*SQRT(C8)))-X8*SQRT(C8)),TRUE())) -> 9.8513489 | AA8: =Y8-Z8 -> -5.4093084e-08
A9: 5 | B9: =DATE(2027,A9+1,1)-1 -> 46538 | C9: =(B9-Inputs!$C$7)/365 -> 0.59178082 | D9: =Inputs!$C$8 -> 40 | E9: =D9*(1-Inputs!$C$24) -> 38 | F9: =2*D9-E9 -> 42 | G9: =Inputs!$C$10*SQRT(C9) -> 34.394192 | H9: =EXP(-Inputs!$C$12*C9)*((E9-D9)*_xlfn.NORM.S.DIST((E9-D9)/G9,TRUE())+G9*_xlfn.NORM.S.DIST((E9-D9)/G9,FALSE())) -> 12.455196 | I9: =EXP(-Inputs!$C$12*C9)*((D9-F9)*_xlfn.NORM.S.DIST((D9-F9)/G9,TRUE())+G9*_xlfn.NORM.S.DIST((D9-F9)/G9,FALSE())) -> 12.455196 | J9: =H9-I9 -> 0 | K9: 44.194586 | L9: =Inputs!$C$10/D9 -> 1.11775 | M9: =EXP(-Inputs!$C$12*C9)*(E9*_xlfn.NORM.S.DIST(-(((LN(D9/E9)+L9^2*C9/2)/(L9*SQRT(C9)))-L9*SQRT(C9)),TRUE())-D9*_xlfn.NORM.S.DIST(-((LN(D9/E9)+L9^2*C9/2)/(L9*SQRT(C9))),TRUE())) -> 11.726629 | N9: =EXP(-Inputs!$C$12*C9)*(D9*_xlfn.NORM.S.DIST(((LN(D9/K9)+L9^2*C9/2)/(L9*SQRT(C9))),TRUE())-K9*_xlfn.NORM.S.DIST((((LN(D9/K9)+L9^2*C9/2)/(L9*SQRT(C9)))-L9*SQRT(C9)),TRUE())) -> 11.726629 | O9: =M9-N9 -> -5.1269597e-08 | P9: =Inputs!$C$9 -> 26.41 | Q9: =P9*(1-Inputs!$C$24) -> 25.0895 | R9: =2*P9-Q9 -> 27.7305 | S9: =Inputs!$C$11*SQRT(C9) -> 31.20171 | T9: =EXP(-Inputs!$C$12*C9)*((Q9-P9)*_xlfn.NORM.S.DIST((Q9-P9)/S9,TRUE())+S9*_xlfn.NORM.S.DIST((Q9-P9)/S9,FALSE())) -> 11.530755 | U9: =EXP(-Inputs!$C$12*C9)*((P9-R9)*_xlfn.NORM.S.DIST((P9-R9)/S9,TRUE())+S9*_xlfn.NORM.S.DIST((P9-R9)/S9,FALSE())) -> 11.530755 | V9: =T9-U9 -> 0 | W9: 30.05677 | X9: =Inputs!$C$11/P9 -> 1.5357819 | Y9: =EXP(-Inputs!$C$12*C9)*(Q9*_xlfn.NORM.S.DIST(-(((LN(P9/Q9)+X9^2*C9/2)/(X9*SQRT(C9)))-X9*SQRT(C9)),TRUE())-P9*_xlfn.NORM.S.DIST(-((LN(P9/Q9)+X9^2*C9/2)/(X9*SQRT(C9))),TRUE())) -> 10.569964 | Z9: =EXP(-Inputs!$C$12*C9)*(P9*_xlfn.NORM.S.DIST(((LN(P9/W9)+X9^2*C9/2)/(X9*SQRT(C9))),TRUE())-W9*_xlfn.NORM.S.DIST((((LN(P9/W9)+X9^2*C9/2)/(X9*SQRT(C9)))-X9*SQRT(C9)),TRUE())) -> 10.569964 | AA9: =Y9-Z9 -> -1.0691083e-07
A10: 6 | B10: =DATE(2027,A10+1,1)-1 -> 46568 | C10: =(B10-Inputs!$C$7)/365 -> 0.6739726 | D10: =Inputs!$C$8 -> 40 | E10: =D10*(1-Inputs!$C$24) -> 38 | F10: =2*D10-E10 -> 42 | G10: =Inputs!$C$10*SQRT(C10) -> 36.705048 | H10: =EXP(-Inputs!$C$12*C10)*((E10-D10)*_xlfn.NORM.S.DIST((E10-D10)/G10,TRUE())+G10*_xlfn.NORM.S.DIST((E10-D10)/G10,FALSE())) -> 13.31222 | I10: =EXP(-Inputs!$C$12*C10)*((D10-F10)*_xlfn.NORM.S.DIST((D10-F10)/G10,TRUE())+G10*_xlfn.NORM.S.DIST((D10-F10)/G10,FALSE())) -> 13.31222 | J10: =H10-I10 -> 0 | K10: 44.404524 | L10: =Inputs!$C$10/D10 -> 1.11775 | M10: =EXP(-Inputs!$C$12*C10)*(E10*_xlfn.NORM.S.DIST(-(((LN(D10/E10)+L10^2*C10/2)/(L10*SQRT(C10)))-L10*SQRT(C10)),TRUE())-D10*_xlfn.NORM.S.DIST(-((LN(D10/E10)+L10^2*C10/2)/(L10*SQRT(C10))),TRUE())) -> 12.481013 | N10: =EXP(-Inputs!$C$12*C10)*(D10*_xlfn.NORM.S.DIST(((LN(D10/K10)+L10^2*C10/2)/(L10*SQRT(C10))),TRUE())-K10*_xlfn.NORM.S.DIST((((LN(D10/K10)+L10^2*C10/2)/(L10*SQRT(C10)))-L10*SQRT(C10)),TRUE())) -> 12.481013 | O10: =M10-N10 -> -1.9754257e-08 | P10: =Inputs!$C$9 -> 26.41 | Q10: =P10*(1-Inputs!$C$24) -> 25.0895 | R10: =2*P10-Q10 -> 27.7305 | S10: =Inputs!$C$11*SQRT(C10) -> 33.29807 | T10: =EXP(-Inputs!$C$12*C10)*((Q10-P10)*_xlfn.NORM.S.DIST((Q10-P10)/S10,TRUE())+S10*_xlfn.NORM.S.DIST((Q10-P10)/S10,FALSE())) -> 12.308099 | U10: =EXP(-Inputs!$C$12*C10)*((P10-R10)*_xlfn.NORM.S.DIST((P10-R10)/S10,TRUE())+S10*_xlfn.NORM.S.DIST((P10-R10)/S10,FALSE())) -> 12.308099 | V10: =T10-U10 -> 0 | W10: 30.318526 | X10: =Inputs!$C$11/P10 -> 1.5357819 | Y10: =EXP(-Inputs!$C$12*C10)*(Q10*_xlfn.NORM.S.DIST(-(((LN(P10/Q10)+X10^2*C10/2)/(X10*SQRT(C10)))-X10*SQRT(C10)),TRUE())-P10*_xlfn.NORM.S.DIST(-((LN(P10/Q10)+X10^2*C10/2)/(X10*SQRT(C10))),TRUE())) -> 11.194771 | Z10: =EXP(-Inputs!$C$12*C10)*(P10*_xlfn.NORM.S.DIST(((LN(P10/W10)+X10^2*C10/2)/(X10*SQRT(C10))),TRUE())-W10*_xlfn.NORM.S.DIST((((LN(P10/W10)+X10^2*C10/2)/(X10*SQRT(C10)))-X10*SQRT(C10)),TRUE())) -> 11.194771 | AA10: =Y10-Z10 -> 6.4960819e-08
A11: 7 | B11: =DATE(2027,A11+1,1)-1 -> 46599 | C11: =(B11-Inputs!$C$7)/365 -> 0.75890411 | D11: =Inputs!$C$8 -> 40 | E11: =D11*(1-Inputs!$C$24) -> 38 | F11: =2*D11-E11 -> 42 | G11: =Inputs!$C$10*SQRT(C11) -> 38.949162 | H11: =EXP(-Inputs!$C$12*C11)*((E11-D11)*_xlfn.NORM.S.DIST((E11-D11)/G11,TRUE())+G11*_xlfn.NORM.S.DIST((E11-D11)/G11,FALSE())) -> 14.136503 | I11: =EXP(-Inputs!$C$12*C11)*((D11-F11)*_xlfn.NORM.S.DIST((D11-F11)/G11,TRUE())+G11*_xlfn.NORM.S.DIST((D11-F11)/G11,FALSE())) -> 14.136503 | J11: =H11-I11 -> 0 | K11: 44.619532 | L11: =Inputs!$C$10/D11 -> 1.11775 | M11: =EXP(-Inputs!$C$12*C11)*(E11*_xlfn.NORM.S.DIST(-(((LN(D11/E11)+L11^2*C11/2)/(L11*SQRT(C11)))-L11*SQRT(C11)),TRUE())-D11*_xlfn.NORM.S.DIST(-((LN(D11/E11)+L11^2*C11/2)/(L11*SQRT(C11))),TRUE())) -> 13.196488 | N11: =EXP(-Inputs!$C$12*C11)*(D11*_xlfn.NORM.S.DIST(((LN(D11/K11)+L11^2*C11/2)/(L11*SQRT(C11))),TRUE())-K11*_xlfn.NORM.S.DIST((((LN(D11/K11)+L11^2*C11/2)/(L11*SQRT(C11)))-L11*SQRT(C11)),TRUE())) -> 13.196488 | O11: =M11-N11 -> -4.1142103e-08 | P11: =Inputs!$C$9 -> 26.41 | Q11: =P11*(1-Inputs!$C$24) -> 25.0895 | R11: =2*P11-Q11 -> 27.7305 | S11: =Inputs!$C$11*SQRT(C11) -> 35.333886 | T11: =EXP(-Inputs!$C$12*C11)*((Q11-P11)*_xlfn.NORM.S.DIST((Q11-P11)/S11,TRUE())+S11*_xlfn.NORM.S.DIST((Q11-P11)/S11,FALSE())) -> 13.055629 | U11: =EXP(-Inputs!$C$12*C11)*((P11-R11)*_xlfn.NORM.S.DIST((P11-R11)/S11,TRUE())+S11*_xlfn.NORM.S.DIST((P11-R11)/S11,FALSE())) -> 13.055629 | V11: =T11-U11 -> 0 | W11: 30.593227 | X11: =Inputs!$C$11/P11 -> 1.5357819 | Y11: =EXP(-Inputs!$C$12*C11)*(Q11*_xlfn.NORM.S.DIST(-(((LN(P11/Q11)+X11^2*C11/2)/(X11*SQRT(C11)))-X11*SQRT(C11)),TRUE())-P11*_xlfn.NORM.S.DIST(-((LN(P11/Q11)+X11^2*C11/2)/(X11*SQRT(C11))),TRUE())) -> 11.779832 | Z11: =EXP(-Inputs!$C$12*C11)*(P11*_xlfn.NORM.S.DIST(((LN(P11/W11)+X11^2*C11/2)/(X11*SQRT(C11))),TRUE())-W11*_xlfn.NORM.S.DIST((((LN(P11/W11)+X11^2*C11/2)/(X11*SQRT(C11)))-X11*SQRT(C11)),TRUE())) -> 11.779832 | AA11: =Y11-Z11 -> -8.2838172e-08
A12: 8 | B12: =DATE(2027,A12+1,1)-1 -> 46630 | C12: =(B12-Inputs!$C$7)/365 -> 0.84383562 | D12: =Inputs!$C$8 -> 40 | E12: =D12*(1-Inputs!$C$24) -> 38 | F12: =2*D12-E12 -> 42 | G12: =Inputs!$C$10*SQRT(C12) -> 41.070841 | H12: =EXP(-Inputs!$C$12*C12)*((E12-D12)*_xlfn.NORM.S.DIST((E12-D12)/G12,TRUE())+G12*_xlfn.NORM.S.DIST((E12-D12)/G12,FALSE())) -> 14.908135 | I12: =EXP(-Inputs!$C$12*C12)*((D12-F12)*_xlfn.NORM.S.DIST((D12-F12)/G12,TRUE())+G12*_xlfn.NORM.S.DIST((D12-F12)/G12,FALSE())) -> 14.908135 | J12: =H12-I12 -> 0 | K12: 44.833537 | L12: =Inputs!$C$10/D12 -> 1.11775 | M12: =EXP(-Inputs!$C$12*C12)*(E12*_xlfn.NORM.S.DIST(-(((LN(D12/E12)+L12^2*C12/2)/(L12*SQRT(C12)))-L12*SQRT(C12)),TRUE())-D12*_xlfn.NORM.S.DIST(-((LN(D12/E12)+L12^2*C12/2)/(L12*SQRT(C12))),TRUE())) -> 13.856691 | N12: =EXP(-Inputs!$C$12*C12)*(D12*_xlfn.NORM.S.DIST(((LN(D12/K12)+L12^2*C12/2)/(L12*SQRT(C12))),TRUE())-K12*_xlfn.NORM.S.DIST((((LN(D12/K12)+L12^2*C12/2)/(L12*SQRT(C12)))-L12*SQRT(C12)),TRUE())) -> 13.856691 | O12: =M12-N12 -> -1.0806801e-07 | P12: =Inputs!$C$9 -> 26.41 | Q12: =P12*(1-Inputs!$C$24) -> 25.0895 | R12: =2*P12-Q12 -> 27.7305 | S12: =Inputs!$C$11*SQRT(C12) -> 37.258629 | T12: =EXP(-Inputs!$C$12*C12)*((Q12-P12)*_xlfn.NORM.S.DIST((Q12-P12)/S12,TRUE())+S12*_xlfn.NORM.S.DIST((Q12-P12)/S12,FALSE())) -> 13.755313 | U12: =EXP(-Inputs!$C$12*C12)*((P12-R12)*_xlfn.NORM.S.DIST((P12-R12)/S12,TRUE())+S12*_xlfn.NORM.S.DIST((P12-R12)/S12,FALSE())) -> 13.755313 | V12: =T12-U12 -> 0 | W12: 30.873289 | X12: =Inputs!$C$11/P12 -> 1.5357819 | Y12: =EXP(-Inputs!$C$12*C12)*(Q12*_xlfn.NORM.S.DIST(-(((LN(P12/Q12)+X12^2*C12/2)/(X12*SQRT(C12)))-X12*SQRT(C12)),TRUE())-P12*_xlfn.NORM.S.DIST(-((LN(P12/Q12)+X12^2*C12/2)/(X12*SQRT(C12))),TRUE())) -> 12.312652 | Z12: =EXP(-Inputs!$C$12*C12)*(P12*_xlfn.NORM.S.DIST(((LN(P12/W12)+X12^2*C12/2)/(X12*SQRT(C12))),TRUE())-W12*_xlfn.NORM.S.DIST((((LN(P12/W12)+X12^2*C12/2)/(X12*SQRT(C12)))-X12*SQRT(C12)),TRUE())) -> 12.312652 | AA12: =Y12-Z12 -> 2.7840114e-08
A13: 9 | B13: =DATE(2027,A13+1,1)-1 -> 46660 | C13: =(B13-Inputs!$C$7)/365 -> 0.9260274 | D13: =Inputs!$C$8 -> 40 | E13: =D13*(1-Inputs!$C$24) -> 38 | F13: =2*D13-E13 -> 42 | G13: =Inputs!$C$10*SQRT(C13) -> 43.024575 | H13: =EXP(-Inputs!$C$12*C13)*((E13-D13)*_xlfn.NORM.S.DIST((E13-D13)/G13,TRUE())+G13*_xlfn.NORM.S.DIST((E13-D13)/G13,FALSE())) -> 15.611737 | I13: =EXP(-Inputs!$C$12*C13)*((D13-F13)*_xlfn.NORM.S.DIST((D13-F13)/G13,TRUE())+G13*_xlfn.NORM.S.DIST((D13-F13)/G13,FALSE())) -> 15.611737 | J13: =H13-I13 -> 0 | K13: 45.040382 | L13: =Inputs!$C$10/D13 -> 1.11775 | M13: =EXP(-Inputs!$C$12*C13)*(E13*_xlfn.NORM.S.DIST(-(((LN(D13/E13)+L13^2*C13/2)/(L13*SQRT(C13)))-L13*SQRT(C13)),TRUE())-D13*_xlfn.NORM.S.DIST(-((LN(D13/E13)+L13^2*C13/2)/(L13*SQRT(C13))),TRUE())) -> 14.450131 | N13: =EXP(-Inputs!$C$12*C13)*(D13*_xlfn.NORM.S.DIST(((LN(D13/K13)+L13^2*C13/2)/(L13*SQRT(C13))),TRUE())-K13*_xlfn.NORM.S.DIST((((LN(D13/K13)+L13^2*C13/2)/(L13*SQRT(C13)))-L13*SQRT(C13)),TRUE())) -> 14.450131 | O13: =M13-N13 -> -5.9500747e-08 | P13: =Inputs!$C$9 -> 26.41 | Q13: =P13*(1-Inputs!$C$24) -> 25.0895 | R13: =2*P13-Q13 -> 27.7305 | S13: =Inputs!$C$11*SQRT(C13) -> 39.031017 | T13: =EXP(-Inputs!$C$12*C13)*((Q13-P13)*_xlfn.NORM.S.DIST((Q13-P13)/S13,TRUE())+S13*_xlfn.NORM.S.DIST((Q13-P13)/S13,FALSE())) -> 14.393234 | U13: =EXP(-Inputs!$C$12*C13)*((P13-R13)*_xlfn.NORM.S.DIST((P13-R13)/S13,TRUE())+S13*_xlfn.NORM.S.DIST((P13-R13)/S13,FALSE())) -> 14.393234 | V13: =T13-U13 -> 0 | W13: 31.150266 | X13: =Inputs!$C$11/P13 -> 1.5357819 | Y13: =EXP(-Inputs!$C$12*C13)*(Q13*_xlfn.NORM.S.DIST(-(((LN(P13/Q13)+X13^2*C13/2)/(X13*SQRT(C13)))-X13*SQRT(C13)),TRUE())-P13*_xlfn.NORM.S.DIST(-((LN(P13/Q13)+X13^2*C13/2)/(X13*SQRT(C13))),TRUE())) -> 12.785361 | Z13: =EXP(-Inputs!$C$12*C13)*(P13*_xlfn.NORM.S.DIST(((LN(P13/W13)+X13^2*C13/2)/(X13*SQRT(C13))),TRUE())-W13*_xlfn.NORM.S.DIST((((LN(P13/W13)+X13^2*C13/2)/(X13*SQRT(C13)))-X13*SQRT(C13)),TRUE())) -> 12.785361 | AA13: =Y13-Z13 -> 2.953499e-08
A14: 10 | B14: =DATE(2027,A14+1,1)-1 -> 46691 | C14: =(B14-Inputs!$C$7)/365 -> 1.0109589 | D14: =Inputs!$C$8 -> 40 | E14: =D14*(1-Inputs!$C$24) -> 38 | F14: =2*D14-E14 -> 42 | G14: =Inputs!$C$10*SQRT(C14) -> 44.954319 | H14: =EXP(-Inputs!$C$12*C14)*((E14-D14)*_xlfn.NORM.S.DIST((E14-D14)/G14,TRUE())+G14*_xlfn.NORM.S.DIST((E14-D14)/G14,FALSE())) -> 16.299854 | I14: =EXP(-Inputs!$C$12*C14)*((D14-F14)*_xlfn.NORM.S.DIST((D14-F14)/G14,TRUE())+G14*_xlfn.NORM.S.DIST((D14-F14)/G14,FALSE())) -> 16.299854 | J14: =H14-I14 -> 0 | K14: 45.254426 | L14: =Inputs!$C$10/D14 -> 1.11775 | M14: =EXP(-Inputs!$C$12*C14)*(E14*_xlfn.NORM.S.DIST(-(((LN(D14/E14)+L14^2*C14/2)/(L14*SQRT(C14)))-L14*SQRT(C14)),TRUE())-D14*_xlfn.NORM.S.DIST(-((LN(D14/E14)+L14^2*C14/2)/(L14*SQRT(C14))),TRUE())) -> 15.022176 | N14: =EXP(-Inputs!$C$12*C14)*(D14*_xlfn.NORM.S.DIST(((LN(D14/K14)+L14^2*C14/2)/(L14*SQRT(C14))),TRUE())-K14*_xlfn.NORM.S.DIST((((LN(D14/K14)+L14^2*C14/2)/(L14*SQRT(C14)))-L14*SQRT(C14)),TRUE())) -> 15.022176 | O14: =M14-N14 -> 1.0861458e-08 | P14: =Inputs!$C$9 -> 26.41 | Q14: =P14*(1-Inputs!$C$24) -> 25.0895 | R14: =2*P14-Q14 -> 27.7305 | S14: =Inputs!$C$11*SQRT(C14) -> 40.781641 | T14: =EXP(-Inputs!$C$12*C14)*((Q14-P14)*_xlfn.NORM.S.DIST((Q14-P14)/S14,TRUE())+S14*_xlfn.NORM.S.DIST((Q14-P14)/S14,FALSE())) -> 15.017047 | U14: =EXP(-Inputs!$C$12*C14)*((P14-R14)*_xlfn.NORM.S.DIST((P14-R14)/S14,TRUE())+S14*_xlfn.NORM.S.DIST((P14-R14)/S14,FALSE())) -> 15.017047 | V14: =T14-U14 -> 0 | W14: 31.443381 | X14: =Inputs!$C$11/P14 -> 1.5357819 | Y14: =EXP(-Inputs!$C$12*C14)*(Q14*_xlfn.NORM.S.DIST(-(((LN(P14/Q14)+X14^2*C14/2)/(X14*SQRT(C14)))-X14*SQRT(C14)),TRUE())-P14*_xlfn.NORM.S.DIST(-((LN(P14/Q14)+X14^2*C14/2)/(X14*SQRT(C14))),TRUE())) -> 13.235023 | Z14: =EXP(-Inputs!$C$12*C14)*(P14*_xlfn.NORM.S.DIST(((LN(P14/W14)+X14^2*C14/2)/(X14*SQRT(C14))),TRUE())-W14*_xlfn.NORM.S.DIST((((LN(P14/W14)+X14^2*C14/2)/(X14*SQRT(C14)))-X14*SQRT(C14)),TRUE())) -> 13.235023 | AA14: =Y14-Z14 -> -7.5597066e-08
A15: 11 | B15: =DATE(2027,A15+1,1)-1 -> 46721 | C15: =(B15-Inputs!$C$7)/365 -> 1.0931507 | D15: =Inputs!$C$8 -> 40 | E15: =D15*(1-Inputs!$C$24) -> 38 | F15: =2*D15-E15 -> 42 | G15: =Inputs!$C$10*SQRT(C15) -> 46.746025 | H15: =EXP(-Inputs!$C$12*C15)*((E15-D15)*_xlfn.NORM.S.DIST((E15-D15)/G15,TRUE())+G15*_xlfn.NORM.S.DIST((E15-D15)/G15,FALSE())) -> 16.932408 | I15: =EXP(-Inputs!$C$12*C15)*((D15-F15)*_xlfn.NORM.S.DIST((D15-F15)/G15,TRUE())+G15*_xlfn.NORM.S.DIST((D15-F15)/G15,FALSE())) -> 16.932408 | J15: =H15-I15 -> 0 | K15: 45.462303 | L15: =Inputs!$C$10/D15 -> 1.11775 | M15: =EXP(-Inputs!$C$12*C15)*(E15*_xlfn.NORM.S.DIST(-(((LN(D15/E15)+L15^2*C15/2)/(L15*SQRT(C15)))-L15*SQRT(C15)),TRUE())-D15*_xlfn.NORM.S.DIST(-((LN(D15/E15)+L15^2*C15/2)/(L15*SQRT(C15))),TRUE())) -> 15.54039 | N15: =EXP(-Inputs!$C$12*C15)*(D15*_xlfn.NORM.S.DIST(((LN(D15/K15)+L15^2*C15/2)/(L15*SQRT(C15))),TRUE())-K15*_xlfn.NORM.S.DIST((((LN(D15/K15)+L15^2*C15/2)/(L15*SQRT(C15)))-L15*SQRT(C15)),TRUE())) -> 15.54039 | O15: =M15-N15 -> -2.913464e-08 | P15: =Inputs!$C$9 -> 26.41 | Q15: =P15*(1-Inputs!$C$24) -> 25.0895 | R15: =2*P15-Q15 -> 27.7305 | S15: =Inputs!$C$11*SQRT(C15) -> 42.40704 | T15: =EXP(-Inputs!$C$12*C15)*((Q15-P15)*_xlfn.NORM.S.DIST((Q15-P15)/S15,TRUE())+S15*_xlfn.NORM.S.DIST((Q15-P15)/S15,FALSE())) -> 15.590432 | U15: =EXP(-Inputs!$C$12*C15)*((P15-R15)*_xlfn.NORM.S.DIST((P15-R15)/S15,TRUE())+S15*_xlfn.NORM.S.DIST((P15-R15)/S15,FALSE())) -> 15.590432 | V15: =T15-U15 -> 0 | W15: 31.734377 | X15: =Inputs!$C$11/P15 -> 1.5357819 | Y15: =EXP(-Inputs!$C$12*C15)*(Q15*_xlfn.NORM.S.DIST(-(((LN(P15/Q15)+X15^2*C15/2)/(X15*SQRT(C15)))-X15*SQRT(C15)),TRUE())-P15*_xlfn.NORM.S.DIST(-((LN(P15/Q15)+X15^2*C15/2)/(X15*SQRT(C15))),TRUE())) -> 13.636919 | Z15: =EXP(-Inputs!$C$12*C15)*(P15*_xlfn.NORM.S.DIST(((LN(P15/W15)+X15^2*C15/2)/(X15*SQRT(C15))),TRUE())-W15*_xlfn.NORM.S.DIST((((LN(P15/W15)+X15^2*C15/2)/(X15*SQRT(C15)))-X15*SQRT(C15)),TRUE())) -> 13.636919 | AA15: =Y15-Z15 -> 5.071775e-08
A16: 12 | B16: =DATE(2027,A16+1,1)-1 -> 46752 | C16: =(B16-Inputs!$C$7)/365 -> 1.1780822 | D16: =Inputs!$C$8 -> 40 | E16: =D16*(1-Inputs!$C$24) -> 38 | F16: =2*D16-E16 -> 42 | G16: =Inputs!$C$10*SQRT(C16) -> 48.528008 | H16: =EXP(-Inputs!$C$12*C16)*((E16-D16)*_xlfn.NORM.S.DIST((E16-D16)/G16,TRUE())+G16*_xlfn.NORM.S.DIST((E16-D16)/G16,FALSE())) -> 17.555248 | I16: =EXP(-Inputs!$C$12*C16)*((D16-F16)*_xlfn.NORM.S.DIST((D16-F16)/G16,TRUE())+G16*_xlfn.NORM.S.DIST((D16-F16)/G16,FALSE())) -> 17.555248 | J16: =H16-I16 -> 0 | K16: 45.678259 | L16: =Inputs!$C$10/D16 -> 1.11775 | M16: =EXP(-Inputs!$C$12*C16)*(E16*_xlfn.NORM.S.DIST(-(((LN(D16/E16)+L16^2*C16/2)/(L16*SQRT(C16)))-L16*SQRT(C16)),TRUE())-D16*_xlfn.NORM.S.DIST(-((LN(D16/E16)+L16^2*C16/2)/(L16*SQRT(C16))),TRUE())) -> 16.043149 | N16: =EXP(-Inputs!$C$12*C16)*(D16*_xlfn.NORM.S.DIST(((LN(D16/K16)+L16^2*C16/2)/(L16*SQRT(C16))),TRUE())-K16*_xlfn.NORM.S.DIST((((LN(D16/K16)+L16^2*C16/2)/(L16*SQRT(C16)))-L16*SQRT(C16)),TRUE())) -> 16.043149 | O16: =M16-N16 -> 4.802688e-08 | P16: =Inputs!$C$9 -> 26.41 | Q16: =P16*(1-Inputs!$C$24) -> 25.0895 | R16: =2*P16-Q16 -> 27.7305 | S16: =Inputs!$C$11*SQRT(C16) -> 44.023619 | T16: =EXP(-Inputs!$C$12*C16)*((Q16-P16)*_xlfn.NORM.S.DIST((Q16-P16)/S16,TRUE())+S16*_xlfn.NORM.S.DIST((Q16-P16)/S16,FALSE())) -> 16.15496 | U16: =EXP(-Inputs!$C$12*C16)*((P16-R16)*_xlfn.NORM.S.DIST((P16-R16)/S16,TRUE())+S16*_xlfn.NORM.S.DIST((P16-R16)/S16,FALSE())) -> 16.15496 | V16: =T16-U16 -> 0 | W16: 32.043281 | X16: =Inputs!$C$11/P16 -> 1.5357819 | Y16: =EXP(-Inputs!$C$12*C16)*(Q16*_xlfn.NORM.S.DIST(-(((LN(P16/Q16)+X16^2*C16/2)/(X16*SQRT(C16)))-X16*SQRT(C16)),TRUE())-P16*_xlfn.NORM.S.DIST(-((LN(P16/Q16)+X16^2*C16/2)/(X16*SQRT(C16))),TRUE())) -> 14.021534 | Z16: =EXP(-Inputs!$C$12*C16)*(P16*_xlfn.NORM.S.DIST(((LN(P16/W16)+X16^2*C16/2)/(X16*SQRT(C16))),TRUE())-W16*_xlfn.NORM.S.DIST((((LN(P16/W16)+X16^2*C16/2)/(X16*SQRT(C16)))-X16*SQRT(C16)),TRUE())) -> 14.021534 | AA16: =Y16-Z16 -> 6.9069692e-09

Sheet Monthly
A1: 2027 month by month, selected case
A2: Hedged barrels are fixed on budget volumes. During an outage the sold calls have no barrels behind them. $ unless stated.
A4: Month | B4: Days | C4: Outage days | D4: Diesel and jet: Budget bbl | E4: Diesel and jet: Run bbl | F4: Diesel and jet: Hedged bbl | G4: Diesel and jet: Crack | H4: Diesel and jet: Payoff /bbl | I4: Diesel and jet: Physical $ | J4: Diesel and jet: Hedge $ | K4: Diesel and jet: Unbacked call $ | L4: Petrol: Budget bbl | M4: Petrol: Run bbl | N4: Petrol: Hedged bbl | O4: Petrol: Crack | P4: Petrol: Payoff /bbl | Q4: Petrol: Physical $ | R4: Petrol: Hedge $ | S4: Petrol: Unbacked call $ | T4: Budget margin $ | U4: Actual margin $
A5: =Pricing!A5 -> 1 | B5: =DAY(Pricing!B5) -> 31 | C5: =Inputs!$C$33*MAX(0,MIN(Pricing!B5,(Inputs!$C$27+Inputs!$C$26-1))-MAX(DATE(2027,A5,1),Inputs!$C$27)+1) -> 0 | D5: =Inputs!$C$17*Inputs!$C$18*Inputs!$C$19*B5 -> 1227600 | E5: =Inputs!$C$17*Inputs!$C$18*Inputs!$C$19*(B5-C5) -> 1227600 | F5: =Inputs!$C$31*D5 -> 982080 | G5: =Inputs!$C$8*(1+Inputs!$C$32) -> 52 | H5: =MAX(Pricing!$E$5-G5,0)-MAX(G5-Pricing!$F$5,0) -> -10 | I5: =E5*G5 -> 63835200 | J5: =F5*H5 -> -9820800 | K5: =Inputs!$C$31*Inputs!$C$17*Inputs!$C$18*Inputs!$C$19*C5*MIN(H5,0) -> 0 | L5: =Inputs!$C$17*Inputs!$C$18*Inputs!$C$20*B5 -> 954800 | M5: =Inputs!$C$17*Inputs!$C$18*Inputs!$C$20*(B5-C5) -> 954800 | N5: =Inputs!$C$31*L5 -> 763840 | O5: =Inputs!$C$9*(1+Inputs!$C$32) -> 34.333 | P5: =MAX(Pricing!$Q$5-O5,0)-MAX(O5-Pricing!$R$5,0) -> -6.6025 | Q5: =M5*O5 -> 32781148 | R5: =N5*P5 -> -5043253.6 | S5: =Inputs!$C$31*Inputs!$C$17*Inputs!$C$18*Inputs!$C$20*C5*MIN(P5,0) -> 0 | T5: =D5*Inputs!$C$8+L5*Inputs!$C$9 -> 74320268 | U5: =I5+J5+Q5+R5 -> 81752295
A6: =Pricing!A6 -> 2 | B6: =DAY(Pricing!B6) -> 28 | C6: =Inputs!$C$33*MAX(0,MIN(Pricing!B6,(Inputs!$C$27+Inputs!$C$26-1))-MAX(DATE(2027,A6,1),Inputs!$C$27)+1) -> 0 | D6: =Inputs!$C$17*Inputs!$C$18*Inputs!$C$19*B6 -> 1108800 | E6: =Inputs!$C$17*Inputs!$C$18*Inputs!$C$19*(B6-C6) -> 1108800 | F6: =Inputs!$C$31*D6 -> 887040 | G6: =Inputs!$C$8*(1+Inputs!$C$32) -> 52 | H6: =MAX(Pricing!$E$5-G6,0)-MAX(G6-Pricing!$F$5,0) -> -10 | I6: =E6*G6 -> 57657600 | J6: =F6*H6 -> -8870400 | K6: =Inputs!$C$31*Inputs!$C$17*Inputs!$C$18*Inputs!$C$19*C6*MIN(H6,0) -> 0 | L6: =Inputs!$C$17*Inputs!$C$18*Inputs!$C$20*B6 -> 862400 | M6: =Inputs!$C$17*Inputs!$C$18*Inputs!$C$20*(B6-C6) -> 862400 | N6: =Inputs!$C$31*L6 -> 689920 | O6: =Inputs!$C$9*(1+Inputs!$C$32) -> 34.333 | P6: =MAX(Pricing!$Q$5-O6,0)-MAX(O6-Pricing!$R$5,0) -> -6.6025 | Q6: =M6*O6 -> 29608779 | R6: =N6*P6 -> -4555196.8 | S6: =Inputs!$C$31*Inputs!$C$17*Inputs!$C$18*Inputs!$C$20*C6*MIN(P6,0) -> 0 | T6: =D6*Inputs!$C$8+L6*Inputs!$C$9 -> 67127984 | U6: =I6+J6+Q6+R6 -> 73840782
A7: =Pricing!A7 -> 3 | B7: =DAY(Pricing!B7) -> 31 | C7: =Inputs!$C$33*MAX(0,MIN(Pricing!B7,(Inputs!$C$27+Inputs!$C$26-1))-MAX(DATE(2027,A7,1),Inputs!$C$27)+1) -> 0 | D7: =Inputs!$C$17*Inputs!$C$18*Inputs!$C$19*B7 -> 1227600 | E7: =Inputs!$C$17*Inputs!$C$18*Inputs!$C$19*(B7-C7) -> 1227600 | F7: =Inputs!$C$31*D7 -> 982080 | G7: =Inputs!$C$8*(1+Inputs!$C$32) -> 52 | H7: =MAX(Pricing!$E$5-G7,0)-MAX(G7-Pricing!$F$5,0) -> -10 | I7: =E7*G7 -> 63835200 | J7: =F7*H7 -> -9820800 | K7: =Inputs!$C$31*Inputs!$C$17*Inputs!$C$18*Inputs!$C$19*C7*MIN(H7,0) -> 0 | L7: =Inputs!$C$17*Inputs!$C$18*Inputs!$C$20*B7 -> 954800 | M7: =Inputs!$C$17*Inputs!$C$18*Inputs!$C$20*(B7-C7) -> 954800 | N7: =Inputs!$C$31*L7 -> 763840 | O7: =Inputs!$C$9*(1+Inputs!$C$32) -> 34.333 | P7: =MAX(Pricing!$Q$5-O7,0)-MAX(O7-Pricing!$R$5,0) -> -6.6025 | Q7: =M7*O7 -> 32781148 | R7: =N7*P7 -> -5043253.6 | S7: =Inputs!$C$31*Inputs!$C$17*Inputs!$C$18*Inputs!$C$20*C7*MIN(P7,0) -> 0 | T7: =D7*Inputs!$C$8+L7*Inputs!$C$9 -> 74320268 | U7: =I7+J7+Q7+R7 -> 81752295
A8: =Pricing!A8 -> 4 | B8: =DAY(Pricing!B8) -> 30 | C8: =Inputs!$C$33*MAX(0,MIN(Pricing!B8,(Inputs!$C$27+Inputs!$C$26-1))-MAX(DATE(2027,A8,1),Inputs!$C$27)+1) -> 0 | D8: =Inputs!$C$17*Inputs!$C$18*Inputs!$C$19*B8 -> 1188000 | E8: =Inputs!$C$17*Inputs!$C$18*Inputs!$C$19*(B8-C8) -> 1188000 | F8: =Inputs!$C$31*D8 -> 950400 | G8: =Inputs!$C$8*(1+Inputs!$C$32) -> 52 | H8: =MAX(Pricing!$E$5-G8,0)-MAX(G8-Pricing!$F$5,0) -> -10 | I8: =E8*G8 -> 61776000 | J8: =F8*H8 -> -9504000 | K8: =Inputs!$C$31*Inputs!$C$17*Inputs!$C$18*Inputs!$C$19*C8*MIN(H8,0) -> 0 | L8: =Inputs!$C$17*Inputs!$C$18*Inputs!$C$20*B8 -> 924000 | M8: =Inputs!$C$17*Inputs!$C$18*Inputs!$C$20*(B8-C8) -> 924000 | N8: =Inputs!$C$31*L8 -> 739200 | O8: =Inputs!$C$9*(1+Inputs!$C$32) -> 34.333 | P8: =MAX(Pricing!$Q$5-O8,0)-MAX(O8-Pricing!$R$5,0) -> -6.6025 | Q8: =M8*O8 -> 31723692 | R8: =N8*P8 -> -4880568 | S8: =Inputs!$C$31*Inputs!$C$17*Inputs!$C$18*Inputs!$C$20*C8*MIN(P8,0) -> 0 | T8: =D8*Inputs!$C$8+L8*Inputs!$C$9 -> 71922840 | U8: =I8+J8+Q8+R8 -> 79115124
A9: =Pricing!A9 -> 5 | B9: =DAY(Pricing!B9) -> 31 | C9: =Inputs!$C$33*MAX(0,MIN(Pricing!B9,(Inputs!$C$27+Inputs!$C$26-1))-MAX(DATE(2027,A9,1),Inputs!$C$27)+1) -> 0 | D9: =Inputs!$C$17*Inputs!$C$18*Inputs!$C$19*B9 -> 1227600 | E9: =Inputs!$C$17*Inputs!$C$18*Inputs!$C$19*(B9-C9) -> 1227600 | F9: =Inputs!$C$31*D9 -> 982080 | G9: =Inputs!$C$8*(1+Inputs!$C$32) -> 52 | H9: =MAX(Pricing!$E$5-G9,0)-MAX(G9-Pricing!$F$5,0) -> -10 | I9: =E9*G9 -> 63835200 | J9: =F9*H9 -> -9820800 | K9: =Inputs!$C$31*Inputs!$C$17*Inputs!$C$18*Inputs!$C$19*C9*MIN(H9,0) -> 0 | L9: =Inputs!$C$17*Inputs!$C$18*Inputs!$C$20*B9 -> 954800 | M9: =Inputs!$C$17*Inputs!$C$18*Inputs!$C$20*(B9-C9) -> 954800 | N9: =Inputs!$C$31*L9 -> 763840 | O9: =Inputs!$C$9*(1+Inputs!$C$32) -> 34.333 | P9: =MAX(Pricing!$Q$5-O9,0)-MAX(O9-Pricing!$R$5,0) -> -6.6025 | Q9: =M9*O9 -> 32781148 | R9: =N9*P9 -> -5043253.6 | S9: =Inputs!$C$31*Inputs!$C$17*Inputs!$C$18*Inputs!$C$20*C9*MIN(P9,0) -> 0 | T9: =D9*Inputs!$C$8+L9*Inputs!$C$9 -> 74320268 | U9: =I9+J9+Q9+R9 -> 81752295
A10: =Pricing!A10 -> 6 | B10: =DAY(Pricing!B10) -> 30 | C10: =Inputs!$C$33*MAX(0,MIN(Pricing!B10,(Inputs!$C$27+Inputs!$C$26-1))-MAX(DATE(2027,A10,1),Inputs!$C$27)+1) -> 0 | D10: =Inputs!$C$17*Inputs!$C$18*Inputs!$C$19*B10 -> 1188000 | E10: =Inputs!$C$17*Inputs!$C$18*Inputs!$C$19*(B10-C10) -> 1188000 | F10: =Inputs!$C$31*D10 -> 950400 | G10: =Inputs!$C$8*(1+Inputs!$C$32) -> 52 | H10: =MAX(Pricing!$E$5-G10,0)-MAX(G10-Pricing!$F$5,0) -> -10 | I10: =E10*G10 -> 61776000 | J10: =F10*H10 -> -9504000 | K10: =Inputs!$C$31*Inputs!$C$17*Inputs!$C$18*Inputs!$C$19*C10*MIN(H10,0) -> 0 | L10: =Inputs!$C$17*Inputs!$C$18*Inputs!$C$20*B10 -> 924000 | M10: =Inputs!$C$17*Inputs!$C$18*Inputs!$C$20*(B10-C10) -> 924000 | N10: =Inputs!$C$31*L10 -> 739200 | O10: =Inputs!$C$9*(1+Inputs!$C$32) -> 34.333 | P10: =MAX(Pricing!$Q$5-O10,0)-MAX(O10-Pricing!$R$5,0) -> -6.6025 | Q10: =M10*O10 -> 31723692 | R10: =N10*P10 -> -4880568 | S10: =Inputs!$C$31*Inputs!$C$17*Inputs!$C$18*Inputs!$C$20*C10*MIN(P10,0) -> 0 | T10: =D10*Inputs!$C$8+L10*Inputs!$C$9 -> 71922840 | U10: =I10+J10+Q10+R10 -> 79115124
A11: =Pricing!A11 -> 7 | B11: =DAY(Pricing!B11) -> 31 | C11: =Inputs!$C$33*MAX(0,MIN(Pricing!B11,(Inputs!$C$27+Inputs!$C$26-1))-MAX(DATE(2027,A11,1),Inputs!$C$27)+1) -> 31 | D11: =Inputs!$C$17*Inputs!$C$18*Inputs!$C$19*B11 -> 1227600 | E11: =Inputs!$C$17*Inputs!$C$18*Inputs!$C$19*(B11-C11) -> 0 | F11: =Inputs!$C$31*D11 -> 982080 | G11: =Inputs!$C$8*(1+Inputs!$C$32) -> 52 | H11: =MAX(Pricing!$E$5-G11,0)-MAX(G11-Pricing!$F$5,0) -> -10 | I11: =E11*G11 -> 0 | J11: =F11*H11 -> -9820800 | K11: =Inputs!$C$31*Inputs!$C$17*Inputs!$C$18*Inputs!$C$19*C11*MIN(H11,0) -> -9820800 | L11: =Inputs!$C$17*Inputs!$C$18*Inputs!$C$20*B11 -> 954800 | M11: =Inputs!$C$17*Inputs!$C$18*Inputs!$C$20*(B11-C11) -> 0 | N11: =Inputs!$C$31*L11 -> 763840 | O11: =Inputs!$C$9*(1+Inputs!$C$32) -> 34.333 | P11: =MAX(Pricing!$Q$5-O11,0)-MAX(O11-Pricing!$R$5,0) -> -6.6025 | Q11: =M11*O11 -> 0 | R11: =N11*P11 -> -5043253.6 | S11: =Inputs!$C$31*Inputs!$C$17*Inputs!$C$18*Inputs!$C$20*C11*MIN(P11,0) -> -5043253.6 | T11: =D11*Inputs!$C$8+L11*Inputs!$C$9 -> 74320268 | U11: =I11+J11+Q11+R11 -> -14864054
A12: =Pricing!A12 -> 8 | B12: =DAY(Pricing!B12) -> 31 | C12: =Inputs!$C$33*MAX(0,MIN(Pricing!B12,(Inputs!$C$27+Inputs!$C$26-1))-MAX(DATE(2027,A12,1),Inputs!$C$27)+1) -> 11 | D12: =Inputs!$C$17*Inputs!$C$18*Inputs!$C$19*B12 -> 1227600 | E12: =Inputs!$C$17*Inputs!$C$18*Inputs!$C$19*(B12-C12) -> 792000 | F12: =Inputs!$C$31*D12 -> 982080 | G12: =Inputs!$C$8*(1+Inputs!$C$32) -> 52 | H12: =MAX(Pricing!$E$5-G12,0)-MAX(G12-Pricing!$F$5,0) -> -10 | I12: =E12*G12 -> 41184000 | J12: =F12*H12 -> -9820800 | K12: =Inputs!$C$31*Inputs!$C$17*Inputs!$C$18*Inputs!$C$19*C12*MIN(H12,0) -> -3484800 | L12: =Inputs!$C$17*Inputs!$C$18*Inputs!$C$20*B12 -> 954800 | M12: =Inputs!$C$17*Inputs!$C$18*Inputs!$C$20*(B12-C12) -> 616000 | N12: =Inputs!$C$31*L12 -> 763840 | O12: =Inputs!$C$9*(1+Inputs!$C$32) -> 34.333 | P12: =MAX(Pricing!$Q$5-O12,0)-MAX(O12-Pricing!$R$5,0) -> -6.6025 | Q12: =M12*O12 -> 21149128 | R12: =N12*P12 -> -5043253.6 | S12: =Inputs!$C$31*Inputs!$C$17*Inputs!$C$18*Inputs!$C$20*C12*MIN(P12,0) -> -1789541.6 | T12: =D12*Inputs!$C$8+L12*Inputs!$C$9 -> 74320268 | U12: =I12+J12+Q12+R12 -> 47469074
A13: =Pricing!A13 -> 9 | B13: =DAY(Pricing!B13) -> 30 | C13: =Inputs!$C$33*MAX(0,MIN(Pricing!B13,(Inputs!$C$27+Inputs!$C$26-1))-MAX(DATE(2027,A13,1),Inputs!$C$27)+1) -> 0 | D13: =Inputs!$C$17*Inputs!$C$18*Inputs!$C$19*B13 -> 1188000 | E13: =Inputs!$C$17*Inputs!$C$18*Inputs!$C$19*(B13-C13) -> 1188000 | F13: =Inputs!$C$31*D13 -> 950400 | G13: =Inputs!$C$8*(1+Inputs!$C$32) -> 52 | H13: =MAX(Pricing!$E$5-G13,0)-MAX(G13-Pricing!$F$5,0) -> -10 | I13: =E13*G13 -> 61776000 | J13: =F13*H13 -> -9504000 | K13: =Inputs!$C$31*Inputs!$C$17*Inputs!$C$18*Inputs!$C$19*C13*MIN(H13,0) -> 0 | L13: =Inputs!$C$17*Inputs!$C$18*Inputs!$C$20*B13 -> 924000 | M13: =Inputs!$C$17*Inputs!$C$18*Inputs!$C$20*(B13-C13) -> 924000 | N13: =Inputs!$C$31*L13 -> 739200 | O13: =Inputs!$C$9*(1+Inputs!$C$32) -> 34.333 | P13: =MAX(Pricing!$Q$5-O13,0)-MAX(O13-Pricing!$R$5,0) -> -6.6025 | Q13: =M13*O13 -> 31723692 | R13: =N13*P13 -> -4880568 | S13: =Inputs!$C$31*Inputs!$C$17*Inputs!$C$18*Inputs!$C$20*C13*MIN(P13,0) -> 0 | T13: =D13*Inputs!$C$8+L13*Inputs!$C$9 -> 71922840 | U13: =I13+J13+Q13+R13 -> 79115124
A14: =Pricing!A14 -> 10 | B14: =DAY(Pricing!B14) -> 31 | C14: =Inputs!$C$33*MAX(0,MIN(Pricing!B14,(Inputs!$C$27+Inputs!$C$26-1))-MAX(DATE(2027,A14,1),Inputs!$C$27)+1) -> 0 | D14: =Inputs!$C$17*Inputs!$C$18*Inputs!$C$19*B14 -> 1227600 | E14: =Inputs!$C$17*Inputs!$C$18*Inputs!$C$19*(B14-C14) -> 1227600 | F14: =Inputs!$C$31*D14 -> 982080 | G14: =Inputs!$C$8*(1+Inputs!$C$32) -> 52 | H14: =MAX(Pricing!$E$5-G14,0)-MAX(G14-Pricing!$F$5,0) -> -10 | I14: =E14*G14 -> 63835200 | J14: =F14*H14 -> -9820800 | K14: =Inputs!$C$31*Inputs!$C$17*Inputs!$C$18*Inputs!$C$19*C14*MIN(H14,0) -> 0 | L14: =Inputs!$C$17*Inputs!$C$18*Inputs!$C$20*B14 -> 954800 | M14: =Inputs!$C$17*Inputs!$C$18*Inputs!$C$20*(B14-C14) -> 954800 | N14: =Inputs!$C$31*L14 -> 763840 | O14: =Inputs!$C$9*(1+Inputs!$C$32) -> 34.333 | P14: =MAX(Pricing!$Q$5-O14,0)-MAX(O14-Pricing!$R$5,0) -> -6.6025 | Q14: =M14*O14 -> 32781148 | R14: =N14*P14 -> -5043253.6 | S14: =Inputs!$C$31*Inputs!$C$17*Inputs!$C$18*Inputs!$C$20*C14*MIN(P14,0) -> 0 | T14: =D14*Inputs!$C$8+L14*Inputs!$C$9 -> 74320268 | U14: =I14+J14+Q14+R14 -> 81752295
A15: =Pricing!A15 -> 11 | B15: =DAY(Pricing!B15) -> 30 | C15: =Inputs!$C$33*MAX(0,MIN(Pricing!B15,(Inputs!$C$27+Inputs!$C$26-1))-MAX(DATE(2027,A15,1),Inputs!$C$27)+1) -> 0 | D15: =Inputs!$C$17*Inputs!$C$18*Inputs!$C$19*B15 -> 1188000 | E15: =Inputs!$C$17*Inputs!$C$18*Inputs!$C$19*(B15-C15) -> 1188000 | F15: =Inputs!$C$31*D15 -> 950400 | G15: =Inputs!$C$8*(1+Inputs!$C$32) -> 52 | H15: =MAX(Pricing!$E$5-G15,0)-MAX(G15-Pricing!$F$5,0) -> -10 | I15: =E15*G15 -> 61776000 | J15: =F15*H15 -> -9504000 | K15: =Inputs!$C$31*Inputs!$C$17*Inputs!$C$18*Inputs!$C$19*C15*MIN(H15,0) -> 0 | L15: =Inputs!$C$17*Inputs!$C$18*Inputs!$C$20*B15 -> 924000 | M15: =Inputs!$C$17*Inputs!$C$18*Inputs!$C$20*(B15-C15) -> 924000 | N15: =Inputs!$C$31*L15 -> 739200 | O15: =Inputs!$C$9*(1+Inputs!$C$32) -> 34.333 | P15: =MAX(Pricing!$Q$5-O15,0)-MAX(O15-Pricing!$R$5,0) -> -6.6025 | Q15: =M15*O15 -> 31723692 | R15: =N15*P15 -> -4880568 | S15: =Inputs!$C$31*Inputs!$C$17*Inputs!$C$18*Inputs!$C$20*C15*MIN(P15,0) -> 0 | T15: =D15*Inputs!$C$8+L15*Inputs!$C$9 -> 71922840 | U15: =I15+J15+Q15+R15 -> 79115124
A16: =Pricing!A16 -> 12 | B16: =DAY(Pricing!B16) -> 31 | C16: =Inputs!$C$33*MAX(0,MIN(Pricing!B16,(Inputs!$C$27+Inputs!$C$26-1))-MAX(DATE(2027,A16,1),Inputs!$C$27)+1) -> 0 | D16: =Inputs!$C$17*Inputs!$C$18*Inputs!$C$19*B16 -> 1227600 | E16: =Inputs!$C$17*Inputs!$C$18*Inputs!$C$19*(B16-C16) -> 1227600 | F16: =Inputs!$C$31*D16 -> 982080 | G16: =Inputs!$C$8*(1+Inputs!$C$32) -> 52 | H16: =MAX(Pricing!$E$5-G16,0)-MAX(G16-Pricing!$F$5,0) -> -10 | I16: =E16*G16 -> 63835200 | J16: =F16*H16 -> -9820800 | K16: =Inputs!$C$31*Inputs!$C$17*Inputs!$C$18*Inputs!$C$19*C16*MIN(H16,0) -> 0 | L16: =Inputs!$C$17*Inputs!$C$18*Inputs!$C$20*B16 -> 954800 | M16: =Inputs!$C$17*Inputs!$C$18*Inputs!$C$20*(B16-C16) -> 954800 | N16: =Inputs!$C$31*L16 -> 763840 | O16: =Inputs!$C$9*(1+Inputs!$C$32) -> 34.333 | P16: =MAX(Pricing!$Q$5-O16,0)-MAX(O16-Pricing!$R$5,0) -> -6.6025 | Q16: =M16*O16 -> 32781148 | R16: =N16*P16 -> -5043253.6 | S16: =Inputs!$C$31*Inputs!$C$17*Inputs!$C$18*Inputs!$C$20*C16*MIN(P16,0) -> 0 | T16: =D16*Inputs!$C$8+L16*Inputs!$C$9 -> 74320268 | U16: =I16+J16+Q16+R16 -> 81752295
A17: Total | B17: =SUM(B5:B16) -> 365 | C17: =SUM(C5:C16) -> 42 | D17: =SUM(D5:D16) -> 14454000 | E17: =SUM(E5:E16) -> 12790800 | F17: =SUM(F5:F16) -> 11563200 | I17: =SUM(I5:I16) -> 665121600 | J17: =SUM(J5:J16) -> -115632000 | K17: =SUM(K5:K16) -> -13305600 | L17: =SUM(L5:L16) -> 11242000 | M17: =SUM(M5:M16) -> 9948400 | N17: =SUM(N5:N16) -> 8993600 | Q17: =SUM(Q5:Q16) -> 3.4155842e+08 | R17: =SUM(R5:R16) -> -59380244 | S17: =SUM(S5:S16) -> -6832795.2 | T17: =SUM(T5:T16) -> 875061220 | U17: =SUM(U5:U16) -> 8.3166777e+08
A19: Margin change vs budget | C19: =U17/T17-1 -> -0.049589041
A20: Unbacked call cost / budget margin | C20: =-(K17+S17)/T17 -> 0.023013699

Sheet Scenarios
A1: Hedge ratio scenarios
A2: Refining margin change vs budget for a parallel 2027 crack move. Uses January strikes (Bachelier strikes are the same in every month).
A4: Margin weight, diesel and jet | C4: =Inputs!$C$19*Inputs!$C$8/(Inputs!$C$19*Inputs!$C$8+Inputs!$C$20*Inputs!$C$9) -> 0.66070806
A5: Margin weight, petrol | C5: =1-C4 -> 0.33929194
A7: Cover \ crack move | B7: -0.3 | C7: -0.15 | D7: 0 | E7: 0.15 | F7: 0.3
A8: 0 | B8: =B$7+$A8*($C$4*(MAX(Pricing!$E$5-Inputs!$C$8*(1+B$7),0)-MAX(Inputs!$C$8*(1+B$7)-Pricing!$F$5,0))/Inputs!$C$8+$C$5*(MAX(Pricing!$Q$5-Inputs!$C$9*(1+B$7),0)-MAX(Inputs!$C$9*(1+B$7)-Pricing!$R$5,0))/Inputs!$C$9) -> -0.3 | C8: =C$7+$A8*($C$4*(MAX(Pricing!$E$5-Inputs!$C$8*(1+C$7),0)-MAX(Inputs!$C$8*(1+C$7)-Pricing!$F$5,0))/Inputs!$C$8+$C$5*(MAX(Pricing!$Q$5-Inputs!$C$9*(1+C$7),0)-MAX(Inputs!$C$9*(1+C$7)-Pricing!$R$5,0))/Inputs!$C$9) -> -0.15 | D8: =D$7+$A8*($C$4*(MAX(Pricing!$E$5-Inputs!$C$8*(1+D$7),0)-MAX(Inputs!$C$8*(1+D$7)-Pricing!$F$5,0))/Inputs!$C$8+$C$5*(MAX(Pricing!$Q$5-Inputs!$C$9*(1+D$7),0)-MAX(Inputs!$C$9*(1+D$7)-Pricing!$R$5,0))/Inputs!$C$9) -> 0 | E8: =E$7+$A8*($C$4*(MAX(Pricing!$E$5-Inputs!$C$8*(1+E$7),0)-MAX(Inputs!$C$8*(1+E$7)-Pricing!$F$5,0))/Inputs!$C$8+$C$5*(MAX(Pricing!$Q$5-Inputs!$C$9*(1+E$7),0)-MAX(Inputs!$C$9*(1+E$7)-Pricing!$R$5,0))/Inputs!$C$9) -> 0.15 | F8: =F$7+$A8*($C$4*(MAX(Pricing!$E$5-Inputs!$C$8*(1+F$7),0)-MAX(Inputs!$C$8*(1+F$7)-Pricing!$F$5,0))/Inputs!$C$8+$C$5*(MAX(Pricing!$Q$5-Inputs!$C$9*(1+F$7),0)-MAX(Inputs!$C$9*(1+F$7)-Pricing!$R$5,0))/Inputs!$C$9) -> 0.3
A9: 0.5 | B9: =B$7+$A9*($C$4*(MAX(Pricing!$E$5-Inputs!$C$8*(1+B$7),0)-MAX(Inputs!$C$8*(1+B$7)-Pricing!$F$5,0))/Inputs!$C$8+$C$5*(MAX(Pricing!$Q$5-Inputs!$C$9*(1+B$7),0)-MAX(Inputs!$C$9*(1+B$7)-Pricing!$R$5,0))/Inputs!$C$9) -> -0.175 | C9: =C$7+$A9*($C$4*(MAX(Pricing!$E$5-Inputs!$C$8*(1+C$7),0)-MAX(Inputs!$C$8*(1+C$7)-Pricing!$F$5,0))/Inputs!$C$8+$C$5*(MAX(Pricing!$Q$5-Inputs!$C$9*(1+C$7),0)-MAX(Inputs!$C$9*(1+C$7)-Pricing!$R$5,0))/Inputs!$C$9) -> -0.1 | D9: =D$7+$A9*($C$4*(MAX(Pricing!$E$5-Inputs!$C$8*(1+D$7),0)-MAX(Inputs!$C$8*(1+D$7)-Pricing!$F$5,0))/Inputs!$C$8+$C$5*(MAX(Pricing!$Q$5-Inputs!$C$9*(1+D$7),0)-MAX(Inputs!$C$9*(1+D$7)-Pricing!$R$5,0))/Inputs!$C$9) -> 0 | E9: =E$7+$A9*($C$4*(MAX(Pricing!$E$5-Inputs!$C$8*(1+E$7),0)-MAX(Inputs!$C$8*(1+E$7)-Pricing!$F$5,0))/Inputs!$C$8+$C$5*(MAX(Pricing!$Q$5-Inputs!$C$9*(1+E$7),0)-MAX(Inputs!$C$9*(1+E$7)-Pricing!$R$5,0))/Inputs!$C$9) -> 0.1 | F9: =F$7+$A9*($C$4*(MAX(Pricing!$E$5-Inputs!$C$8*(1+F$7),0)-MAX(Inputs!$C$8*(1+F$7)-Pricing!$F$5,0))/Inputs!$C$8+$C$5*(MAX(Pricing!$Q$5-Inputs!$C$9*(1+F$7),0)-MAX(Inputs!$C$9*(1+F$7)-Pricing!$R$5,0))/Inputs!$C$9) -> 0.175
A10: 0.7 | B10: =B$7+$A10*($C$4*(MAX(Pricing!$E$5-Inputs!$C$8*(1+B$7),0)-MAX(Inputs!$C$8*(1+B$7)-Pricing!$F$5,0))/Inputs!$C$8+$C$5*(MAX(Pricing!$Q$5-Inputs!$C$9*(1+B$7),0)-MAX(Inputs!$C$9*(1+B$7)-Pricing!$R$5,0))/Inputs!$C$9) -> -0.125 | C10: =C$7+$A10*($C$4*(MAX(Pricing!$E$5-Inputs!$C$8*(1+C$7),0)-MAX(Inputs!$C$8*(1+C$7)-Pricing!$F$5,0))/Inputs!$C$8+$C$5*(MAX(Pricing!$Q$5-Inputs!$C$9*(1+C$7),0)-MAX(Inputs!$C$9*(1+C$7)-Pricing!$R$5,0))/Inputs!$C$9) -> -0.08 | D10: =D$7+$A10*($C$4*(MAX(Pricing!$E$5-Inputs!$C$8*(1+D$7),0)-MAX(Inputs!$C$8*(1+D$7)-Pricing!$F$5,0))/Inputs!$C$8+$C$5*(MAX(Pricing!$Q$5-Inputs!$C$9*(1+D$7),0)-MAX(Inputs!$C$9*(1+D$7)-Pricing!$R$5,0))/Inputs!$C$9) -> 0 | E10: =E$7+$A10*($C$4*(MAX(Pricing!$E$5-Inputs!$C$8*(1+E$7),0)-MAX(Inputs!$C$8*(1+E$7)-Pricing!$F$5,0))/Inputs!$C$8+$C$5*(MAX(Pricing!$Q$5-Inputs!$C$9*(1+E$7),0)-MAX(Inputs!$C$9*(1+E$7)-Pricing!$R$5,0))/Inputs!$C$9) -> 0.08 | F10: =F$7+$A10*($C$4*(MAX(Pricing!$E$5-Inputs!$C$8*(1+F$7),0)-MAX(Inputs!$C$8*(1+F$7)-Pricing!$F$5,0))/Inputs!$C$8+$C$5*(MAX(Pricing!$Q$5-Inputs!$C$9*(1+F$7),0)-MAX(Inputs!$C$9*(1+F$7)-Pricing!$R$5,0))/Inputs!$C$9) -> 0.125
A11: 0.8 | B11: =B$7+$A11*($C$4*(MAX(Pricing!$E$5-Inputs!$C$8*(1+B$7),0)-MAX(Inputs!$C$8*(1+B$7)-Pricing!$F$5,0))/Inputs!$C$8+$C$5*(MAX(Pricing!$Q$5-Inputs!$C$9*(1+B$7),0)-MAX(Inputs!$C$9*(1+B$7)-Pricing!$R$5,0))/Inputs!$C$9) -> -0.1 | C11: =C$7+$A11*($C$4*(MAX(Pricing!$E$5-Inputs!$C$8*(1+C$7),0)-MAX(Inputs!$C$8*(1+C$7)-Pricing!$F$5,0))/Inputs!$C$8+$C$5*(MAX(Pricing!$Q$5-Inputs!$C$9*(1+C$7),0)-MAX(Inputs!$C$9*(1+C$7)-Pricing!$R$5,0))/Inputs!$C$9) -> -0.07 | D11: =D$7+$A11*($C$4*(MAX(Pricing!$E$5-Inputs!$C$8*(1+D$7),0)-MAX(Inputs!$C$8*(1+D$7)-Pricing!$F$5,0))/Inputs!$C$8+$C$5*(MAX(Pricing!$Q$5-Inputs!$C$9*(1+D$7),0)-MAX(Inputs!$C$9*(1+D$7)-Pricing!$R$5,0))/Inputs!$C$9) -> 0 | E11: =E$7+$A11*($C$4*(MAX(Pricing!$E$5-Inputs!$C$8*(1+E$7),0)-MAX(Inputs!$C$8*(1+E$7)-Pricing!$F$5,0))/Inputs!$C$8+$C$5*(MAX(Pricing!$Q$5-Inputs!$C$9*(1+E$7),0)-MAX(Inputs!$C$9*(1+E$7)-Pricing!$R$5,0))/Inputs!$C$9) -> 0.07 | F11: =F$7+$A11*($C$4*(MAX(Pricing!$E$5-Inputs!$C$8*(1+F$7),0)-MAX(Inputs!$C$8*(1+F$7)-Pricing!$F$5,0))/Inputs!$C$8+$C$5*(MAX(Pricing!$Q$5-Inputs!$C$9*(1+F$7),0)-MAX(Inputs!$C$9*(1+F$7)-Pricing!$R$5,0))/Inputs!$C$9) -> 0.1
A12: 0.9 | B12: =B$7+$A12*($C$4*(MAX(Pricing!$E$5-Inputs!$C$8*(1+B$7),0)-MAX(Inputs!$C$8*(1+B$7)-Pricing!$F$5,0))/Inputs!$C$8+$C$5*(MAX(Pricing!$Q$5-Inputs!$C$9*(1+B$7),0)-MAX(Inputs!$C$9*(1+B$7)-Pricing!$R$5,0))/Inputs!$C$9) -> -0.075 | C12: =C$7+$A12*($C$4*(MAX(Pricing!$E$5-Inputs!$C$8*(1+C$7),0)-MAX(Inputs!$C$8*(1+C$7)-Pricing!$F$5,0))/Inputs!$C$8+$C$5*(MAX(Pricing!$Q$5-Inputs!$C$9*(1+C$7),0)-MAX(Inputs!$C$9*(1+C$7)-Pricing!$R$5,0))/Inputs!$C$9) -> -0.06 | D12: =D$7+$A12*($C$4*(MAX(Pricing!$E$5-Inputs!$C$8*(1+D$7),0)-MAX(Inputs!$C$8*(1+D$7)-Pricing!$F$5,0))/Inputs!$C$8+$C$5*(MAX(Pricing!$Q$5-Inputs!$C$9*(1+D$7),0)-MAX(Inputs!$C$9*(1+D$7)-Pricing!$R$5,0))/Inputs!$C$9) -> 0 | E12: =E$7+$A12*($C$4*(MAX(Pricing!$E$5-Inputs!$C$8*(1+E$7),0)-MAX(Inputs!$C$8*(1+E$7)-Pricing!$F$5,0))/Inputs!$C$8+$C$5*(MAX(Pricing!$Q$5-Inputs!$C$9*(1+E$7),0)-MAX(Inputs!$C$9*(1+E$7)-Pricing!$R$5,0))/Inputs!$C$9) -> 0.06 | F12: =F$7+$A12*($C$4*(MAX(Pricing!$E$5-Inputs!$C$8*(1+F$7),0)-MAX(Inputs!$C$8*(1+F$7)-Pricing!$F$5,0))/Inputs!$C$8+$C$5*(MAX(Pricing!$Q$5-Inputs!$C$9*(1+F$7),0)-MAX(Inputs!$C$9*(1+F$7)-Pricing!$R$5,0))/Inputs!$C$9) -> 0.075
A15: Cover | B15: 30% fall | C15: Outage: unbacked call cost | D15: Outage + spike: total change | E15: Within appetite
A16: 0.5 | B16: =-0.3+$A16*($C$4*(MAX(Pricing!$E$5-Inputs!$C$8*(1+-0.3),0)-MAX(Inputs!$C$8*(1+-0.3)-Pricing!$F$5,0))/Inputs!$C$8+$C$5*(MAX(Pricing!$Q$5-Inputs!$C$9*(1+-0.3),0)-MAX(Inputs!$C$9*(1+-0.3)-Pricing!$R$5,0))/Inputs!$C$9) -> -0.175 | C16: =-$A16*Inputs!$C$26/365*($C$4*MIN(MAX(Pricing!$E$5-Inputs!$C$8*(1+Inputs!$C$28),0)-MAX(Inputs!$C$8*(1+Inputs!$C$28)-Pricing!$F$5,0),0)/Inputs!$C$8+$C$5*MIN(MAX(Pricing!$Q$5-Inputs!$C$9*(1+Inputs!$C$28),0)-MAX(Inputs!$C$9*(1+Inputs!$C$28)-Pricing!$R$5,0),0)/Inputs!$C$9) -> 0.014383562 | D16: =(1+Inputs!$C$28)*(1-Inputs!$C$26/365)+$A16*($C$4*(MAX(Pricing!$E$5-Inputs!$C$8*(1+Inputs!$C$28),0)-MAX(Inputs!$C$8*(1+Inputs!$C$28)-Pricing!$F$5,0))/Inputs!$C$8+$C$5*(MAX(Pricing!$Q$5-Inputs!$C$9*(1+Inputs!$C$28),0)-MAX(Inputs!$C$9*(1+Inputs!$C$28)-Pricing!$R$5,0))/Inputs!$C$9)-1 -> 0.025410959 | E16: =IF(C16<=Inputs!$C$25,1,0) -> 1
A17: 0.7 | B17: =-0.3+$A17*($C$4*(MAX(Pricing!$E$5-Inputs!$C$8*(1+-0.3),0)-MAX(Inputs!$C$8*(1+-0.3)-Pricing!$F$5,0))/Inputs!$C$8+$C$5*(MAX(Pricing!$Q$5-Inputs!$C$9*(1+-0.3),0)-MAX(Inputs!$C$9*(1+-0.3)-Pricing!$R$5,0))/Inputs!$C$9) -> -0.125 | C17: =-$A17*Inputs!$C$26/365*($C$4*MIN(MAX(Pricing!$E$5-Inputs!$C$8*(1+Inputs!$C$28),0)-MAX(Inputs!$C$8*(1+Inputs!$C$28)-Pricing!$F$5,0),0)/Inputs!$C$8+$C$5*MIN(MAX(Pricing!$Q$5-Inputs!$C$9*(1+Inputs!$C$28),0)-MAX(Inputs!$C$9*(1+Inputs!$C$28)-Pricing!$R$5,0),0)/Inputs!$C$9) -> 0.020136986 | D17: =(1+Inputs!$C$28)*(1-Inputs!$C$26/365)+$A17*($C$4*(MAX(Pricing!$E$5-Inputs!$C$8*(1+Inputs!$C$28),0)-MAX(Inputs!$C$8*(1+Inputs!$C$28)-Pricing!$F$5,0))/Inputs!$C$8+$C$5*(MAX(Pricing!$Q$5-Inputs!$C$9*(1+Inputs!$C$28),0)-MAX(Inputs!$C$9*(1+Inputs!$C$28)-Pricing!$R$5,0))/Inputs!$C$9)-1 -> -0.024589041 | E17: =IF(C17<=Inputs!$C$25,1,0) -> 1
A18: 0.8 | B18: =-0.3+$A18*($C$4*(MAX(Pricing!$E$5-Inputs!$C$8*(1+-0.3),0)-MAX(Inputs!$C$8*(1+-0.3)-Pricing!$F$5,0))/Inputs!$C$8+$C$5*(MAX(Pricing!$Q$5-Inputs!$C$9*(1+-0.3),0)-MAX(Inputs!$C$9*(1+-0.3)-Pricing!$R$5,0))/Inputs!$C$9) -> -0.1 | C18: =-$A18*Inputs!$C$26/365*($C$4*MIN(MAX(Pricing!$E$5-Inputs!$C$8*(1+Inputs!$C$28),0)-MAX(Inputs!$C$8*(1+Inputs!$C$28)-Pricing!$F$5,0),0)/Inputs!$C$8+$C$5*MIN(MAX(Pricing!$Q$5-Inputs!$C$9*(1+Inputs!$C$28),0)-MAX(Inputs!$C$9*(1+Inputs!$C$28)-Pricing!$R$5,0),0)/Inputs!$C$9) -> 0.023013699 | D18: =(1+Inputs!$C$28)*(1-Inputs!$C$26/365)+$A18*($C$4*(MAX(Pricing!$E$5-Inputs!$C$8*(1+Inputs!$C$28),0)-MAX(Inputs!$C$8*(1+Inputs!$C$28)-Pricing!$F$5,0))/Inputs!$C$8+$C$5*(MAX(Pricing!$Q$5-Inputs!$C$9*(1+Inputs!$C$28),0)-MAX(Inputs!$C$9*(1+Inputs!$C$28)-Pricing!$R$5,0))/Inputs!$C$9)-1 -> -0.049589041 | E18: =IF(C18<=Inputs!$C$25,1,0) -> 1
A19: 0.9 | B19: =-0.3+$A19*($C$4*(MAX(Pricing!$E$5-Inputs!$C$8*(1+-0.3),0)-MAX(Inputs!$C$8*(1+-0.3)-Pricing!$F$5,0))/Inputs!$C$8+$C$5*(MAX(Pricing!$Q$5-Inputs!$C$9*(1+-0.3),0)-MAX(Inputs!$C$9*(1+-0.3)-Pricing!$R$5,0))/Inputs!$C$9) -> -0.075 | C19: =-$A19*Inputs!$C$26/365*($C$4*MIN(MAX(Pricing!$E$5-Inputs!$C$8*(1+Inputs!$C$28),0)-MAX(Inputs!$C$8*(1+Inputs!$C$28)-Pricing!$F$5,0),0)/Inputs!$C$8+$C$5*MIN(MAX(Pricing!$Q$5-Inputs!$C$9*(1+Inputs!$C$28),0)-MAX(Inputs!$C$9*(1+Inputs!$C$28)-Pricing!$R$5,0),0)/Inputs!$C$9) -> 0.025890411 | D19: =(1+Inputs!$C$28)*(1-Inputs!$C$26/365)+$A19*($C$4*(MAX(Pricing!$E$5-Inputs!$C$8*(1+Inputs!$C$28),0)-MAX(Inputs!$C$8*(1+Inputs!$C$28)-Pricing!$F$5,0))/Inputs!$C$8+$C$5*(MAX(Pricing!$Q$5-Inputs!$C$9*(1+Inputs!$C$28),0)-MAX(Inputs!$C$9*(1+Inputs!$C$28)-Pricing!$R$5,0))/Inputs!$C$9)-1 -> -0.074589041 | E19: =IF(C19<=Inputs!$C$25,1,0) -> 0
A21: Recommended cover (most protection within appetite) | D21: =_xlfn.MAXIFS(A16:A19,E16:E19,1) -> 0.8

Sheet FX
A1: ZAR overlay: sell USD forward against the rand cost budget
A2: The refinery earns dollars and pays rand costs. Selling dollars forward locks the rand value of the cost budget. ZAR millions.
A4: Month | B4: t (yrs) | C4: USD/ZAR forward | D4: USD margin $m | E4: Rand cost Rm | F4: USD sold $m | G4: Unhedged -15% | H4: Hedged -15% | I4: Unhedged +0% | J4: Hedged +0% | K4: Unhedged +15% | L4: Hedged +15%
A5: =Pricing!A5 -> 1 | B5: =Pricing!C5 -> 0.2630137 | C5: =Inputs!$C$14*((1+Inputs!$C$13)/(1+Inputs!$C$12))^B5 -> 16.781121 | D5: =(Monthly!D5*Inputs!$C$8+Monthly!L5*Inputs!$C$9)/1000000 -> 74.320268 | E5: =Inputs!$C$17*Inputs!$C$18*Monthly!B5*Inputs!$C$21/1000000 -> 272.8 | F5: =E5/C5 -> 16.256363 | G5: =D5*C5*(1+-0.15)-E5 -> 787.30083 | H5: =(D5-F5)*C5*(1+-0.15)+F5*C5-E5 -> 828.22083 | I5: =D5*C5*(1+0)-E5 -> 974.37744 | J5: =(D5-F5)*C5*(1+0)+F5*C5-E5 -> 974.37744 | K5: =D5*C5*(1+0.15)-E5 -> 1161.4541 | L5: =(D5-F5)*C5*(1+0.15)+F5*C5-E5 -> 1120.5341
A6: =Pricing!A6 -> 2 | B6: =Pricing!C6 -> 0.33972603 | C6: =Inputs!$C$14*((1+Inputs!$C$13)/(1+Inputs!$C$12))^B6 -> 16.822271 | D6: =(Monthly!D6*Inputs!$C$8+Monthly!L6*Inputs!$C$9)/1000000 -> 67.127984 | E6: =Inputs!$C$17*Inputs!$C$18*Monthly!B6*Inputs!$C$21/1000000 -> 246.4 | F6: =E6/C6 -> 14.647249 | G6: =D6*C6*(1+-0.15)-E6 -> 713.45837 | H6: =(D6-F6)*C6*(1+-0.15)+F6*C6-E6 -> 750.41837 | I6: =D6*C6*(1+0)-E6 -> 882.84514 | J6: =(D6-F6)*C6*(1+0)+F6*C6-E6 -> 882.84514 | K6: =D6*C6*(1+0.15)-E6 -> 1052.2319 | L6: =(D6-F6)*C6*(1+0.15)+F6*C6-E6 -> 1015.2719
A7: =Pricing!A7 -> 3 | B7: =Pricing!C7 -> 0.42465753 | C7: =Inputs!$C$14*((1+Inputs!$C$13)/(1+Inputs!$C$12))^B7 -> 16.867947 | D7: =(Monthly!D7*Inputs!$C$8+Monthly!L7*Inputs!$C$9)/1000000 -> 74.320268 | E7: =Inputs!$C$17*Inputs!$C$18*Monthly!B7*Inputs!$C$21/1000000 -> 272.8 | F7: =E7/C7 -> 16.172685 | G7: =D7*C7*(1+-0.15)-E7 -> 792.7858 | H7: =(D7-F7)*C7*(1+-0.15)+F7*C7-E7 -> 833.7058 | I7: =D7*C7*(1+0)-E7 -> 980.83035 | J7: =(D7-F7)*C7*(1+0)+F7*C7-E7 -> 980.83035 | K7: =D7*C7*(1+0.15)-E7 -> 1168.8749 | L7: =(D7-F7)*C7*(1+0.15)+F7*C7-E7 -> 1127.9549
A8: =Pricing!A8 -> 4 | B8: =Pricing!C8 -> 0.50684932 | C8: =Inputs!$C$14*((1+Inputs!$C$13)/(1+Inputs!$C$12))^B8 -> 16.912268 | D8: =(Monthly!D8*Inputs!$C$8+Monthly!L8*Inputs!$C$9)/1000000 -> 71.92284 | E8: =Inputs!$C$17*Inputs!$C$18*Monthly!B8*Inputs!$C$21/1000000 -> 264 | F8: =E8/C8 -> 15.60997 | G8: =D8*C8*(1+-0.15)-E8 -> 769.92159 | H8: =(D8-F8)*C8*(1+-0.15)+F8*C8-E8 -> 809.52159 | I8: =D8*C8*(1+0)-E8 -> 952.37834 | J8: =(D8-F8)*C8*(1+0)+F8*C8-E8 -> 952.37834 | K8: =D8*C8*(1+0.15)-E8 -> 1134.8351 | L8: =(D8-F8)*C8*(1+0.15)+F8*C8-E8 -> 1095.2351
A9: =Pricing!A9 -> 5 | B9: =Pricing!C9 -> 0.59178082 | C9: =Inputs!$C$14*((1+Inputs!$C$13)/(1+Inputs!$C$12))^B9 -> 16.958188 | D9: =(Monthly!D9*Inputs!$C$8+Monthly!L9*Inputs!$C$9)/1000000 -> 74.320268 | E9: =Inputs!$C$17*Inputs!$C$18*Monthly!B9*Inputs!$C$21/1000000 -> 272.8 | F9: =E9/C9 -> 16.086624 | G9: =D9*C9*(1+-0.15)-E9 -> 798.48654 | H9: =(D9-F9)*C9*(1+-0.15)+F9*C9-E9 -> 839.40654 | I9: =D9*C9*(1+0)-E9 -> 987.5371 | J9: =(D9-F9)*C9*(1+0)+F9*C9-E9 -> 987.5371 | K9: =D9*C9*(1+0.15)-E9 -> 1176.5877 | L9: =(D9-F9)*C9*(1+0.15)+F9*C9-E9 -> 1135.6677
A10: =Pricing!A10 -> 6 | B10: =Pricing!C10 -> 0.6739726 | C10: =Inputs!$C$14*((1+Inputs!$C$13)/(1+Inputs!$C$12))^B10 -> 17.002746 | D10: =(Monthly!D10*Inputs!$C$8+Monthly!L10*Inputs!$C$9)/1000000 -> 71.92284 | E10: =Inputs!$C$17*Inputs!$C$18*Monthly!B10*Inputs!$C$21/1000000 -> 264 | F10: =E10/C10 -> 15.526903 | G10: =D10*C10*(1+-0.15)-E10 -> 775.45293 | H10: =(D10-F10)*C10*(1+-0.15)+F10*C10-E10 -> 815.05293 | I10: =D10*C10*(1+0)-E10 -> 958.8858 | J10: =(D10-F10)*C10*(1+0)+F10*C10-E10 -> 958.8858 | K10: =D10*C10*(1+0.15)-E10 -> 1142.3187 | L10: =(D10-F10)*C10*(1+0.15)+F10*C10-E10 -> 1102.7187
A11: =Pricing!A11 -> 7 | B11: =Pricing!C11 -> 0.75890411 | C11: =Inputs!$C$14*((1+Inputs!$C$13)/(1+Inputs!$C$12))^B11 -> 17.048912 | D11: =(Monthly!D11*Inputs!$C$8+Monthly!L11*Inputs!$C$9)/1000000 -> 74.320268 | E11: =Inputs!$C$17*Inputs!$C$18*Monthly!B11*Inputs!$C$21/1000000 -> 272.8 | F11: =E11/C11 -> 16.001021 | G11: =D11*C11*(1+-0.15)-E11 -> 804.21778 | H11: =(D11-F11)*C11*(1+-0.15)+F11*C11-E11 -> 845.13778 | I11: =D11*C11*(1+0)-E11 -> 994.27974 | J11: =(D11-F11)*C11*(1+0)+F11*C11-E11 -> 994.27974 | K11: =D11*C11*(1+0.15)-E11 -> 1184.3417 | L11: =(D11-F11)*C11*(1+0.15)+F11*C11-E11 -> 1143.4217
A12: =Pricing!A12 -> 8 | B12: =Pricing!C12 -> 0.84383562 | C12: =Inputs!$C$14*((1+Inputs!$C$13)/(1+Inputs!$C$12))^B12 -> 17.095204 | D12: =(Monthly!D12*Inputs!$C$8+Monthly!L12*Inputs!$C$9)/1000000 -> 74.320268 | E12: =Inputs!$C$17*Inputs!$C$18*Monthly!B12*Inputs!$C$21/1000000 -> 272.8 | F12: =E12/C12 -> 15.957692 | G12: =D12*C12*(1+-0.15)-E12 -> 807.14212 | H12: =(D12-F12)*C12*(1+-0.15)+F12*C12-E12 -> 848.06212 | I12: =D12*C12*(1+0)-E12 -> 997.72014 | J12: =(D12-F12)*C12*(1+0)+F12*C12-E12 -> 997.72014 | K12: =D12*C12*(1+0.15)-E12 -> 1188.2982 | L12: =(D12-F12)*C12*(1+0.15)+F12*C12-E12 -> 1147.3782
A13: =Pricing!A13 -> 9 | B13: =Pricing!C13 -> 0.9260274 | C13: =Inputs!$C$14*((1+Inputs!$C$13)/(1+Inputs!$C$12))^B13 -> 17.140122 | D13: =(Monthly!D13*Inputs!$C$8+Monthly!L13*Inputs!$C$9)/1000000 -> 71.92284 | E13: =Inputs!$C$17*Inputs!$C$18*Monthly!B13*Inputs!$C$21/1000000 -> 264 | F13: =E13/C13 -> 15.402458 | G13: =D13*C13*(1+-0.15)-E13 -> 783.8513 | H13: =(D13-F13)*C13*(1+-0.15)+F13*C13-E13 -> 823.4513 | I13: =D13*C13*(1+0)-E13 -> 968.76624 | J13: =(D13-F13)*C13*(1+0)+F13*C13-E13 -> 968.76624 | K13: =D13*C13*(1+0.15)-E13 -> 1153.6812 | L13: =(D13-F13)*C13*(1+0.15)+F13*C13-E13 -> 1114.0812
A14: =Pricing!A14 -> 10 | B14: =Pricing!C14 -> 1.0109589 | C14: =Inputs!$C$14*((1+Inputs!$C$13)/(1+Inputs!$C$12))^B14 -> 17.186661 | D14: =(Monthly!D14*Inputs!$C$8+Monthly!L14*Inputs!$C$9)/1000000 -> 74.320268 | E14: =Inputs!$C$17*Inputs!$C$18*Monthly!B14*Inputs!$C$21/1000000 -> 272.8 | F14: =E14/C14 -> 15.872775 | G14: =D14*C14*(1+-0.15)-E14 -> 812.91966 | H14: =(D14-F14)*C14*(1+-0.15)+F14*C14-E14 -> 853.83966 | I14: =D14*C14*(1+0)-E14 -> 1004.5172 | J14: =(D14-F14)*C14*(1+0)+F14*C14-E14 -> 1004.5172 | K14: =D14*C14*(1+0.15)-E14 -> 1196.1148 | L14: =(D14-F14)*C14*(1+0.15)+F14*C14-E14 -> 1155.1948
A15: =Pricing!A15 -> 11 | B15: =Pricing!C15 -> 1.0931507 | C15: =Inputs!$C$14*((1+Inputs!$C$13)/(1+Inputs!$C$12))^B15 -> 17.231819 | D15: =(Monthly!D15*Inputs!$C$8+Monthly!L15*Inputs!$C$9)/1000000 -> 71.92284 | E15: =Inputs!$C$17*Inputs!$C$18*Monthly!B15*Inputs!$C$21/1000000 -> 264 | F15: =E15/C15 -> 15.320495 | G15: =D15*C15*(1+-0.15)-E15 -> 789.45717 | H15: =(D15-F15)*C15*(1+-0.15)+F15*C15-E15 -> 829.05717 | I15: =D15*C15*(1+0)-E15 -> 975.36137 | J15: =(D15-F15)*C15*(1+0)+F15*C15-E15 -> 975.36137 | K15: =D15*C15*(1+0.15)-E15 -> 1161.2656 | L15: =(D15-F15)*C15*(1+0.15)+F15*C15-E15 -> 1121.6656
A16: =Pricing!A16 -> 12 | B16: =Pricing!C16 -> 1.1780822 | C16: =Inputs!$C$14*((1+Inputs!$C$13)/(1+Inputs!$C$12))^B16 -> 17.278607 | D16: =(Monthly!D16*Inputs!$C$8+Monthly!L16*Inputs!$C$9)/1000000 -> 74.320268 | E16: =Inputs!$C$17*Inputs!$C$18*Monthly!B16*Inputs!$C$21/1000000 -> 272.8 | F16: =E16/C16 -> 15.78831 | G16: =D16*C16*(1+-0.15)-E16 -> 818.72812 | H16: =(D16-F16)*C16*(1+-0.15)+F16*C16-E16 -> 859.64812 | I16: =D16*C16*(1+0)-E16 -> 1011.3507 | J16: =(D16-F16)*C16*(1+0)+F16*C16-E16 -> 1011.3507 | K16: =D16*C16*(1+0.15)-E16 -> 1203.9733 | L16: =(D16-F16)*C16*(1+0.15)+F16*C16-E16 -> 1163.0533
A17: Total | D17: =SUM(D5:D16) -> 875.06122 | E17: =SUM(E5:E16) -> 3212 | F17: =SUM(F5:F16) -> 188.64255 | G17: =SUM(G5:G16) -> 9453.7222 | H17: =SUM(H5:H16) -> 9935.5222 | I17: =SUM(I5:I16) -> 11688.85 | J17: =SUM(J5:J16) -> 11688.85 | K17: =SUM(K5:K16) -> 13923.977 | L17: =SUM(L5:L16) -> 13442.177

Sheet Sources
A1: Sources
A2: Read 27 Oct 2026. Secondary sources are labelled and used as cross-checks or where no primary source was found.
A4: Key | B4: Source | C4: URL
