Workbook

Sheet Cover
A1: Darktrace plc / Thoma Bravo take-private (2024)
A2: Project 04: sell-side fairness view. Project 08: LBO and IC case. Retrospective analysis: April market inputs, July FY24 update; not an April information set.
A3: Tobenna Agubuche | github.com/Tobenna30/finance-models | Not investment advice
A5: Offer price (p) | B5: =Inputs!$C$8 -> 620
A6: Premium to undisturbed close | B6: =Offer!$B$16 -> 0.19922631
A7: Premium to 3-month VWAP | B7: =Offer!$B$18 -> 0.44219586
A8: Offer EV / LTM revenue | B8: =Offer!$B$11 -> 8.1038961
A9: Offer EV / NTM revenue | B9: =Comps!$B$25 -> 6.1617268
A10: DCF value per share (p) | B10: =DCF!$B$30 -> 455.09414
A11: Peer median EV/NTM value (p) | B11: =Comps!$B$28 -> 816.95276
A12: Precedent median EV/LTM value (p) | B12: =Precedents!$B$20 -> 879.4318
A13: Precedent median premium value (p) | B13: =Precedents!$B$23 -> 744.48
A14: LBO ability to pay at 20% IRR (p) | B14: ='Ability to pay'!$B$9 -> 661.3987
A15: Strategic maximum (p) | B15: ='Rival bid'!B9 -> 486.72358
A16: LBO base IRR | B16: =LBO!$H$49 -> 0.22884489
A17: LBO base MOIC | B17: =LBO!$G$49 -> 2.6614056
A18: LBO downside IRR | B18: =Downside!$H$49 -> -0.10955101
A19: LBO downside MOIC | B19: =Downside!$G$49 -> 0.57629251
A20: Sponsor equity cheque ($m) | B20: =LBO!$B$15 -> 3001.07
A21: Debt / LTM EBITDA at close | B21: =LBO!$B$17 -> 14.691781
A22: Base liquidity low point ($m) | B22: =LBO!$B$56 -> 77.834824
A23: Base shortfall to operating cash minimum ($m) | B23: =MAX(0,Inputs!$C$79-LBO!$B$56) -> 22.165176
A24: Downside liquidity low point ($m) | B24: =Downside!$B$52 -> 19.180055
A25: Downside shortfall to operating cash minimum ($m) | B25: =MAX(0,Inputs!$C$79-Downside!$B$52) -> 80.819945
A26: Bridge check (should be 0) | B26: =LBO!$B$66 -> 0

Sheet Inputs
A1: Inputs
A2: Blue = hard-coded input. Tag: S = sourced, A = assumption, D = derived. $m unless stated. Series columns F onwards = FY25 onwards.
A4: Input | B4: Unit | C4: Value | D4: Tag | E4: Source / note | F4: FY25 | G4: FY26 | H4: FY27 | I4: FY28 | J4: FY29 | K4: FY30 | L4: FY31
A6: Offer terms (Rule 2.7 announcement, 26 Apr 2024)
A7: Offer price per share | B7: $ | C7: 7.75 | D7: S | E7: R27: Rule 2.7 announcement, Recommended Cash Acquisition of Darktrace plc, 26 Apr 2024
A8: Offer price, GBP equivalent at announcement | B8: p | C8: 620 | D8: S | E8: R27: Rule 2.7 announcement, Recommended Cash Acquisition of Darktrace plc, 26 Apr 2024
A9: Equity value, fully diluted | B9: $m | C9: 5315 | D9: S | E9: R27: Rule 2.7 announcement, Recommended Cash Acquisition of Darktrace plc, 26 Apr 2024
A10: Enterprise value | B10: $m | C10: 4992 | D10: S | E10: R27: Rule 2.7 announcement, Recommended Cash Acquisition of Darktrace plc, 26 Apr 2024
A11: LTM revenue (12m to 31 Dec 2023) | B11: $m | C11: 616 | D11: S | E11: R27: Rule 2.7 announcement, Recommended Cash Acquisition of Darktrace plc, 26 Apr 2024
A12: LTM adjusted EBITDA (12m to 31 Dec 2023) | B12: $m | C12: 146 | D12: S | E12: R27: Rule 2.7 announcement, Recommended Cash Acquisition of Darktrace plc, 26 Apr 2024
A13: Stated EV / LTM revenue | B13: x | C13: 8.1 | D13: S | E13: R27: Rule 2.7 announcement, Recommended Cash Acquisition of Darktrace plc, 26 Apr 2024
A14: Stated EV / LTM adjusted EBITDA | B14: x | C14: 34.2 | D14: S | E14: R27: Rule 2.7 announcement, Recommended Cash Acquisition of Darktrace plc, 26 Apr 2024
A15: Undisturbed close, 25 Apr 2024 | B15: p | C15: 517 | D15: S | E15: R27: Rule 2.7 announcement, Recommended Cash Acquisition of Darktrace plc, 26 Apr 2024
A16: 3-month VWAP to 25 Apr 2024 | B16: p | C16: 429.9 | D16: S | E16: R27: Rule 2.7 announcement, Recommended Cash Acquisition of Darktrace plc, 26 Apr 2024
A17: 12-month high close | B17: p | C17: 518.6 | D17: S | E17: R27: Rule 2.7 announcement, Recommended Cash Acquisition of Darktrace plc, 26 Apr 2024
A18: Secondary placing price, 21 Mar 2024 | B18: p | C18: 425 | D18: S | E18: R27: Rule 2.7 announcement, Recommended Cash Acquisition of Darktrace plc, 26 Apr 2024
... A26: Lease liabilities, 31 Dec 2023 | B26: $m | C26: 60.2 | D26: S | E26: H124: Darktrace half-year results to 31 Dec 2023, 7 Mar 2024
A28: History (FY to 30 June)
A29: Revenue FY22 (FY23 less reported $129.9m increase) | B29: $m | C29: 415.5 | D29: D | E29: FY23: Darktrace FY 2023 final results, 6 Sep 2023
A30: Revenue FY23 | B30: $m | C30: 545.4 | D30: S | E30: FY23: Darktrace FY 2023 final results, 6 Sep 2023
A31: Revenue FY24 ('at least', unaudited) | B31: $m | C31: 689.5 | D31: S | E31: Q424: Darktrace Q4 FY 2024 trading update, 18 Jul 2024
A32: ARR FY23, constant currency | B32: $m | C32: 637.3 | D32: S | E32: FY23: Darktrace FY 2023 final results, 6 Sep 2023
A33: ARR FY24, constant currency | B33: $m | C33: 782.2 | D33: S | E33: Q424: Darktrace Q4 FY 2024 trading update, 18 Jul 2024
A34: Net ARR retention FY24 | B34: % | C34: 1.066 | D34: S | E34: Q424: Darktrace Q4 FY 2024 trading update, 18 Jul 2024
A35: Gross ARR churn FY24 | B35: % | C35: 0.063 | D35: S | E35: Q424: Darktrace Q4 FY 2024 trading update, 18 Jul 2024
A36: Revenue H1 FY24 | B36: $m | C36: 330.3 | D36: S | E36: H124: Darktrace half-year results to 31 Dec 2023, 7 Mar 2024
A37: Revenue H1 FY23 | B37: $m | C37: 259.3 | D37: S | E37: H124: Darktrace half-year results to 31 Dec 2023, 7 Mar 2024
A38: Adjusted EBITDA H1 FY24 | B38: $m | C38: 84.5 | D38: S | E38: H124: Darktrace half-year results to 31 Dec 2023, 7 Mar 2024
A39: Adjusted EBITDA H1 FY23 (restated definition) | B39: $m | C39: 45.2 | D39: S | E39: H124: Darktrace half-year results to 31 Dec 2023, 7 Mar 2024
A40: Adjusted EBIT H1 FY24 | B40: $m | C40: 71 | D40: S | E40: H124: Darktrace half-year results to 31 Dec 2023, 7 Mar 2024
... A46: Working capital inflow, % of revenue increase | B46: % | C46: 0.1 | D46: A | E46: Deferred revenue builds with billings
A48: Project 04: standalone DCF (valuation at 1 Jul 2024, mid-year discounting)
A49: Revenue growth | B49: % | D49: A | E49: FY24 +26%, ARR +22.7%; net ARR added flat y/y, so growth fades | F49: 0.21 | G49: 0.19 | H49: 0.17 | I49: 0.15 | J49: 0.13 | K49: 0.11 | L49: 0.09
A50: Adjusted EBITDA margin | B50: % | D50: A | E50: Steady-state adj EBIT target 'mid-20%s' (FY23) plus D&A of c.4% | F50: 0.24 | G50: 0.255 | H50: 0.27 | I50: 0.285 | J50: 0.295 | K50: 0.305 | L50: 0.31
A51: Share-based payments, % revenue (treated as a cost) | B51: % | D51: A | E51: H1 FY24 6.9% of revenue | F51: 0.065 | G51: 0.06 | H51: 0.055 | I51: 0.05 | J51: 0.045 | K51: 0.04 | L51: 0.04
A52: Risk-free rate: US 10-year, Apr 2024 average | B52: % | C52: 0.0454 | D52: S | E52: UST: US 10-year Treasury yield, monthly average, via Alpha Vantage TREASURY_YIELD (Federal Reserve H.15)
A53: Equity beta | B53: x | C53: 1.25 | D53: A | E53: No debt; listed cyber peers trade above market beta
A54: Equity risk premium | B54: % | C54: 0.05 | D54: A
A55: Terminal growth | B55: % | C55: 0.035 | D55: A
A56: Deduct SBP in free cash flow (1 = yes, 0 = no) | B56: 1/0 | C56: 1 | D56: A | E56: Set 0 to see the value with SBP added back
...

Sheet History
A1: Darktrace history (FY to 30 June) and LTM bridge
A4: $m | B4: FY22 | C4: FY23 | D4: FY24
A5: Revenue | B5: =Inputs!$C$29 -> 415.5 | C5: =Inputs!$C$30 -> 545.4 | D5: =Inputs!$C$31 -> 689.5
A6: Growth | C6: =C5/B5-1 -> 0.31263538 | D6: =D5/C5-1 -> 0.26420975
A7: ARR (constant currency) | C7: =Inputs!$C$32 -> 637.3 | D7: =Inputs!$C$33 -> 782.2
A8: ARR growth | D8: =D7/C7-1 -> 0.22736545
A9: Adjusted EBITDA (FY23 derived on the new definition; FY24 assumed margin) | C9: =Inputs!$C$12-Inputs!$C$38+Inputs!$C$39 -> 106.7 | D9: =D5*Inputs!$C$43 -> 158.585
A10: Margin | C10: =C9/C5 -> 0.19563623 | D10: =D9/D5 -> 0.23
A12: LTM to 31 Dec 2023
A13: Revenue: FY23 + H1 FY24 - H1 FY23 | B13: =Inputs!$C$30+Inputs!$C$36-Inputs!$C$37 -> 616.4
A14: Stated in the Rule 2.7 announcement | B14: =Inputs!$C$11 -> 616
A15: SBP as % revenue, H1 FY24 | B15: =Inputs!$C$41/Inputs!$C$36 -> 0.068725401
A16: Adjusted EBITDA margin, H1 FY24 | B16: =Inputs!$C$38/Inputs!$C$36 -> 0.25582804
A17: Net ARR retention FY24 / gross churn FY24 | B17: =Inputs!$C$34 -> 1.066 | C17: =Inputs!$C$35 -> 0.063

Sheet Offer
A1: Offer analysis: what Thoma Bravo paid
A2: All figures recomputed from inputs and checked against the stated numbers
A4: Offer price ($) | B4: =Inputs!$C$7 -> 7.75
A5: Offer price (p) | B5: =Inputs!$C$8 -> 620
A6: Implied FX ($ per GBP) | B6: =Inputs!$C$98 -> 1.25
A7: Fully diluted shares (m) | B7: =Inputs!$C$99 -> 685.80645
A8: Equity value ($m) | B8: =Inputs!$C$9 -> 5315
A9: Net cash ($m) | B9: =Inputs!$C$100 -> 323
A10: Enterprise value ($m) | B10: =Inputs!$C$10 -> 4992
A11: EV / LTM revenue | B11: =Inputs!$C$10/Inputs!$C$11 -> 8.1038961
A12: Stated EV / LTM revenue | B12: =Inputs!$C$13 -> 8.1
A13: EV / LTM adjusted EBITDA | B13: =Inputs!$C$10/Inputs!$C$12 -> 34.191781
A14: Stated EV / LTM EBITDA | B14: =Inputs!$C$14 -> 34.2
A15: EV / FY24 ARR | B15: =Inputs!$C$10/Inputs!$C$33 -> 6.3819995
A16: Premium to undisturbed close (517p) | B16: =Inputs!$C$8/Inputs!$C$15-1 -> 0.19922631
A17: Stated premium to close | B17: =Inputs!$C$20 -> 0.2
A18: Premium to 3-month VWAP (429.9p) | B18: =Inputs!$C$8/Inputs!$C$16-1 -> 0.44219586
A19: Stated premium to VWAP | B19: =Inputs!$C$21 -> 0.443
A20: Premium to 12-month high (518.6p) | B20: =Inputs!$C$8/Inputs!$C$17-1 -> 0.19552642
A21: Premium to March 2024 placing (425p) | B21: =Inputs!$C$8/Inputs!$C$18-1 -> 0.45882353
A22: Multiple of IPO price (250p) | B22: =Inputs!$C$8/Inputs!$C$19 -> 2.48
A23: Run-up: undisturbed close vs 3-month VWAP | B23: =Inputs!$C$15/Inputs!$C$16-1 -> 0.20260526
A24: Irrevocables (% of issued capital) | B24: =Inputs!$C$22 -> 0.1471
A25: Court Meeting: % of Scheme Shares voted in favour | B25: =Inputs!$C$23 -> 0.9955
A26: Court Meeting: turnout (% of issued capital) | B26: =Inputs!$C$24 -> 0.6529
A28: Timetable
A29: Announcement (Rule 2.7) | B29: 26 Apr 2024
A30: Scheme Document | B30: 23 May 2024
A31: Court Meeting and General Meeting | B31: 18 Jun 2024
A32: Regulatory conditions satisfied | B32: 16 Sep 2024
A33: Court sanction | B33: 24 Sep 2024
A34: Effective; delisted next day | B34: 1 Oct 2024
A35: Long stop date | B35: 27 Jan 2025
A36: Rule 3 advisers to the board | B36: Jefferies and Qatalyst Partners
A37: Bidco financial adviser | B37: Goldman Sachs International

Sheet DCF
A1: Standalone DCF (public-company case, before any bid)
A2: $m. Mid-year discounting from 1 Jul 2024. SBP is treated as a cost.
A4: $m | B4: FY24A | C4: FY25E | D4: FY26E | E4: FY27E | F4: FY28E | G4: FY29E | H4: FY30E | I4: FY31E
A5: Revenue | B5: =History!D5 -> 689.5 | C5: =B5*(1+C6) -> 834.295 | D5: =C5*(1+D6) -> 992.81105 | E5: =D5*(1+E6) -> 1161.5889 | F5: =E5*(1+F6) -> 1335.8273 | G5: =F5*(1+G6) -> 1509.4848 | H5: =G5*(1+H6) -> 1675.5281 | I5: =H5*(1+I6) -> 1826.3257
A6: Growth | C6: =Inputs!$F$49 -> 0.21 | D6: =Inputs!$G$49 -> 0.19 | E6: =Inputs!$H$49 -> 0.17 | F6: =Inputs!$I$49 -> 0.15 | G6: =Inputs!$J$49 -> 0.13 | H6: =Inputs!$K$49 -> 0.11 | I6: =Inputs!$L$49 -> 0.09
A7: Adjusted EBITDA | C7: =C5*C8 -> 200.2308 | D7: =D5*D8 -> 253.16682 | E7: =E5*E8 -> 313.62901 | F7: =F5*F8 -> 380.71077 | G7: =G5*G8 -> 445.29802 | H7: =H5*H8 -> 511.03608 | I7: =I5*I8 -> 566.16096
A8: Margin | C8: =Inputs!$F$50 -> 0.24 | D8: =Inputs!$G$50 -> 0.255 | E8: =Inputs!$H$50 -> 0.27 | F8: =Inputs!$I$50 -> 0.285 | G8: =Inputs!$J$50 -> 0.295 | H8: =Inputs!$K$50 -> 0.305 | I8: =Inputs!$L$50 -> 0.31
A9: Share-based payments | C9: =C5*Inputs!$F$51 -> 54.229175 | D9: =D5*Inputs!$G$51 -> 59.568663 | E9: =E5*Inputs!$H$51 -> 63.887391 | F9: =F5*Inputs!$I$51 -> 66.791363 | G9: =G5*Inputs!$J$51 -> 67.926817 | H9: =H5*Inputs!$K$51 -> 67.021126 | I9: =I5*Inputs!$L$51 -> 73.053027
A10: D&A | C10: =C5*Inputs!$C$102 -> 34.099251 | D10: =D5*Inputs!$C$102 -> 40.578108 | E10: =E5*Inputs!$C$102 -> 47.476387 | F10: =F5*Inputs!$C$102 -> 54.597845 | G10: =G5*Inputs!$C$102 -> 61.695565 | H10: =H5*Inputs!$C$102 -> 68.482077 | I10: =I5*Inputs!$C$102 -> 74.645464
A11: EBIT after SBP | C11: =C7-C9-C10 -> 111.90237 | D11: =D7-D9-D10 -> 153.02005 | E11: =E7-E9-E10 -> 202.26523 | F11: =F7-F9-F10 -> 259.32156 | G11: =G7-G9-G10 -> 315.67564 | H11: =H7-H9-H10 -> 375.53288 | I11: =I7-I9-I10 -> 418.46247
A12: Tax | C12: =MAX(0,C11)*Inputs!$C$44 -> 27.975594 | D12: =MAX(0,D11)*Inputs!$C$44 -> 38.255012 | E12: =MAX(0,E11)*Inputs!$C$44 -> 50.566308 | F12: =MAX(0,F11)*Inputs!$C$44 -> 64.830391 | G12: =MAX(0,G11)*Inputs!$C$44 -> 78.91891 | H12: =MAX(0,H11)*Inputs!$C$44 -> 93.88322 | I12: =MAX(0,I11)*Inputs!$C$44 -> 104.61562
A13: Capex | C13: =C5*Inputs!$C$101 -> 20.206963 | D13: =D5*Inputs!$C$101 -> 24.046286 | E13: =E5*Inputs!$C$101 -> 28.134155 | F13: =F5*Inputs!$C$101 -> 32.354278 | G13: =G5*Inputs!$C$101 -> 36.560335 | H13: =H5*Inputs!$C$101 -> 40.581971 | I13: =I5*Inputs!$C$101 -> 44.234349
A14: Working capital inflow | C14: =(C5-B5)*Inputs!$C$46 -> 14.4795 | D14: =(D5-C5)*Inputs!$C$46 -> 15.851605 | E14: =(E5-D5)*Inputs!$C$46 -> 16.877788 | F14: =(F5-E5)*Inputs!$C$46 -> 17.423834 | G14: =(G5-F5)*Inputs!$C$46 -> 17.365754 | H14: =(H5-G5)*Inputs!$C$46 -> 16.604333 | I14: =(I5-H5)*Inputs!$C$46 -> 15.079753
A15: Unlevered free cash flow | C15: =C7-C9*Inputs!$C$56-C12-C13+C14 -> 112.29857 | D15: =D7-D9*Inputs!$C$56-D12-D13+D14 -> 147.14846 | E15: =E7-E9*Inputs!$C$56-E12-E13+E14 -> 187.91894 | F15: =F7-F9*Inputs!$C$56-F12-F13+F14 -> 234.15857 | G15: =G7-G9*Inputs!$C$56-G12-G13+G14 -> 279.25771 | H15: =H7-H9*Inputs!$C$56-H12-H13+H14 -> 326.1541 | I15: =I7-I9*Inputs!$C$56-I12-I13+I14 -> 359.33772
A16: Discount period (mid-year) | C16: =0+0.5 -> 0.5 | D16: =1+0.5 -> 1.5 | E16: =2+0.5 -> 2.5 | F16: =3+0.5 -> 3.5 | G16: =4+0.5 -> 4.5 | H16: =5+0.5 -> 5.5 | I16: =6+0.5 -> 6.5
A17: Discount factor | C17: =1/(1+Inputs!$C$103)^C16 -> 0.95005712 | D17: =1/(1+Inputs!$C$103)^D16 -> 0.85752967 | E17: =1/(1+Inputs!$C$103)^E16 -> 0.7740136 | F17: =1/(1+Inputs!$C$103)^F16 -> 0.69863129 | G17: =1/(1+Inputs!$C$103)^G16 -> 0.63059057 | H17: =1/(1+Inputs!$C$103)^H16 -> 0.56917643 | I17: =1/(1+Inputs!$C$103)^I16 -> 0.51374351
A18: PV of UFCF | C18: =C15*C17 -> 106.69005 | D18: =D15*D17 -> 126.18417 | E18: =E15*E17 -> 145.45182 | F18: =F15*F17 -> 163.59051 | G18: =G15*G17 -> 176.09728 | H18: =H15*H17 -> 185.63923 | I18: =I15*I17 -> 184.60742
A21: WACC | B21: =Inputs!$C$103 -> 0.1079
A22: Terminal growth | B22: =Inputs!$C$55 -> 0.035
A23: Sum of PV of UFCF | B23: =SUM(C18:I18) -> 1088.2605
A24: Terminal value (Gordon growth) | B24: =I15*(1+B22)/(B21-B22) -> 5101.7084
A25: PV of terminal value | B25: =B24/(1+B21)^7 -> 2490.0708
A26: Enterprise value | B26: =B23+B25 -> 3578.3313
A27: Net cash | B27: =Inputs!$C$100 -> 323
A28: Equity value | B28: =B26+B27 -> 3901.3313
A29: Value per share ($) | B29: =B28/Inputs!$C$99 -> 5.6886768
A30: Value per share (p) | B30: =B29*100/Inputs!$C$98 -> 455.09414
A31: vs offer 620p | B31: =B30/Inputs!$C$8-1 -> -0.26597719
A32: vs undisturbed 517p | B32: =B30/Inputs!$C$15-1 -> -0.11974053
A33: Terminal value as % of EV | B33: =B25/B26 -> 0.69587487
A34: Implied terminal EV / EBITDA | B34: =B24/I7 -> 9.0110565
A35: Offer EV / FY25E EBITDA | B35: =Inputs!$C$10/C7 -> 24.931229
A38: Value per share (p): WACC (rows) x terminal growth (columns)
B39: =Inputs!$C$55+-0.01 -> 0.025 | C39: =Inputs!$C$55+-0.005 -> 0.03 | D39: =Inputs!$C$55+0 -> 0.035 | E39: =Inputs!$C$55+0.005 -> 0.04 | F39: =Inputs!$C$55+0.01 -> 0.045
A40: =Inputs!$C$103+-0.01 -> 0.0979 | B40: =(SUMPRODUCT($C$15:$I$15,1/(1+$A40)^$C$16:$I$16)+$I$15*(1+B$39)/($A40-B$39)/(1+$A40)^7+Inputs!$C$100)/Inputs!$C$99*100/Inputs!$C$98 -> 475.66984 | C40: =(SUMPRODUCT($C$15:$I$15,1/(1+$A40)^$C$16:$I$16)+$I$15*(1+C$39)/($A40-C$39)/(1+$A40)^7+Inputs!$C$100)/Inputs!$C$99*100/Inputs!$C$98 -> 499.84599 | D40: =(SUMPRODUCT($C$15:$I$15,1/(1+$A40)^$C$16:$I$16)+$I$15*(1+D$39)/($A40-D$39)/(1+$A40)^7+Inputs!$C$100)/Inputs!$C$99*100/Inputs!$C$98 -> 527.86573 | E40: =(SUMPRODUCT($C$15:$I$15,1/(1+$A40)^$C$16:$I$16)+$I$15*(1+E$39)/($A40-E$39)/(1+$A40)^7+Inputs!$C$100)/Inputs!$C$99*100/Inputs!$C$98 -> 560.72481 | F40: =(SUMPRODUCT($C$15:$I$15,1/(1+$A40)^$C$16:$I$16)+$I$15*(1+F$39)/($A40-F$39)/(1+$A40)^7+Inputs!$C$100)/Inputs!$C$99*100/Inputs!$C$98 -> 599.79542
A41: =Inputs!$C$103+-0.005 -> 0.1029 | B41: =(SUMPRODUCT($C$15:$I$15,1/(1+$A41)^$C$16:$I$16)+$I$15*(1+B$39)/($A41-B$39)/(1+$A41)^7+Inputs!$C$100)/Inputs!$C$99*100/Inputs!$C$98 -> 444.72036 | C41: =(SUMPRODUCT($C$15:$I$15,1/(1+$A41)^$C$16:$I$16)+$I$15*(1+C$39)/($A41-C$39)/(1+$A41)^7+Inputs!$C$100)/Inputs!$C$99*100/Inputs!$C$98 -> 465.22629 | D41: =(SUMPRODUCT($C$15:$I$15,1/(1+$A41)^$C$16:$I$16)+$I$15*(1+D$39)/($A41-D$39)/(1+$A41)^7+Inputs!$C$100)/Inputs!$C$99*100/Inputs!$C$98 -> 488.75224 | E41: =(SUMPRODUCT($C$15:$I$15,1/(1+$A41)^$C$16:$I$16)+$I$15*(1+E$39)/($A41-E$39)/(1+$A41)^7+Inputs!$C$100)/Inputs!$C$99*100/Inputs!$C$98 -> 516.0184 | F41: =(SUMPRODUCT($C$15:$I$15,1/(1+$A41)^$C$16:$I$16)+$I$15*(1+F$39)/($A41-F$39)/(1+$A41)^7+Inputs!$C$100)/Inputs!$C$99*100/Inputs!$C$98 -> 547.99374
A42: =Inputs!$C$103+0 -> 0.1079 | B42: =(SUMPRODUCT($C$15:$I$15,1/(1+$A42)^$C$16:$I$16)+$I$15*(1+B$39)/($A42-B$39)/(1+$A42)^7+Inputs!$C$100)/Inputs!$C$99*100/Inputs!$C$98 -> 417.58771 | C42: =(SUMPRODUCT($C$15:$I$15,1/(1+$A42)^$C$16:$I$16)+$I$15*(1+C$39)/($A42-C$39)/(1+$A42)^7+Inputs!$C$100)/Inputs!$C$99*100/Inputs!$C$98 -> 435.13725 | D42: =(SUMPRODUCT($C$15:$I$15,1/(1+$A42)^$C$16:$I$16)+$I$15*(1+D$39)/($A42-D$39)/(1+$A42)^7+Inputs!$C$100)/Inputs!$C$99*100/Inputs!$C$98 -> 455.09414 | E42: =(SUMPRODUCT($C$15:$I$15,1/(1+$A42)^$C$16:$I$16)+$I$15*(1+E$39)/($A42-E$39)/(1+$A42)^7+Inputs!$C$100)/Inputs!$C$99*100/Inputs!$C$98 -> 477.99019 | F42: =(SUMPRODUCT($C$15:$I$15,1/(1+$A42)^$C$16:$I$16)+$I$15*(1+F$39)/($A42-F$39)/(1+$A42)^7+Inputs!$C$100)/Inputs!$C$99*100/Inputs!$C$98 -> 504.52632
A43: =Inputs!$C$103+0.005 -> 0.1129 | B43: =(SUMPRODUCT($C$15:$I$15,1/(1+$A43)^$C$16:$I$16)+$I$15*(1+B$39)/($A43-B$39)/(1+$A43)^7+Inputs!$C$100)/Inputs!$C$99*100/Inputs!$C$98 -> 393.61753 | C43: =(SUMPRODUCT($C$15:$I$15,1/(1+$A43)^$C$16:$I$16)+$I$15*(1+C$39)/($A43-C$39)/(1+$A43)^7+Inputs!$C$100)/Inputs!$C$99*100/Inputs!$C$98 -> 408.75597 | D43: =(SUMPRODUCT($C$15:$I$15,1/(1+$A43)^$C$16:$I$16)+$I$15*(1+D$39)/($A43-D$39)/(1+$A43)^7+Inputs!$C$100)/Inputs!$C$99*100/Inputs!$C$98 -> 425.83772 | E43: =(SUMPRODUCT($C$15:$I$15,1/(1+$A43)^$C$16:$I$16)+$I$15*(1+E$39)/($A43-E$39)/(1+$A43)^7+Inputs!$C$100)/Inputs!$C$99*100/Inputs!$C$98 -> 445.26264 | F43: =(SUMPRODUCT($C$15:$I$15,1/(1+$A43)^$C$16:$I$16)+$I$15*(1+F$39)/($A43-F$39)/(1+$A43)^7+Inputs!$C$100)/Inputs!$C$99*100/Inputs!$C$98 -> 467.54839
A44: =Inputs!$C$103+0.01 -> 0.1179 | B44: =(SUMPRODUCT($C$15:$I$15,1/(1+$A44)^$C$16:$I$16)+$I$15*(1+B$39)/($A44-B$39)/(1+$A44)^7+Inputs!$C$100)/Inputs!$C$99*100/Inputs!$C$98 -> 372.29648 | C44: =(SUMPRODUCT($C$15:$I$15,1/(1+$A44)^$C$16:$I$16)+$I$15*(1+C$39)/($A44-C$39)/(1+$A44)^7+Inputs!$C$100)/Inputs!$C$99*100/Inputs!$C$98 -> 385.44688 | D44: =(SUMPRODUCT($C$15:$I$15,1/(1+$A44)^$C$16:$I$16)+$I$15*(1+D$39)/($A44-D$39)/(1+$A44)^7+Inputs!$C$100)/Inputs!$C$99*100/Inputs!$C$98 -> 400.18357 | E44: =(SUMPRODUCT($C$15:$I$15,1/(1+$A44)^$C$16:$I$16)+$I$15*(1+E$39)/($A44-E$39)/(1+$A44)^7+Inputs!$C$100)/Inputs!$C$99*100/Inputs!$C$98 -> 416.81201 | F44: =(SUMPRODUCT($C$15:$I$15,1/(1+$A44)^$C$16:$I$16)+$I$15*(1+F$39)/($A44-F$39)/(1+$A44)^7+Inputs!$C$100)/Inputs!$C$99*100/Inputs!$C$98 -> 435.72145

Sheet Comps
A1: Listed cybersecurity peers at the undisturbed date
A2: Prices: week ending 19 Apr 2024 (PX). Balance sheets and guidance: latest release before 25 Apr 2024. NTM = next-FY guidance midpoint.
A4: Company | B4: Ticker | C4: Price $ | D4: Diluted shares m | E4: Cash & inv. $m | F4: Debt $m | G4: NTM revenue $m | H4: Last FY revenue $m | I4: Guide year | J4: Market cap $m | K4: EV $m | L4: EV / NTM revenue | M4: NTM growth | N4: Source
A5: CrowdStrike | B5: CRWD | C5: 282.64 | D5: 247.94 | E5: 3474.7 | F5: 742.5 | G5: 3956.95 | H5: 3055.6 | I5: FY Jan-25 | J5: =C5*D5 -> 70077.762 | K5: =J5-E5+F5 -> 67345.562 | L5: =K5/G5 -> 17.019563 | M5: =G5/H5-1 -> 0.29498298 | N5: CRWD: CrowdStrike Q4 FY2024 results (8-K), 5 Mar 2024
A6: Palo Alto Networks | B6: PANW | C6: 277.71 | D6: 344.5 | E6: 6990.6 | F6: 1821.8 | G6: 7975 | H6: 6892.7 | I6: FY Jul-24 | J6: =C6*D6 -> 95671.095 | K6: =J6-E6+F6 -> 90502.295 | L6: =K6/G6 -> 11.34825 | M6: =G6/H6-1 -> 0.1570212 | N6: PANW: Palo Alto Networks Q2 FY2024 results (8-K), 20 Feb 2024
A7: Fortinet | B7: FTNT | C7: 63.4 | D7: 772.3 | E7: 2419.4 | F7: 992.3 | G7: 5765 | H7: 5304.8 | I7: FY Dec-24 | J7: =C7*D7 -> 48963.82 | K7: =J7-E7+F7 -> 47536.72 | L7: =K7/G7 -> 8.245745 | M7: =G7/H7-1 -> 0.086751621 | N7: FTNT: Fortinet Q4 2023 results (8-K), 6 Feb 2024
A8: Zscaler | B8: ZS | C8: 169.21 | D8: 148.95 | E8: 2459.8 | F8: 1141 | G8: 2120 | H8: 1617 | I8: FY Jul-24 | J8: =C8*D8 -> 25203.829 | K8: =J8-E8+F8 -> 23885.03 | L8: =K8/G8 -> 11.266523 | M8: =G8/H8-1 -> 0.31106988 | N8: ZS: Zscaler Q2 FY2024 results (8-K), 29 Feb 2024
A9: SentinelOne | B9: S | C9: 20.05 | D9: 301.36 | E9: 1130.8 | F9: 0 | G9: 815 | H9: 621.2 | I9: FY Jan-25 | J9: =C9*D9 -> 6042.268 | K9: =J9-E9+F9 -> 4911.468 | L9: =K9/G9 -> 6.0263411 | M9: =G9/H9-1 -> 0.31197682 | N9: S: SentinelOne Q4 FY2024 results (8-K), 13 Mar 2024
A10: Rapid7 | B10: RPD | C10: 44.31 | D10: 61.5 | E10: 439.3 | F10: 930 | G10: 852 | H10: 777.7 | I10: FY Dec-24 | J10: =C10*D10 -> 2725.065 | K10: =J10-E10+F10 -> 3215.765 | L10: =K10/G10 -> 3.7743721 | M10: =G10/H10-1 -> 0.095538125 | N10: RPD: Rapid7 Q4 2023 results (8-K), 7 Feb 2024
A11: Tenable | B11: TENB | C11: 44.83 | D11: 116.72 | E11: 474 | F11: 359.3 | G11: 900 | H11: 798.7 | I11: FY Dec-24 | J11: =C11*D11 -> 5232.5576 | K11: =J11-E11+F11 -> 5117.8576 | L11: =K11/G11 -> 5.6865084 | M11: =G11/H11-1 -> 0.1268311 | N11: TENB: Tenable Q4 2023 results (8-K), 7 Feb 2024
K13: 25th percentile | L13: =PERCENTILE($L$5:$L$11,0.25) -> 5.8564248
K14: Median | L14: =MEDIAN($L$5:$L$11) -> 8.245745
K15: 75th percentile | L15: =PERCENTILE($L$5:$L$11,0.75) -> 11.307387
K16: Regression slope (multiple per unit of growth) | L16: =SLOPE($L$5:$L$11,$M$5:$M$11) -> 22.440412
K17: Regression intercept | L17: =INTERCEPT($L$5:$L$11,$M$5:$M$11) -> 4.6151313
K18: R-squared | L18: =RSQ($L$5:$L$11,$M$5:$M$11) -> 0.26606625
A21: Applied to Darktrace
A22: Darktrace FY25E revenue (DCF case) | B22: =DCF!C5 -> 834.295
A23: Darktrace NTM revenue at 25 Apr 2024 | B23: =Inputs!$C$104*Inputs!$C$31+(1-Inputs!$C$104)*B22 -> 810.1625
A24: Darktrace NTM growth (FY25E) | B24: =DCF!C6 -> 0.21
A25: Offer EV / NTM revenue | B25: =Inputs!$C$10/B23 -> 6.1617268
A26: Regression-implied multiple | B26: =Comps!$L$17+Comps!$L$16*B24 -> 9.3276179
A27: Value per share at 25th pct (p) | B27: =((Comps!$L$13*B23)+Inputs!$C$100)/Inputs!$C$99*100/Inputs!$C$98 -> 591.14705
A28: Value per share at median (p) | B28: =((Comps!$L$14*B23)+Inputs!$C$100)/Inputs!$C$99*100/Inputs!$C$98 -> 816.95276
A29: Value per share at 75th pct (p) | B29: =((Comps!$L$15*B23)+Inputs!$C$100)/Inputs!$C$99*100/Inputs!$C$98 -> 1106.2971
A30: Regression value, multiple -1x (p) | B30: =(((B26-1)*B23)+Inputs!$C$100)/Inputs!$C$99*100/Inputs!$C$98 -> 824.69026
A31: Regression value, multiple +1x (p) | B31: =(((B26+1)*B23)+Inputs!$C$100)/Inputs!$C$99*100/Inputs!$C$98 -> 1013.7028

Sheet Precedents
A1: Precedent cybersecurity take-privates
A2: EV / last full fiscal-year revenue before announcement. Premium on the basis stated by each party.
A4: Target | B4: Buyer | C4: Announced | D4: EV $m | E4: Last FY revenue $m | F4: EV / revenue | G4: Premium | H4: Premium basis | I4: Deal source | J4: Revenue source
A5: Sophos | B5: Thoma Bravo | C5: Oct 2019 | D5: 3948 | E5: 711 | F5: =D5/E5 -> 5.5527426 | G5: 0.371 | H5: to close 11 Oct 2019 | I5: SOPH: Thoma Bravo, Recommended cash offer for Sophos Group plc, 14 Oct 2019 | J5: SOPH: Thoma Bravo, Recommended cash offer for Sophos Group plc, 14 Oct 2019
A6: Proofpoint | B6: Thoma Bravo | C6: Apr 2021 | D6: 12300 | E6: 1050 | F6: =D6/E6 -> 11.714286 | G6: 0.34 | H6: to close 23 Apr 2021 | I6: PFPT: Help Net Security, Thoma Bravo to acquire Proofpoint, 27 Apr 2021 | J6: PFPT20: Proofpoint Q4 and FY2020 results, Feb 2021
A7: Mimecast | B7: Permira | C7: Dec 2021 | D7: 5800 | E7: 501.4 | F7: =D7/E7 -> 11.567611 | G7: 0.16 | H7: to unaffected close 27 Oct 2021 | I7: MIME: Mimecast / Permira transaction press release (8-K), 7 Dec 2021 | J7: MIME21: Mimecast Q4 and FY2021 results, May 2021
A8: SailPoint | B8: Thoma Bravo | C8: Apr 2022 | D8: 7051.2 | E8: 439 | F8: =D8/E8 -> 16.061959 | G8: 0.48 | H8: to 90-day VWAP | I8: ICON: ICON Corporate Finance, Cybersecurity sector update, Oct 2022 (SailPoint deal EV) | J8: SAIL21: SailPoint Q4 and FY2021 results, 28 Feb 2022
A9: Ping Identity | B9: Thoma Bravo | C9: Aug 2022 | D9: 2800 | E9: 299.4 | F9: =D9/E9 -> 9.3520374 | G9: 0.63 | H9: to close 2 Aug 2022 | I9: PING: Ping Identity / Thoma Bravo press release, 3 Aug 2022 | J9: PING21: Ping Identity Q4 and FY2021 results (8-K), 24 Feb 2022
A10: ForgeRock | B10: Thoma Bravo | C10: Oct 2022 | D10: 2300 | E10: 176.9 | F10: =D10/E10 -> 13.001696 | G10: 0.53 | H10: to close 10 Oct 2022 | I10: FORG: ForgeRock / Thoma Bravo press release (8-K), 11 Oct 2022 | J10: FORG21: ForgeRock Q4 and FY2021 results, 1 Mar 2022
A11: KnowBe4 | B11: Vista | C11: Oct 2022 | D11: 4600 | E11: 246.3 | F11: =D11/E11 -> 18.676411 | G11: 0.44 | H11: to unaffected close 16 Sep 2022 | I11: KNBE: KnowBe4 / Vista press release (8-K), 11 Oct 2022 | J11: KNBE21: KnowBe4 Q4 and FY2021 results, Feb 2022
A12: Darktrace (Thoma Bravo) | D12: =Inputs!$C$10 -> 4992 | E12: =Inputs!$C$11 -> 616 | F12: =D12/E12 -> 8.1038961 | G12: =Offer!$B$16 -> 0.19922631 | H12: LTM revenue to Dec 2023; premium to close 25 Apr 2024
C14: 25th percentile | F14: =PERCENTILE($F$5:$F$11,0.25) -> 10.459824 | G14: =PERCENTILE($G$5:$G$11,0.25) -> 0.3555
C15: Median | F15: =PERCENTILE($F$5:$F$11,0.5) -> 11.714286 | G15: =PERCENTILE($G$5:$G$11,0.5) -> 0.44
C16: 75th percentile | F16: =PERCENTILE($F$5:$F$11,0.75) -> 14.531827 | G16: =PERCENTILE($G$5:$G$11,0.75) -> 0.505
A18: Applied to Darktrace
A19: EV/revenue on LTM revenue, 25th pct (p) | B19: =(($F$14*Inputs!$C$11)+Inputs!$C$100)/Inputs!$C$99*100/Inputs!$C$98 -> 789.28993
A20: EV/revenue on LTM revenue, median (p) | B20: =(($F$15*Inputs!$C$11)+Inputs!$C$100)/Inputs!$C$99*100/Inputs!$C$98 -> 879.4318
A21: EV/revenue on LTM revenue, 75th pct (p) | B21: =(($F$16*Inputs!$C$11)+Inputs!$C$100)/Inputs!$C$99*100/Inputs!$C$98 -> 1081.8919
A22: Premium on undisturbed 517p, 25th pct (p) | B22: =Inputs!$C$15*(1+$G$14) -> 700.7935
A23: Premium on undisturbed 517p, median (p) | B23: =Inputs!$C$15*(1+$G$15) -> 744.48
A24: Premium on undisturbed 517p, 75th pct (p) | B24: =Inputs!$C$15*(1+$G$16) -> 778.085
A25: Premium on 3-month VWAP 429.9p, median (p) | B25: =Inputs!$C$16*(1+$G$15) -> 619.056

Sheet Football field
A1: Valuation football field (pence per share)
A2: Offer 620p. Undisturbed close 517p.
A4: Method | B4: Low | C4: High | D4: Width | E4: Offer
A5: March placing to 12-month high | B5: =Inputs!$C$18 -> 425 | C5: =Inputs!$C$17 -> 518.6 | D5: =C5-B5 -> 93.6 | E5: =Inputs!$C$8 -> 620
A6: DCF (WACC +/-1%, g +/-0.5%) | B6: =DCF!$C$44 -> 385.44688 | C6: =DCF!$E$40 -> 560.72481 | D6: =C6-B6 -> 175.27793 | E6: =Inputs!$C$8 -> 620
A7: Trading comps EV/NTM revenue (Q1-Q3) | B7: =Comps!$B$27 -> 591.14705 | C7: =Comps!$B$29 -> 1106.2971 | D7: =C7-B7 -> 515.15001 | E7: =Inputs!$C$8 -> 620
A8: Growth-adjusted comps (regression +/-1x) | B8: =Comps!$B$30 -> 824.69026 | C8: =Comps!$B$31 -> 1013.7028 | D8: =C8-B8 -> 189.01251 | E8: =Inputs!$C$8 -> 620
A9: Precedent take-privates EV/LTM revenue (Q1-Q3) | B9: =Precedents!$B$19 -> 789.28993 | C9: =Precedents!$B$21 -> 1081.8919 | D9: =C9-B9 -> 292.60198 | E9: =Inputs!$C$8 -> 620
A10: Precedent premiums on undisturbed 517p (Q1-Q3) | B10: =Precedents!$B$22 -> 700.7935 | C10: =Precedents!$B$24 -> 778.085 | D10: =C10-B10 -> 77.2915 | E10: =Inputs!$C$8 -> 620
A11: LBO ability to pay (25% to 20% IRR) | B11: ='Ability to pay'!$B$13 -> 593.00667 | C11: ='Ability to pay'!$B$9 -> 661.3987 | D11: =C11-B11 -> 68.39203 | E11: =Inputs!$C$8 -> 620

Sheet Rival bid
A1: Would a rival bid make sense?
A4: Strategic: FY25E revenue ($m) | B4: =DCF!C5 -> 834.295
A5: Run-rate cost synergies ($m) | B5: =B4*Inputs!$C$59 -> 83.4295
A6: Capitalised after-tax synergies less integration cost ($m) | B6: =B5*(1-Inputs!$C$44)*Inputs!$C$60-B5*Inputs!$C$61 -> 542.29175
A7: Standalone DCF EV ($m) | B7: =DCF!B26 -> 3578.3313
A8: EV with share of synergies paid away ($m) | B8: =B7+B6*Inputs!$C$62 -> 3849.4771
A9: Strategic maximum value per share (p) | B9: =((B8)+Inputs!$C$100)/Inputs!$C$99*100/Inputs!$C$98 -> 486.72358
A10: Rival sponsor at its IRR hurdle, same plan and debt (p) | B10: ='Ability to pay'!$B$17 -> 661.3987
A11: Offer (p) | B11: =Inputs!$C$8 -> 620
A12: Strategic headroom vs offer | B12: =B9/B11-1 -> -0.21496197
A13: Sponsor headroom vs offer | B13: =B10/B11-1 -> 0.066772096
A14: Share of capital not bound by irrevocables | B14: =1-Inputs!$C$22 -> 0.8529
A16: Irrevocables from directors, KKR DA and Summit Partners stay binding if a higher competing offer is made (R27). A scheme needs 75% by value of shares voted, so 14.7% committed to Thoma Bravo is a large block against an interloper.

Sheet LBO
A1: LBO: Base case
A2: Thoma Bravo's actual financing; operating case is an assumption. Interest on opening balances (no circularity).
J3: Actual debt at close ($m) | K3: =Inputs!$C$66+Inputs!$C$71 -> 2145
A4: Base case | J4: Exit multiples for the table
A5: Total debt at close | B5: =LBO!$K$3 -> 2145 | K5: 14
A6: First-lien term loan | B6: =B5*Inputs!$C$66/(Inputs!$C$66+Inputs!$C$71) -> 1735 | K6: 16
A7: Second-lien term loan | B7: =B5-B6 -> 410 | K7: 18
A8: Equity purchase price | B8: =Inputs!$C$7*Inputs!$C$99 -> 5315 | K8: 20
A9: Entry enterprise value | B9: =B8-Inputs!$C$100 -> 4992 | K9: 22
A10: OID | B10: =B6*(1-Inputs!$C$68)+B7*(1-Inputs!$C$73) -> 10.725
A11: Financing fees | B11: =B5*Inputs!$C$76 -> 53.625
A12: Advisory and deal fees | B12: =B9*Inputs!$C$77 -> 49.92
A13: Total uses | B13: =B8+B10+B11+B12 -> 5429.27
A14: Target balance sheet cash used | B14: =Inputs!$C$78-Inputs!$C$79 -> 283.2
A15: Sponsor equity (plug) | B15: =B13-B5-B14 -> 3001.07
A16: Sponsor equity % of uses | B16: =B15/B13 -> 0.55275755
A17: Debt / LTM adjusted EBITDA (Dec 2023) | B17: =B5/Inputs!$C$12 -> 14.691781
A18: Debt / FY24 ARR | B18: =B5/Inputs!$C$33 -> 2.7422654
A20: $m | B20: FY24A | C20: FY25E | D20: FY26E | E20: FY27E | F20: FY28E | G20: FY29E
A21: Revenue | B21: =History!D5 -> 689.5 | C21: =B21*(1+C22) -> 820.505 | D21: =C21*(1+D22) -> 959.99085 | E21: =D21*(1+E22) -> 1103.9895 | F21: =E21*(1+F22) -> 1247.5081 | G21: =F21*(1+G22) -> 1397.2091
A22: Growth | C22: =Inputs!$F$88 -> 0.19 | D22: =Inputs!$G$88 -> 0.17 | E22: =Inputs!$H$88 -> 0.15 | F22: =Inputs!$I$88 -> 0.13 | G22: =Inputs!$J$88 -> 0.12
A23: Adjusted EBITDA | C23: =C21*C24 -> 221.53635 | D23: =D21*D24 -> 297.59716 | E23: =E21*E24 -> 386.39632 | F23: =F21*F24 -> 474.05308 | G23: =G21*G24 -> 558.88363
A24: Margin | C24: =Inputs!$F$89 -> 0.27 | D24: =Inputs!$G$89 -> 0.31 | E24: =Inputs!$H$89 -> 0.35 | F24: =Inputs!$I$89 -> 0.38 | G24: =Inputs!$J$89 -> 0.4
A25: Capex | C25: =C21*Inputs!$C$101 -> 19.872964 | D25: =D21*Inputs!$C$101 -> 23.251368 | E25: =E21*Inputs!$C$101 -> 26.739073 | F25: =F21*Inputs!$C$101 -> 30.215153 | G25: =G21*Inputs!$C$101 -> 33.840971
A26: Working capital inflow | C26: =(C21-B21)*Inputs!$C$46 -> 13.1005 | D26: =(D21-C21)*Inputs!$C$46 -> 13.948585 | E26: =(E21-D21)*Inputs!$C$46 -> 14.399863 | F26: =(F21-E21)*Inputs!$C$46 -> 14.351863 | G26: =(G21-F21)*Inputs!$C$46 -> 14.970097
A27: D&A (tax) | C27: =C21*Inputs!$C$102 -> 33.535627 | D27: =D21*Inputs!$C$102 -> 39.236683 | E27: =E21*Inputs!$C$102 -> 45.122186 | F27: =F21*Inputs!$C$102 -> 50.98807 | G27: =G21*Inputs!$C$102 -> 57.106638
A28: Ownership fraction of year | C28: =Inputs!$C$84 -> 0.75 | D28: =1 -> 1 | E28: =1 -> 1 | F28: =1 -> 1 | G28: =1 -> 1
A29: SOFR | C29: =Inputs!$F$75 -> 0.046 | D29: =Inputs!$G$75 -> 0.039 | E29: =Inputs!$H$75 -> 0.036 | F29: =Inputs!$I$75 -> 0.035 | G29: =Inputs!$J$75 -> 0.035
A30: First lien: opening | C30: =$B$6 -> 1735 | D30: =C41 -> 1721.9875 | E30: =D41 -> 1685.2337 | F30: =E41 -> 1566.5491 | G30: =F41 -> 1367.2199
A31: Interest: first lien | C31: =C30*(C29+Inputs!$C$67)*C28 -> 102.14812 | D31: =D30*(D29+Inputs!$C$67)*D28 -> 123.12211 | E31: =E30*(E29+Inputs!$C$67)*E28 -> 115.43851 | F31: =F30*(F29+Inputs!$C$67)*F28 -> 105.74207 | G31: =G30*(G29+Inputs!$C$67)*G28 -> 92.287346
A32: Interest: second lien | C32: =C42*(C29+Inputs!$C$72)*C28 -> 30.28875 | D32: =D42*(D29+Inputs!$C$72)*D28 -> 37.515 | E32: =E42*(E29+Inputs!$C$72)*E28 -> 36.285 | F32: =F42*(F29+Inputs!$C$72)*F28 -> 35.875 | G32: =G42*(G29+Inputs!$C$72)*G28 -> 35.875
A33: Total cash interest | C33: =C31+C32 -> 132.43687 | D33: =D31+D32 -> 160.63711 | E33: =E31+E32 -> 151.72351 | F33: =F31+F32 -> 141.61707 | G33: =G31+G32 -> 128.16235
A34: Deductible interest (30% of tax-EBITDA cap) | C34: =MIN(C33,Inputs!$C$45*C23*C28) -> 49.845679 | D34: =MIN(D33,Inputs!$C$45*D23*D28) -> 89.279149 | E34: =MIN(E33,Inputs!$C$45*E23*E28) -> 115.9189 | F34: =MIN(F33,Inputs!$C$45*F23*F28) -> 141.61707 | G34: =MIN(G33,Inputs!$C$45*G23*G28) -> 128.16235
A35: Cash tax | C35: =MAX(0,(C23-C27)*C28-C34)*Inputs!$C$44 -> 22.788716 | D35: =MAX(0,(D23-D27)*D28-D34)*Inputs!$C$44 -> 42.270333 | E35: =MAX(0,(E23-E27)*E28-E34)*Inputs!$C$44 -> 56.338809 | F35: =MAX(0,(F23-F27)*F28-F34)*Inputs!$C$44 -> 70.361986 | G35: =MAX(0,(G23-G27)*G28-G34)*Inputs!$C$44 -> 93.403662
A36: Free cash flow after interest and tax | C36: =(C23-C25+C26-Inputs!$C$81)*C28-C33-C35 -> -9.1526764 | D36: =(D23-D25+D26-Inputs!$C$81)*D28-D33-D35 -> 65.386942 | E36: =(E23-E25+E26-Inputs!$C$81)*E28-E33-E35 -> 145.99479 | F36: =(F23-F25+F26-Inputs!$C$81)*F28-F33-F35 -> 226.21074 | G36: =(G23-G25+G26-Inputs!$C$81)*G28-G33-G35 -> 298.44675
A37: First lien: mandatory amortisation | C37: =MIN(C30,$B$6*Inputs!$C$70*C28) -> 13.0125 | D37: =MIN(D30,$B$6*Inputs!$C$70*D28) -> 17.35 | E37: =MIN(E30,$B$6*Inputs!$C$70*E28) -> 17.35 | F37: =MIN(F30,$B$6*Inputs!$C$70*F28) -> 17.35 | G37: =MIN(G30,$B$6*Inputs!$C$70*G28) -> 17.35
A38: Opening cash | C38: =Inputs!$C$79 -> 100 | D38: =C43 -> 77.834824 | E38: =D43 -> 106.46794 | F38: =E43 -> 133.77818 | G38: =F43 -> 160.65973
A39: Cash available after amortisation | C39: =C38+C36-C37 -> 77.834824 | D39: =D38+D36-D37 -> 125.87177 | E39: =E38+E36-E37 -> 235.11273 | F39: =F38+F36-F37 -> 342.63892 | G39: =G38+G36-G37 -> 441.75648
A40: First lien: cash sweep | C40: =MIN(MAX(0,C39-Inputs!$C$79)*Inputs!$C$80,C30-C37) -> 0 | D40: =MIN(MAX(0,D39-Inputs!$C$79)*Inputs!$C$80,D30-D37) -> 19.403824 | E40: =MIN(MAX(0,E39-Inputs!$C$79)*Inputs!$C$80,E30-E37) -> 101.33455 | F40: =MIN(MAX(0,F39-Inputs!$C$79)*Inputs!$C$80,F30-F37) -> 181.97919 | G40: =MIN(MAX(0,G39-Inputs!$C$79)*Inputs!$C$80,G30-G37) -> 256.31736
A41: First lien: closing | C41: =C30-C37-C40 -> 1721.9875 | D41: =D30-D37-D40 -> 1685.2337 | E41: =E30-E37-E40 -> 1566.5491 | F41: =F30-F37-F40 -> 1367.2199 | G41: =G30-G37-G40 -> 1093.5526
...

Sheet Downside
A1: LBO: Downside case
A2: Same financing, slower growth and a weaker cost programme
A4: Downside case
A5: Total debt at close | B5: =LBO!$K$3 -> 2145
A6: First-lien term loan | B6: =B5*Inputs!$C$66/(Inputs!$C$66+Inputs!$C$71) -> 1735
A7: Second-lien term loan | B7: =B5-B6 -> 410
A8: Equity purchase price | B8: =Inputs!$C$7*Inputs!$C$99 -> 5315
A9: Entry enterprise value | B9: =B8-Inputs!$C$100 -> 4992
A10: OID | B10: =B6*(1-Inputs!$C$68)+B7*(1-Inputs!$C$73) -> 10.725
A11: Financing fees | B11: =B5*Inputs!$C$76 -> 53.625
A12: Advisory and deal fees | B12: =B9*Inputs!$C$77 -> 49.92
A13: Total uses | B13: =B8+B10+B11+B12 -> 5429.27
A14: Target balance sheet cash used | B14: =Inputs!$C$78-Inputs!$C$79 -> 283.2
A15: Sponsor equity (plug) | B15: =B13-B5-B14 -> 3001.07
A16: Sponsor equity % of uses | B16: =B15/B13 -> 0.55275755
A17: Debt / LTM adjusted EBITDA (Dec 2023) | B17: =B5/Inputs!$C$12 -> 14.691781
A18: Debt / FY24 ARR | B18: =B5/Inputs!$C$33 -> 2.7422654
A20: $m | B20: FY24A | C20: FY25E | D20: FY26E | E20: FY27E | F20: FY28E | G20: FY29E
A21: Revenue | B21: =History!D5 -> 689.5 | C21: =B21*(1+C22) -> 772.24 | D21: =C21*(1+D22) -> 841.7416 | E21: =D21*(1+E22) -> 900.66351 | F21: =E21*(1+F22) -> 954.70332 | G21: =F21*(1+G22) -> 1002.4385
A22: Growth | C22: =Inputs!$F$93 -> 0.12 | D22: =Inputs!$G$93 -> 0.09 | E22: =Inputs!$H$93 -> 0.07 | F22: =Inputs!$I$93 -> 0.06 | G22: =Inputs!$J$93 -> 0.05
A23: Adjusted EBITDA | C23: =C21*C24 -> 185.3376 | D23: =D21*D24 -> 210.4354 | E23: =E21*E24 -> 234.17251 | F23: =F21*F24 -> 257.7699 | G23: =G21*G24 -> 280.68278
A24: Margin | C24: =Inputs!$F$94 -> 0.24 | D24: =Inputs!$G$94 -> 0.25 | E24: =Inputs!$H$94 -> 0.26 | F24: =Inputs!$I$94 -> 0.27 | G24: =Inputs!$J$94 -> 0.28
A25: Capex | C25: =C21*Inputs!$C$101 -> 18.703966 | D25: =D21*Inputs!$C$101 -> 20.387323 | E25: =E21*Inputs!$C$101 -> 21.814436 | F25: =F21*Inputs!$C$101 -> 23.123302 | G25: =G21*Inputs!$C$101 -> 24.279467
A26: Working capital inflow | C26: =(C21-B21)*Inputs!$C$46 -> 8.274 | D26: =(D21-C21)*Inputs!$C$46 -> 6.95016 | E26: =(E21-D21)*Inputs!$C$46 -> 5.8921912 | F26: =(F21-E21)*Inputs!$C$46 -> 5.4039811 | G26: =(G21-F21)*Inputs!$C$46 -> 4.7735166
A27: D&A (tax) | C27: =C21*Inputs!$C$102 -> 31.562943 | D27: =D21*Inputs!$C$102 -> 34.403608 | E27: =E21*Inputs!$C$102 -> 36.81186 | F27: =F21*Inputs!$C$102 -> 39.020572 | G27: =G21*Inputs!$C$102 -> 40.9716
A28: Ownership fraction of year | C28: =Inputs!$C$84 -> 0.75 | D28: =1 -> 1 | E28: =1 -> 1 | F28: =1 -> 1 | G28: =1 -> 1
A29: SOFR | C29: =Inputs!$F$75 -> 0.046 | D29: =Inputs!$G$75 -> 0.039 | E29: =Inputs!$H$75 -> 0.036 | F29: =Inputs!$I$75 -> 0.035 | G29: =Inputs!$J$75 -> 0.035
A30: First lien: opening | C30: =$B$6 -> 1735 | D30: =C41 -> 1721.9875 | E30: =D41 -> 1704.6375 | F30: =E41 -> 1687.2875 | G30: =F41 -> 1669.9375
A31: Interest: first lien | C31: =C30*(C29+Inputs!$C$67)*C28 -> 102.14812 | D31: =D30*(D29+Inputs!$C$67)*D28 -> 123.12211 | E31: =E30*(E29+Inputs!$C$67)*E28 -> 116.76767 | F31: =F30*(F29+Inputs!$C$67)*F28 -> 113.89191 | G31: =G30*(G29+Inputs!$C$67)*G28 -> 112.72078
A32: Interest: second lien | C32: =C42*(C29+Inputs!$C$72)*C28 -> 30.28875 | D32: =D42*(D29+Inputs!$C$72)*D28 -> 37.515 | E32: =E42*(E29+Inputs!$C$72)*E28 -> 36.285 | F32: =F42*(F29+Inputs!$C$72)*F28 -> 35.875 | G32: =G42*(G29+Inputs!$C$72)*G28 -> 35.875
A33: Total cash interest | C33: =C31+C32 -> 132.43687 | D33: =D31+D32 -> 160.63711 | E33: =E31+E32 -> 153.05267 | F33: =F31+F32 -> 149.76691 | G33: =G31+G32 -> 148.59578
A34: Deductible interest (30% of tax-EBITDA cap) | C34: =MIN(C33,Inputs!$C$45*C23*C28) -> 41.70096 | D34: =MIN(D33,Inputs!$C$45*D23*D28) -> 63.13062 | E34: =MIN(E33,Inputs!$C$45*E23*E28) -> 70.251754 | F34: =MIN(F33,Inputs!$C$45*F23*F28) -> 77.330969 | G34: =MIN(G33,Inputs!$C$45*G23*G28) -> 84.204833
A35: Cash tax | C35: =MAX(0,(C23-C27)*C28-C34)*Inputs!$C$44 -> 18.407508 | D35: =MAX(0,(D23-D27)*D28-D34)*Inputs!$C$44 -> 28.225293 | E35: =MAX(0,(E23-E27)*E28-E34)*Inputs!$C$44 -> 31.777225 | F35: =MAX(0,(F23-F27)*F28-F34)*Inputs!$C$44 -> 35.354589 | G35: =MAX(0,(G23-G27)*G28-G34)*Inputs!$C$44 -> 38.876586
A36: Free cash flow after interest and tax | C36: =(C23-C25+C26-Inputs!$C$81)*C28-C33-C35 -> -34.663658 | D36: =(D23-D25+D26-Inputs!$C$81)*D28-D33-D35 -> -11.864162 | E36: =(E23-E25+E26-Inputs!$C$81)*E28-E33-E35 -> 13.420375 | F36: =(F23-F25+F26-Inputs!$C$81)*F28-F33-F35 -> 34.929081 | G36: =(G23-G25+G26-Inputs!$C$81)*G28-G33-G35 -> 53.704459
A37: First lien: mandatory amortisation | C37: =MIN(C30,$B$6*Inputs!$C$70*C28) -> 13.0125 | D37: =MIN(D30,$B$6*Inputs!$C$70*D28) -> 17.35 | E37: =MIN(E30,$B$6*Inputs!$C$70*E28) -> 17.35 | F37: =MIN(F30,$B$6*Inputs!$C$70*F28) -> 17.35 | G37: =MIN(G30,$B$6*Inputs!$C$70*G28) -> 17.35
A38: Opening cash | C38: =Inputs!$C$79 -> 100 | D38: =C43 -> 52.323842 | E38: =D43 -> 23.10968 | F38: =E43 -> 19.180055 | G38: =F43 -> 36.759136
A39: Cash available after amortisation | C39: =C38+C36-C37 -> 52.323842 | D39: =D38+D36-D37 -> 23.10968 | E39: =E38+E36-E37 -> 19.180055 | F39: =F38+F36-F37 -> 36.759136 | G39: =G38+G36-G37 -> 73.113596
A40: First lien: cash sweep | C40: =MIN(MAX(0,C39-Inputs!$C$79)*Inputs!$C$80,C30-C37) -> 0 | D40: =MIN(MAX(0,D39-Inputs!$C$79)*Inputs!$C$80,D30-D37) -> 0 | E40: =MIN(MAX(0,E39-Inputs!$C$79)*Inputs!$C$80,E30-E37) -> 0 | F40: =MIN(MAX(0,F39-Inputs!$C$79)*Inputs!$C$80,F30-F37) -> 0 | G40: =MIN(MAX(0,G39-Inputs!$C$79)*Inputs!$C$80,G30-G37) -> 0
A41: First lien: closing | C41: =C30-C37-C40 -> 1721.9875 | D41: =D30-D37-D40 -> 1704.6375 | E41: =E30-E37-E40 -> 1687.2875 | F41: =F30-F37-F40 -> 1669.9375 | G41: =G30-G37-G40 -> 1652.5875
A42: Second lien: closing | C42: =$B$7 -> 410 | D42: =$B$7 -> 410 | E42: =$B$7 -> 410 | F42: =$B$7 -> 410 | G42: =$B$7 -> 410
...

Sheet LBO grid
A1: LBO grid: IRR by exit multiple and debt at close (Base case)
A2: Each column is a full re-run of the debt schedule (blocks below)
A3: Total debt at close ($m) | B3: 1500 | C3: 1800 | D3: 2145 | E3: 2400 | F3: 2700
A4: Debt / LTM EBITDA | B4: =B3/Inputs!$C$12 -> 10.273973 | C4: =C3/Inputs!$C$12 -> 12.328767 | D4: =D3/Inputs!$C$12 -> 14.691781 | E4: =E3/Inputs!$C$12 -> 16.438356 | F4: =F3/Inputs!$C$12 -> 18.493151
A5: IRR: exit multiple (rows) x debt (columns)
A6: 14 | B6: =$H$60 -> 0.13886822 | C6: =$H$114 -> 0.14542113 | D6: =$H$168 -> 0.15418366 | E6: =$H$222 -> 0.16164605 | F6: =$H$276 -> 0.17202225
A7: 16 | B7: =$H$61 -> 0.17349533 | C7: =$H$115 -> 0.18215311 | D7: =$H$169 -> 0.19370057 | E7: =$H$223 -> 0.20354072 | F7: =$H$277 -> 0.21712627
A8: 18 | B8: =$H$62 -> 0.20466701 | C8: =$H$116 -> 0.21504496 | D8: =$H$170 -> 0.22884489 | E8: =$H$224 -> 0.24058762 | F8: =$H$278 -> 0.2567138
A9: 20 | B9: =$H$63 -> 0.23307802 | C9: =$H$117 -> 0.24490136 | D9: =$H$171 -> 0.26057995 | E9: =$H$225 -> 0.27389752 | F9: =$H$279 -> 0.29211141
A10: 22 | B10: =$H$64 -> 0.25922715 | C10: =$H$118 -> 0.27229144 | D10: =$H$172 -> 0.28957417 | E10: =$H$226 -> 0.30422903 | F10: =$H$280 -> 0.32420669
A12: Sponsor equity cheque ($m) | B12: =$B$26 -> 3626.72 | C12: =$B$80 -> 3335.72 | D12: =$B$134 -> 3001.07 | E12: =$B$188 -> 2753.72 | F12: =$B$242 -> 2462.72
A15: Block 1: debt $1,500m
A16: Total debt at close | B16: ='LBO grid'!$B$3 -> 1500
A17: First-lien term loan | B17: =B16*Inputs!$C$66/(Inputs!$C$66+Inputs!$C$71) -> 1213.2867
A18: Second-lien term loan | B18: =B16-B17 -> 286.71329
A19: Equity purchase price | B19: =Inputs!$C$7*Inputs!$C$99 -> 5315
A20: Entry enterprise value | B20: =B19-Inputs!$C$100 -> 4992
A21: OID | B21: =B17*(1-Inputs!$C$68)+B18*(1-Inputs!$C$73) -> 7.5
A22: Financing fees | B22: =B16*Inputs!$C$76 -> 37.5
A23: Advisory and deal fees | B23: =B20*Inputs!$C$77 -> 49.92
A24: Total uses | B24: =B19+B21+B22+B23 -> 5409.92
A25: Target balance sheet cash used | B25: =Inputs!$C$78-Inputs!$C$79 -> 283.2
A26: Sponsor equity (plug) | B26: =B24-B16-B25 -> 3626.72
A27: Sponsor equity % of uses | B27: =B26/B24 -> 0.6703833
A28: Debt / LTM adjusted EBITDA (Dec 2023) | B28: =B16/Inputs!$C$12 -> 10.273973
A29: Debt / FY24 ARR | B29: =B16/Inputs!$C$33 -> 1.9176681
A31: $m | B31: FY24A | C31: FY25E | D31: FY26E | E31: FY27E | F31: FY28E | G31: FY29E
A32: Revenue | B32: =History!D5 -> 689.5 | C32: =B32*(1+C33) -> 820.505 | D32: =C32*(1+D33) -> 959.99085 | E32: =D32*(1+E33) -> 1103.9895 | F32: =E32*(1+F33) -> 1247.5081 | G32: =F32*(1+G33) -> 1397.2091
A33: Growth | C33: =Inputs!$F$88 -> 0.19 | D33: =Inputs!$G$88 -> 0.17 | E33: =Inputs!$H$88 -> 0.15 | F33: =Inputs!$I$88 -> 0.13 | G33: =Inputs!$J$88 -> 0.12
A34: Adjusted EBITDA | C34: =C32*C35 -> 221.53635 | D34: =D32*D35 -> 297.59716 | E34: =E32*E35 -> 386.39632 | F34: =F32*F35 -> 474.05308 | G34: =G32*G35 -> 558.88363
A35: Margin | C35: =Inputs!$F$89 -> 0.27 | D35: =Inputs!$G$89 -> 0.31 | E35: =Inputs!$H$89 -> 0.35 | F35: =Inputs!$I$89 -> 0.38 | G35: =Inputs!$J$89 -> 0.4
A36: Capex | C36: =C32*Inputs!$C$101 -> 19.872964 | D36: =D32*Inputs!$C$101 -> 23.251368 | E36: =E32*Inputs!$C$101 -> 26.739073 | F36: =F32*Inputs!$C$101 -> 30.215153 | G36: =G32*Inputs!$C$101 -> 33.840971
A37: Working capital inflow | C37: =(C32-B32)*Inputs!$C$46 -> 13.1005 | D37: =(D32-C32)*Inputs!$C$46 -> 13.948585 | E37: =(E32-D32)*Inputs!$C$46 -> 14.399863 | F37: =(F32-E32)*Inputs!$C$46 -> 14.351863 | G37: =(G32-F32)*Inputs!$C$46 -> 14.970097
A38: D&A (tax) | C38: =C32*Inputs!$C$102 -> 33.535627 | D38: =D32*Inputs!$C$102 -> 39.236683 | E38: =E32*Inputs!$C$102 -> 45.122186 | F38: =F32*Inputs!$C$102 -> 50.98807 | G38: =G32*Inputs!$C$102 -> 57.106638
A39: Ownership fraction of year | C39: =Inputs!$C$84 -> 0.75 | D39: =1 -> 1 | E39: =1 -> 1 | F39: =1 -> 1 | G39: =1 -> 1
A40: SOFR | C40: =Inputs!$F$75 -> 0.046 | D40: =Inputs!$G$75 -> 0.039 | E40: =Inputs!$H$75 -> 0.036 | F40: =Inputs!$I$75 -> 0.035 | G40: =Inputs!$J$75 -> 0.035
A41: First lien: opening | C41: =$B$17 -> 1213.2867 | D41: =C52 -> 1188.0086 | E41: =D52 -> 1094.7953 | F41: =E52 -> 926.39487 | G41: =F52 -> 684.26283
A42: Interest: first lien | C42: =C41*(C40+Inputs!$C$67)*C39 -> 71.432255 | D42: =D41*(D40+Inputs!$C$67)*D39 -> 84.942611 | E42: =E41*(E40+Inputs!$C$67)*E39 -> 74.99348 | F42: =F41*(F40+Inputs!$C$67)*F39 -> 62.531654 | G42: =G41*(G40+Inputs!$C$67)*G39 -> 46.187741
A43: Interest: second lien | C43: =C53*(C40+Inputs!$C$72)*C39 -> 21.180944 | D43: =D53*(D40+Inputs!$C$72)*D39 -> 26.234266 | E43: =E53*(E40+Inputs!$C$72)*E39 -> 25.374126 | F43: =F53*(F40+Inputs!$C$72)*F39 -> 25.087413 | G43: =G53*(G40+Inputs!$C$72)*G39 -> 25.087413
A44: Total cash interest | C44: =C42+C43 -> 92.613199 | D44: =D42+D43 -> 111.17688 | E44: =E42+E43 -> 100.36761 | F44: =F42+F43 -> 87.619066 | G44: =G42+G43 -> 71.275153
...

Sheet Ability to pay
A1: LBO ability to pay
A2: Exit equity does not depend on the entry price, so the price is solved in closed form for each IRR hurdle
A4: Sponsor exit proceeds, Base case ($m) | B4: =LBO!$F$49 -> 7987.0646
A6: IRR hurdle | B6: 0.2
A7: Sponsor equity that clears the hurdle ($m) | B7: =B4/(1+B6)^Inputs!$C$85 -> 3359.5126
A8: Maximum price per share ($) | B8: =(B7+LBO!$K$3+LBO!$B$14-LBO!$B$10-LBO!$B$11+Inputs!$C$77*Inputs!$C$100)/(Inputs!$C$99*(1+Inputs!$C$77)) -> 8.2674837
A9: Maximum price per share (p) | B9: =B8*100/Inputs!$C$98 -> 661.3987
A10: IRR hurdle | B10: 0.25
A11: Sponsor equity that clears the hurdle ($m) | B11: =B4/(1+B10)^Inputs!$C$85 -> 2767.3535
A12: Maximum price per share ($) | B12: =(B11+LBO!$K$3+LBO!$B$14-LBO!$B$10-LBO!$B$11+Inputs!$C$77*Inputs!$C$100)/(Inputs!$C$99*(1+Inputs!$C$77)) -> 7.4125834
A13: Maximum price per share (p) | B13: =B12*100/Inputs!$C$98 -> 593.00667
A14: IRR hurdle | B14: =Inputs!$C$63 -> 0.2
A15: Sponsor equity that clears the hurdle ($m) | B15: =B4/(1+B14)^Inputs!$C$85 -> 3359.5126
A16: Maximum price per share ($) | B16: =(B15+LBO!$K$3+LBO!$B$14-LBO!$B$10-LBO!$B$11+Inputs!$C$77*Inputs!$C$100)/(Inputs!$C$99*(1+Inputs!$C$77)) -> 8.2674837
A17: Maximum price per share (p) | B17: =B16*100/Inputs!$C$98 -> 661.3987
A19: Offer price (p) | B19: =Inputs!$C$8 -> 620
A20: Base-case IRR at the offer price | B20: =LBO!$H$49 -> 0.22884489

Sheet Sources
A1: Sources
A3: Key | B3: Document | C3: URL
A4: R27 | B4: Rule 2.7 announcement, Recommended Cash Acquisition of Darktrace plc, 26 Apr 2024 | C4: https://ir.darktrace.com/regulatory-news/2024/4/26/1813465
A5: SCH | B5: Scheme document, 23 May 2024, pp. 15, 19, 28 and 87 (offer, undertakings, interim financing) | C5: https://data.fca.org.uk/artefacts/NSM/Portal/NI-000097497/NI-000097497.pdf
A6: VOTE | B6: Results of Court Meeting and General Meeting, 18 Jun 2024 | C6: https://www.investegate.co.uk/announcement/rns/darktrace--dark/result-of-meeting/8266218
A7: REG | B7: Regulatory approval and timetable update, 16 Sep 2024 | C7: https://www.lse.co.uk/rns/DARK/regulatory-approval-timetable-update-r7souzslq618lx3.html
A8: EFF | B8: Scheme Effective, 1 Oct 2024 | C8: https://ir.darktrace.com/regulatory-news/2024/10/1/1870431
A9: FY23 | B9: Darktrace FY 2023 final results, 6 Sep 2023 | C9: https://ir.darktrace.com/regulatory-news/2023/9/6/1713518
A10: H124 | B10: Darktrace half-year results to 31 Dec 2023, 7 Mar 2024 | C10: https://ir.darktrace.com/regulatory-news/2024/3/7/1796862
A11: Q424 | B11: Darktrace Q4 FY 2024 trading update, 18 Jul 2024 | C11: https://ir.darktrace.com/regulatory-news/2024/7/18/1843731
A12: BBG1 | B12: Bloomberg Law, Thoma Bravo lines up $2 billion financing for Darktrace buyout, 26 Apr 2024 | C12: https://news.bloomberglaw.com/private-equity/thoma-bravo-lines-up-2-billion-financing-for-darktrace-buyout
A13: BBG2 | B13: Bloomberg Law, Banks kick off $2.1 billion loan package for Darktrace LBO, 13 Jun 2024 | C13: https://news.bloomberglaw.com/private-equity/banks-kick-off-2-1-billion-loan-package-for-darktrace-buyout
A14: PB | B14: PitchBook LCD, Darktrace wraps loan package backing Thoma Bravo's buyout, 2024 | C14: https://pitchbook.com/news/articles/darktrace-wraps-loan-package-backing-thoma-bravos-buyout
... A40: KNBE21 | B40: KnowBe4 Q4 and FY2021 results, Feb 2022 | C40: https://www.stocktitan.net/news/KNBE/know-be4-announces-fourth-quarter-and-fiscal-year-2021-financial-k4oklarrxaz2.html
A42: Conventions: blue = input, black = formula, green = link to another sheet. Not investment advice.
